1128=99=262535=X49=CME34=21100052=2013071515013022375=20130715268=26279=222=848=24341283=1863107=GEH5 C9725269=1270=199.5271=75273=150130000336=2346=11023=1279=122=848=24341283=1864107=GEH5 C9725269=1270=200271=125273=150130000336=2346=21023=1279=222=848=27610983=1853107=GEH5 C9762269=1270=164271=75273=150130000336=2346=11023=1279=122=848=27610983=1854107=GEH5 C9762269=1270=164.5271=125273=150130000336=2346=21023=1279=222=848=53035583=1410107=GEH5 C9750269=1270=176271=75273=150130000336=2346=11023=1279=122=848=53035583=1411107=GEH5 C9750269=1270=176.5271=125273=150130000336=2346=21023=1279=222=848=43579483=1745107=GEH5 C9775269=1270=152.5271=75273=150130000336=2346=11023=1279=122=848=43579483=1746107=GEH5 C9775269=1270=153271=125273=150130000336=2346=21023=1279=222=848=2866183=1659107=GEH5 C9800269=1270=129.5271=75273=150130000336=2346=11023=1279=122=848=2866183=1660107=GEH5 C9800269=1270=130271=125273=150130000336=2346=21023=1279=222=848=80705883=1690107=GEH5 C9787269=1270=141271=75273=150130000336=2346=11023=1279=122=848=80705883=1691107=GEH5 C9787269=1270=141.5271=125273=150130000336=2346=21023=1279=222=848=2308583=998107=GEH5 C9900269=1270=46271=150273=150130000336=2346=11023=1279=122=848=2308583=999107=GEH5 C9900269=1270=46.5271=250273=150130000336=2346=21023=1279=222=848=11969183=1024107=GEH5 P9962269=0270=50.5271=75273=150130000336=2346=11023=1279=022=848=11969183=1025107=GEH5 P9962269=0270=50271=75273=150130000336=2346=11023=1279=222=848=27043383=960107=GEH5 P9950269=0270=43.5271=75273=150130000336=2346=11023=1279=022=848=27043383=961107=GEH5 P9950269=0270=43271=75273=150130000336=2346=11023=1279=222=848=57304683=1261107=GEH5 P9937269=0270=38271=75273=150130000336=2346=11023=1279=122=848=57304683=1262107=GEH5 P9937269=0270=37.5271=125273=150130000336=2346=21023=1279=222=848=75866783=2339107=GEH5 P9862269=0270=18271=150273=150130000336=2346=11023=1279=122=848=75866783=2340107=GEH5 P9862269=0270=17.5271=750273=150130000336=2346=31023=1279=222=848=25692083=2208107=GEH5 P9850269=0270=16271=150273=150130000336=2346=11023=1279=122=848=25692083=2209107=GEH5 P9850269=0270=15.5271=750273=150130000336=2346=31023=1279=222=848=38742583=445107=GEH5 P9675269=0270=3.5271=150273=150130000336=2346=11023=1279=122=848=38742583=446107=GEH5 P9675269=0270=3271=250273=150130000336=2346=21023=110=029
1128=99=25835=X49=CME34=12840252=2013071513211546975=20130715268=2279=122=848=25677583=1895107=GEZ4 P9900269=0270=17271=333273=132115000336=2346=31023=1279=122=848=25677583=1896107=GEZ4 P9900269=1270=19271=1025273=132115000336=2346=41023=110=142
1128=99=368335=X49=CME34=16063352=2013071514000772075=20130715268=37279=022=848=89142083=1026107=GEM5 P9875269=0270=30271=500273=140007000336=2346=11023=1279=022=848=89142083=1027107=GEM5 P9875269=1270=33.5271=500273=140007000336=2346=11023=1279=022=848=56610983=1192107=GEM5 P9887269=0270=33271=500273=140007000336=2346=11023=1279=022=848=56610983=1193107=GEM5 P9887269=1270=37271=500273=140007000336=2346=11023=1279=022=848=27025983=1408107=GEM5 C9887269=0270=46271=500273=140007000336=2346=11023=1279=022=848=27025983=1409107=GEM5 C9887269=1270=49.5271=500273=140007000336=2346=11023=1279=022=848=5616483=1346107=GEM5 P9912269=0270=42271=500273=140007000336=2346=11023=1279=022=848=5616483=1347107=GEM5 P9912269=1270=45.5271=500273=140007000336=2346=11023=1279=022=848=62717183=1172107=GEM5 P9900269=0270=37271=500273=140007000336=2346=11023=1279=022=848=62717183=1173107=GEM5 P9900269=1270=41271=500273=140007000336=2346=11023=1279=122=848=7822483=1040107=GEM5 C9900269=0270=37.5271=575273=140007000336=2346=21023=1279=122=848=7822483=1041107=GEM5 C9900269=1270=41271=575273=140007000336=2346=21023=1279=122=848=12624783=872107=GEM5 C9912269=0270=29.5271=575273=140007000336=2346=21023=1279=022=848=12624783=873107=GEM5 C9912269=1270=33.5271=500273=140007000336=2346=11023=2279=022=848=24323583=248107=GEM5 C9950269=0270=10271=500273=140007000336=2346=11023=1279=022=848=24323583=249107=GEM5 C9950269=1270=13.5271=500273=140007000336=2346=11023=1279=122=848=20191983=797107=GEM5 C9937269=0270=15.5271=575273=140007000336=2346=21023=1279=022=848=20191983=798107=GEM5 C9937269=1270=19.5271=500273=140007000336=2346=11023=2279=022=848=22972583=977107=GEM5 C9925269=0270=22.5271=500273=140007000336=2346=11023=1279=122=848=22972583=978107=GEM5 C9925269=1270=26271=575273=140007000336=2346=21023=1279=022=848=51105783=406107=GEM5 C9962269=0270=5.5271=500273=140007000336=2346=11023=1279=022=848=51105783=407107=GEM5 C9962269=1270=9271=500273=140007000336=2346=11023=1279=022=848=77875183=52107=GEM5 C9987269=1270=3.5271=500273=140007000336=2346=11023=1279=022=848=42210983=124107=GEM5 C9975269=0270=2271=500273=140007000336=2346=11023=1279=022=848=42210983=125107=GEM5 C9975269=1270=5.5271=500273=140007000336=2346=11023=1279=122=848=25917983=324107=GEM5 P9762269=0270=11.5271=575273=140007000336=2346=21023=1279=122=848=25917983=325107=GEM5 P9762269=1270=15271=575273=140007000336=2346=21023=1279=022=848=59448183=520107=GEM5 P9750269=0270=10271=500273=140007000336=2346=11023=2279=122=848=59448183=521107=GEM5 P9750269=1270=14271=575273=140007000336=2346=21023=1279=022=848=61727283=544107=GEM5 P9737269=0270=9271=500273=140007000336=2346=11023=2279=022=848=61727283=545107=GEM5 P9737269=1270=12.5271=500273=140007000336=2346=11023=1279=022=848=10841283=436107=GEM5 P9725269=0270=8271=500273=140007000336=2346=11023=2279=122=848=10841283=437107=GEM5 P9725269=1270=12271=575273=140007000336=2346=21023=1279=122=848=1469183=728107=GEM5 P9787269=0270=14271=575273=140007000336=2346=21023=1279=022=848=1469183=729107=GEM5 P9787269=1270=18271=500273=140007000336=2346=11023=2279=122=848=30078683=584107=GEM5 P9775269=0270=12.5271=575273=140007000336=2346=21023=1279=122=848=30078683=585107=GEM5 P9775269=1270=16.5271=575273=140007000336=2346=21023=110=067
1128=99=25735=X49=CME34=23891652=2013071515461983275=20130715268=2279=022=848=37100783=251107=GEM4 P9962269=0270=15.5271=125273=154619000336=2346=11023=1279=222=848=37100783=252107=GEM4 P9962269=0270=15271=125273=154619000336=2346=11023=210=061
1128=99=461035=X49=CME34=32883852=2013071518125044175=20130715268=46279=022=848=72272783=2406107=GEH5 C9850269=1270=85.5271=150273=181250000336=2346=11023=1279=122=848=72272783=2407107=GEH5 C9850269=1270=86271=100273=181250000336=2346=11023=2279=022=848=36716183=1700107=GEH5 C9275269=1270=644271=75273=181250000336=2346=11023=1279=222=848=36716183=1701107=GEH5 C9275269=1270=644.5271=75273=181250000336=2346=11023=2279=022=848=81378183=1700107=GEH5 C9300269=1270=619271=75273=181250000336=2346=11023=1279=222=848=81378183=1701107=GEH5 C9300269=1270=619.5271=75273=181250000336=2346=11023=2279=022=848=69003883=1700107=GEH5 C9325269=1270=594271=75273=181250000336=2346=11023=1279=222=848=69003883=1701107=GEH5 C9325269=1270=594.5271=75273=181250000336=2346=11023=2279=022=848=22104483=1692107=GEH5 C9350269=1270=569271=75273=181250000336=2346=11023=1279=222=848=22104483=1693107=GEH5 C9350269=1270=569.5271=75273=181250000336=2346=11023=2279=022=848=42903383=1684107=GEH5 C9375269=1270=544271=75273=181250000336=2346=11023=1279=222=848=42903383=1685107=GEH5 C9375269=1270=544.5271=75273=181250000336=2346=11023=2279=022=848=28285883=1680107=GEH5 C9400269=1270=519271=75273=181250000336=2346=11023=1279=222=848=28285883=1681107=GEH5 C9400269=1270=519.5271=75273=181250000336=2346=11023=2279=022=848=47804683=1362107=GEH5 C9600269=1270=320.5271=75273=181250000336=2346=11023=1279=222=848=47804683=1363107=GEH5 C9600269=1270=321271=75273=181250000336=2346=11023=2279=022=848=88240983=1673107=GEH5 C9425269=1270=494271=75273=181250000336=2346=11023=1279=222=848=88240983=1674107=GEH5 C9425269=1270=494.5271=75273=181250000336=2346=11023=2279=022=848=66100483=1617107=GEH5 C9450269=1270=469271=75273=181250000336=2346=11023=1279=222=848=66100483=1618107=GEH5 C9450269=1270=469.5271=75273=181250000336=2346=11023=2279=022=848=82053483=1653107=GEH5 C9475269=1270=444.5271=75273=181250000336=2346=11023=1279=222=848=82053483=1654107=GEH5 C9475269=1270=445271=75273=181250000336=2346=11023=2279=022=848=33797983=1466107=GEH5 C9625269=1270=296271=75273=181250000336=2346=11023=1279=222=848=33797983=1467107=GEH5 C9625269=1270=296.5271=75273=181250000336=2346=11023=2279=022=848=8373583=1649107=GEH5 C9500269=1270=419.5271=75273=181250000336=2346=11023=1279=222=848=8373583=1650107=GEH5 C9500269=1270=420271=75273=181250000336=2346=11023=2279=022=848=40660783=1889107=GEH5 C9862269=1270=75271=150273=181250000336=2346=11023=1279=122=848=40660783=1890107=GEH5 C9862269=1270=75.5271=100273=181250000336=2346=11023=2279=022=848=4430783=1497107=GEH5 C9525269=1270=394.5271=75273=181250000336=2346=11023=1279=222=848=4430783=1498107=GEH5 C9525269=1270=395271=75273=181250000336=2346=11023=2279=022=848=34473283=1645107=GEH5 C9550269=1270=370271=75273=181250000336=2346=11023=1279=222=848=34473283=1646107=GEH5 C9550269=1270=370.5271=75273=181250000336=2346=11023=2279=022=848=10624283=1565107=GEH5 C9575269=1270=345.5271=75273=181250000336=2346=11023=1279=222=848=10624283=1566107=GEH5 C9575269=1270=346271=75273=181250000336=2346=11023=2279=022=848=62816183=1302107=GEH5 C9650269=1270=272271=75273=181250000336=2346=11023=1279=222=848=62816183=1303107=GEH5 C9650269=1270=272.5271=75273=181250000336=2346=11023=2279=022=848=85323383=1560107=GEH5 C9675269=1270=247.5271=75273=181250000336=2346=11023=1279=222=848=85323383=1561107=GEH5 C9675269=1270=248271=75273=181250000336=2346=11023=2279=022=848=60573483=1588107=GEH5 C9687269=1270=235.5271=75273=181250000336=2346=11023=1279=222=848=60573483=1589107=GEH5 C9687269=1270=236271=75273=181250000336=2346=11023=2279=022=848=30528983=2054107=GEH5 C9875269=1270=65271=150273=181250000336=2346=11023=1279=122=848=30528983=2055107=GEH5 C9875269=1270=65.5271=100273=181250000336=2346=11023=2279=022=848=29853883=1496107=GEH5 C9700269=1270=223.5271=75273=181250000336=2346=11023=1279=222=848=29853883=1497107=GEH5 C9700269=1270=224271=75273=181250000336=2346=11023=2279=022=848=2319483=1474107=GEH5 C9712269=1270=211.5271=75273=181250000336=2346=11023=1279=222=848=2319483=1475107=GEH5 C9712269=1270=212271=75273=181250000336=2346=11023=210=097
1128=99=331835=X49=CME34=28081352=2013071516460906275=20130715268=33279=022=848=65225983=812107=GEU4 C9812269=0270=133271=100273=164609000336=2346=11023=1279=122=848=65225983=813107=GEU4 C9812269=0270=132.5271=75273=164609000336=2346=11023=2279=022=848=38558383=797107=GEU4 C9787269=0270=157271=100273=164609000336=2346=11023=1279=122=848=38558383=798107=GEU4 C9787269=0270=156.5271=75273=164609000336=2346=11023=2279=022=848=50150483=805107=GEU4 C9800269=0270=145271=100273=164609000336=2346=11023=1279=122=848=50150483=806107=GEU4 C9800269=0270=144.5271=75273=164609000336=2346=11023=2279=022=848=30912183=1195107=GEU4 C9850269=0270=97.5271=100273=164609000336=2346=11023=1279=122=848=30912183=1196107=GEU4 C9850269=0270=97271=192273=164609000336=2346=21023=2279=022=848=26751483=1015107=GEU4 C9862269=0270=86271=100273=164609000336=2346=11023=1279=122=848=26751483=1016107=GEU4 C9862269=0270=85.5271=182273=164609000336=2346=21023=2279=022=848=63875283=1251107=GEU4 C9887269=0270=63.5271=100273=164609000336=2346=11023=1279=122=848=63875283=1252107=GEU4 C9887269=0270=63271=182273=164609000336=2346=21023=2279=022=848=63199683=1134107=GEU4 C9900269=0270=52.5271=100273=164609000336=2346=11023=1279=122=848=63199683=1135107=GEU4 C9900269=0270=52271=222273=164609000336=2346=21023=2279=022=848=48015183=1094107=GEU4 C9912269=0270=42271=100273=164609000336=2346=11023=1279=122=848=48015183=1095107=GEU4 C9912269=0270=41.5271=297273=164609000336=2346=21023=2279=022=848=28101983=694107=GEU4 C9575269=0270=366.5271=50273=164609000336=2346=11023=1279=122=848=28101983=695107=GEU4 C9575269=0270=366271=75273=164609000336=2346=11023=2279=022=848=82437483=1034107=GEU4 C9625269=0270=317271=50273=164609000336=2346=11023=1279=122=848=82437483=1035107=GEU4 C9625269=0270=316.5271=75273=164609000336=2346=11023=2279=022=848=59714083=587107=GEU4 C9650269=0270=292271=50273=164609000336=2346=11023=1279=122=848=59714083=588107=GEU4 C9650269=0270=291.5271=75273=164609000336=2346=11023=2279=022=848=43962583=1062107=GEU4 C9675269=0270=267.5271=50273=164609000336=2346=11023=1279=122=848=43962583=1063107=GEU4 C9675269=0270=267271=75273=164609000336=2346=11023=2279=022=848=19213083=759107=GEU4 C9687269=0270=255271=50273=164609000336=2346=11023=1279=122=848=19213083=760107=GEU4 C9687269=0270=254.5271=75273=164609000336=2346=11023=2279=022=848=37775283=1011107=GEU4 C9712269=0270=230.5271=50273=164609000336=2346=11023=1279=122=848=37775283=1012107=GEU4 C9712269=0270=230271=75273=164609000336=2346=11023=2279=022=848=21239383=596107=GEU4 C9725269=0270=218271=50273=164609000336=2346=11023=1279=122=848=21239383=597107=GEU4 C9725269=0270=217.5271=75273=164609000336=2346=11023=2279=022=848=88624883=605107=GEU4 C9750269=0270=193.5271=50273=164609000336=2346=11023=1279=122=848=88624883=606107=GEU4 C9750269=0270=193271=75273=164609000336=2346=11023=2279=122=848=31721683=1033107=GEU4 P9900269=1270=11.5271=1087273=164609000336=2346=41023=110=084
1128=99=501335=X49=CME34=19197652=2013071514321832275=20130715268=50279=122=848=84740383=909107=GEZ4 C9725269=1270=211.5271=100273=143218000336=2346=21023=1279=122=848=39402183=928107=GEZ4 C9787269=0270=149271=233273=143218000336=2346=31023=1279=122=848=39402183=929107=GEZ4 C9787269=1270=151.5271=250273=143218000336=2346=31023=1279=122=848=53128783=1084107=GEZ4 C9800269=0270=137271=233273=143218000336=2346=31023=1279=122=848=53128783=1085107=GEZ4 C9800269=1270=139.5271=200273=143218000336=2346=31023=1279=122=848=84066783=1550107=GEZ4 P9925269=0270=22.5271=200273=143218000336=2346=21023=2279=122=848=84066783=1551107=GEZ4 P9925269=0270=22271=500273=143218000336=2346=11023=3279=122=848=84066783=1552107=GEZ4 P9925269=1270=24.5271=500273=143218000336=2346=21023=2279=022=848=84066783=1553107=GEZ4 P9925269=1270=25271=100273=143218000336=2346=11023=3279=122=848=69664283=1087107=GEZ4 C9912269=0270=39271=167273=143218000336=2346=21023=1279=022=848=69664283=1088107=GEZ4 C9912269=0270=38.5271=100273=143218000336=2346=11023=2279=122=848=69664283=1089107=GEZ4 C9912269=1270=41271=200273=143218000336=2346=21023=2279=222=848=69664283=1090107=GEZ4 C9912269=1270=41.5271=100273=143218000336=2346=11023=3279=122=848=4525583=902107=GEZ4 C9812269=0270=125.5271=233273=143218000336=2346=31023=1279=122=848=4525583=903107=GEZ4 C9812269=1270=128271=250273=143218000336=2346=31023=1279=122=848=78552983=1061107=GEZ4 C9825269=0270=114271=167273=143218000336=2346=21023=1279=022=848=78552983=1062107=GEZ4 C9825269=0270=113.5271=50273=143218000336=2346=11023=2279=122=848=78552983=1063107=GEZ4 C9825269=1270=116271=107273=143218000336=2346=21023=1279=122=848=78552983=1064107=GEZ4 C9825269=1270=116.5271=100273=143218000336=2346=11023=2279=122=848=59315083=1425107=GEZ4 C9837269=0270=102.5271=233273=143218000336=2346=31023=1279=122=848=59315083=1426107=GEZ4 C9837269=1270=104.5271=107273=143218000336=2346=21023=1279=122=848=59315083=1427107=GEZ4 C9837269=1270=105271=100273=143218000336=2346=11023=2279=122=848=87658983=1398107=GEZ4 P9912269=0270=19.5271=300273=143218000336=2346=31023=1279=122=848=87658983=1399107=GEZ4 P9912269=0270=19271=500273=143218000336=2346=11023=2279=122=848=87658983=1400107=GEZ4 P9912269=1270=21.5271=553273=143218000336=2346=21023=2279=022=848=87658983=1401107=GEZ4 P9912269=1270=22271=100273=143218000336=2346=11023=3279=122=848=25677583=2126107=GEZ4 P9900269=0270=17271=300273=143218000336=2346=31023=1279=122=848=25677583=2127107=GEZ4 P9900269=0270=16.5271=500273=143218000336=2346=11023=2279=122=848=25677583=2128107=GEZ4 P9900269=1270=18.5271=915273=143218000336=2346=31023=1279=022=848=25677583=2129107=GEZ4 P9900269=1270=19271=100273=143218000336=2346=11023=2279=122=848=62233683=2379107=GEZ4 C9925269=1270=31.5271=700273=143218000336=2346=31023=2279=222=848=62233683=2380107=GEZ4 C9925269=1270=32271=100273=143218000336=2346=11023=3279=122=848=66177783=1366107=GEZ4 C9850269=0270=91.5271=167273=143218000336=2346=21023=1279=022=848=66177783=1367107=GEZ4 C9850269=0270=90.5271=50273=143218000336=2346=11023=2279=122=848=66177783=1368107=GEZ4 C9850269=1270=93.5271=250273=143218000336=2346=31023=1279=122=848=83496983=1522107=GEZ4 P9950269=0270=31271=250273=143218000336=2346=31023=1279=222=848=83496983=1523107=GEZ4 P9950269=0270=30.5271=50273=143218000336=2346=11023=2279=022=848=83496983=1524107=GEZ4 P9950269=0270=1271=8273=143218000336=2346=21023=3279=122=848=83496983=1525107=GEZ4 P9950269=1270=33271=167273=143218000336=2346=21023=1279=022=848=83496983=1526107=GEZ4 P9950269=1270=33.5271=50273=143218000336=2346=11023=2279=122=848=10714983=1435107=GEZ4 C9862269=0270=80271=233273=143218000336=2346=31023=1279=122=848=10714983=1436107=GEZ4 C9862269=1270=82271=107273=143218000336=2346=21023=1279=222=848=10714983=1437107=GEZ4 C9862269=1270=83271=50273=143218000336=2346=11023=3279=122=848=33890283=2736107=GEZ4 C9937269=0270=21271=300273=143218000336=2346=31023=1279=122=848=33890283=2737107=GEZ4 C9937269=1270=22.5271=533273=143218000336=2346=21023=1279=122=848=33890283=2738107=GEZ4 C9937269=1270=23271=600273=143218000336=2346=21023=2279=122=848=13981783=1216107=GEZ4 C9875269=0270=69.5271=167273=143218000336=2346=21023=1279=022=848=13981783=1217107=GEZ4 C9875269=0270=69271=100273=143218000336=2346=11023=2279=122=848=13981783=1218107=GEZ4 C9875269=1270=71.5271=333273=143218000336=2346=31023=1279=122=848=1924783=1067107=GEZ4 P9887269=1270=16.5271=1133273=143218000336=2346=41023=110=196
1128=99=152335=X49=CME34=3489552=2013071510265825275=20130715268=15279=222=848=33890283=846107=GEZ4 C9937269=0270=20.5271=500273=102658000336=2346=11023=1279=122=848=33890283=847107=GEZ4 C9937269=0270=20271=650273=102658000336=2346=21023=1279=022=848=33890283=848107=GEZ4 C9937269=0270=2271=12273=102658000336=2346=31023=3279=222=848=62233683=637107=GEZ4 C9925269=0270=29271=500273=102658000336=2346=11023=1279=122=848=62233683=638107=GEZ4 C9925269=0270=28.5271=650273=102658000336=2346=21023=1279=222=848=43671583=542107=GEZ4 P9787269=1270=7271=500273=102658000336=2346=11023=1279=122=848=43671583=543107=GEZ4 P9787269=1270=7.5271=650273=102658000336=2346=21023=1279=222=848=12739883=546107=GEZ4 P9825269=1270=9.5271=500273=102658000336=2346=11023=1279=122=848=12739883=547107=GEZ4 P9825269=1270=10271=650273=102658000336=2346=21023=1279=222=848=38726583=546107=GEZ4 P9837269=1270=10.5271=500273=102658000336=2346=11023=1279=122=848=38726583=547107=GEZ4 P9837269=1270=11271=650273=102658000336=2346=21023=1279=222=848=70448783=546107=GEZ4 P9650269=1270=2.5271=500273=102658000336=2346=11023=1279=022=848=70448783=547107=GEZ4 P9650269=1270=3271=500273=102658000336=2346=11023=1279=222=848=25677583=627107=GEZ4 P9900269=1270=19271=500273=102658000336=2346=11023=1279=122=848=25677583=628107=GEZ4 P9900269=1270=19.5271=650273=102658000336=2346=21023=110=033
1128=99=25535=X49=CME34=33157452=2013071518151598175=20130715268=2279=122=848=2150383=688107=GEU3 P9550269=1270=0.5271=51273=181515000336=2346=21023=1279=122=848=2150383=689107=GEU3 P9550269=1270=0.75271=550273=181515000336=2346=21023=210=219
1128=99=10435=f49=CME34=1079252=2013071418013515322=848=3746675=20130715107=GEM5 C9850332=9999900333=0.2510=092
1128=99=276335=X49=CME34=3937952=2013071511475489875=20130715268=28279=022=848=83577283=30107=GEU3 P9862269=1270=1271=200273=114754000336=2346=11023=2279=122=848=52851983=46107=GEU4 P9762269=0270=1.5271=300273=114754000336=2346=21023=1279=122=848=52851983=47107=GEU4 P9762269=1270=4271=300273=114754000336=2346=21023=2279=122=848=80957483=146107=GEH4 P9837269=0270=0.5271=850273=114754000336=2346=31023=1279=022=848=80957483=147107=GEH4 P9837269=1270=2.5271=200273=114754000336=2346=11023=2279=022=848=30024583=30107=GEU3 P9850269=1270=1271=200273=114754000336=2346=11023=2279=122=848=8974983=40107=GEZ3 P9875269=1270=1.5271=800273=114754000336=2346=31023=1279=122=848=80807783=80107=GEZ4 P9712269=0270=2.5271=250273=114754000336=2346=21023=1279=022=848=80807783=81107=GEZ4 P9712269=1270=5271=150273=114754000336=2346=11023=2279=022=848=76039183=30107=GEU3 P9837269=1270=1271=200273=114754000336=2346=11023=2279=022=848=81977883=34107=GEZ3 P9825269=1270=1.25271=200273=114754000336=2346=11023=2279=022=848=77708683=34107=GEZ3 P9837269=1270=1.5271=200273=114754000336=2346=11023=3279=022=848=40584783=34107=GEZ3 P9812269=1270=1.25271=200273=114754000336=2346=11023=2279=022=848=41260483=37107=GEZ3 P9850269=1270=1.5271=200273=114754000336=2346=11023=2279=122=848=46105783=34107=GEZ3 P9800269=1270=1.25271=250273=114754000336=2346=21023=2279=022=848=80410883=34107=GEZ3 P9862269=1270=1.75271=200273=114754000336=2346=11023=3279=022=848=13673983=34107=GEZ3 P9787269=1270=1.25271=200273=114754000336=2346=11023=3279=022=848=85922683=34107=GEZ3 P9775269=1270=1.25271=200273=114754000336=2346=11023=3279=122=848=37484883=160107=GEZ4 P9700269=0270=2271=750273=114754000336=2346=31023=2279=022=848=37484883=161107=GEZ4 P9700269=1270=4.5271=150273=114754000336=2346=11023=2279=022=848=67360383=34107=GEZ3 P9762269=1270=1.25271=200273=114754000336=2346=11023=3279=122=848=6974083=192107=GEM4 P9800269=0270=1271=800273=114754000336=2346=31023=1279=022=848=6974083=193107=GEM4 P9800269=1270=3.5271=200273=114754000336=2346=11023=3279=022=848=84571783=34107=GEZ3 P9750269=1270=1271=200273=114754000336=2346=11023=2279=022=848=82226883=30107=GEU3 P9825269=1270=1271=200273=114754000336=2346=11023=2279=022=848=52148883=34107=GEZ3 P9737269=1270=1271=200273=114754000336=2346=11023=2279=022=848=79735183=34107=GEZ3 P9725269=1270=1271=200273=114754000336=2346=11023=2279=022=848=11215983=34107=GEZ3 P9700269=1270=1271=200273=114754000336=2346=11023=210=066
1128=99=19235=X49=CME34=2414752=2013071420095414475=20130712268=2279=022=848=3746683=2107=GEM5 C9850269=B271=0273=200954000279=022=848=3746683=3107=GEM5 C9850269=C271=1273=20095400010=134
1128=99=25435=X49=CME34=12513452=2013071513191501675=20130715268=2279=122=848=2150383=262107=GEU3 P9550269=1270=0.5271=1273=131915000336=2346=11023=1279=122=848=2150383=263107=GEU3 P9550269=1270=0.75271=600273=131915000336=2346=31023=210=116
1128=99=123335=X49=CME34=11488852=2013071513044108275=20130715268=12279=122=848=43579483=765107=GEH5 C9775269=0270=150271=125273=130441000336=2346=21023=1279=222=848=43579483=766107=GEH5 C9775269=0270=149.5271=50273=130441000336=2346=11023=2279=222=848=43579483=767107=GEH5 C9775269=1270=153271=50273=130441000336=2346=11023=1279=022=848=43579483=768107=GEH5 C9775269=1270=158271=75273=130441000336=2346=11023=2279=122=848=2866183=661107=GEH5 C9800269=0270=127271=125273=130441000336=2346=21023=1279=222=848=2866183=662107=GEH5 C9800269=0270=126.5271=50273=130441000336=2346=11023=2279=222=848=2866183=663107=GEH5 C9800269=1270=130271=50273=130441000336=2346=11023=1279=022=848=2866183=664107=GEH5 C9800269=1270=135271=75273=130441000336=2346=11023=2279=122=848=24341283=803107=GEH5 C9725269=0270=197271=125273=130441000336=2346=21023=1279=222=848=24341283=804107=GEH5 C9725269=0270=196.5271=50273=130441000336=2346=11023=2279=222=848=24341283=805107=GEH5 C9725269=1270=200271=50273=130441000336=2346=11023=1279=022=848=24341283=806107=GEH5 C9725269=1270=204.5271=75273=130441000336=2346=11023=210=155
1128=99=14235=X49=CME34=1079152=2013071418013515375=20130715268=1279=022=848=3746664=2013071283=1107=GEM5 C9850269=6270=74.25273=18013500010=025
1128=99=15835=X49=CME34=23716852=2013071515424218075=20130715268=1279=122=848=27027983=977107=GEZ4 P9800269=0270=6271=1167273=154242000336=2346=41023=110=005
1128=99=19035=X49=CME34=2719752=2013071506094363175=20130712268=2279=022=848=3746683=4107=GEM5 C9850269=B271=0273=60943000279=022=848=3746683=5107=GEM5 C9850269=C271=1273=6094300010=056
1128=99=25435=X49=CME34=33164352=2013071518151610975=20130715268=2279=122=848=2150383=690107=GEU3 P9550269=1270=0.5271=1273=181516000336=2346=11023=1279=122=848=2150383=691107=GEU3 P9550269=1270=0.75271=600273=181516000336=2346=31023=210=139
1128=99=65135=X49=CME34=10179552=2013071512470654175=20130715268=6279=122=848=11386283=1347107=GEZ4 P9937269=1270=27.5271=503273=124706000336=2346=21023=1279=122=848=11386283=1348107=GEZ4 P9937269=1270=28271=600273=124706000336=2346=21023=2279=122=848=62233683=1822107=GEZ4 C9925269=0270=30271=625273=124706000336=2346=31023=1279=022=848=62233683=1823107=GEZ4 C9925269=0270=29.5271=500273=124706000336=2346=11023=2279=122=848=27027983=511107=GEZ4 P9800269=1270=7.5271=465273=124706000336=2346=31023=1279=022=848=27027983=512107=GEZ4 P9800269=1270=8271=500273=124706000336=2346=11023=210=048
1128=99=103835=X49=CME34=31154052=2013071517385469875=20130715268=10279=222=848=59313883=1308107=GEM5 C9837269=1270=88271=75273=173854000336=2346=11023=1279=022=848=59313883=1309107=GEM5 C9837269=1270=88.5271=75273=173854000336=2346=11023=1279=022=848=43560983=1108107=GEM5 C9825269=0270=93.5271=75273=173854000336=2346=11023=1279=222=848=43560983=1109107=GEM5 C9825269=0270=93271=75273=173854000336=2346=11023=2279=222=848=43560983=1110107=GEM5 C9825269=1270=98.5271=75273=173854000336=2346=11023=1279=022=848=43560983=1111107=GEM5 C9825269=1270=99271=75273=173854000336=2346=11023=1279=222=848=5616483=2622107=GEM5 P9912269=0270=41271=75273=173854000336=2346=11023=2279=022=848=5616483=2623107=GEM5 P9912269=0270=40.5271=75273=173854000336=2346=11023=2279=222=848=3746683=1398107=GEM5 C9850269=1270=78271=75273=173854000336=2346=11023=1279=022=848=3746683=1399107=GEM5 C9850269=1270=78.5271=75273=173854000336=2346=11023=110=001
