1128=99=10535=f49=CME34=1835452=2013071418021272922=848=10216675=20130715107=GEH4 P0100332=9999900333=0.2510=124
1128=99=14335=X49=CME34=2238952=2013071418023267675=20130715268=1279=022=848=10714964=2013071283=1107=GEZ4 C9862269=6270=79.75273=18023200010=107
1128=99=14135=X49=CME34=1859552=2013071418021392175=20130715268=1279=022=848=10275964=2013071283=1107=GEZ5 P0300269=6270=450273=18021300010=237
1128=99=10535=f49=CME34=1786852=2013071418021048422=848=10189475=20130715107=GEH4 P0375332=9999900333=0.2510=150
1128=99=15435=X49=CME34=2304852=2013071419000586275=20130624268=1279=022=848=11433683=2107=GEZ5 P9325269=0270=0.5271=1273=190005000336=0346=11023=110=004
1128=99=19635=X49=CME34=2400452=2013071420095329175=20130712268=2279=022=848=10324083=2107=GEM4 P9825269=B271=0273=200953000279=022=848=10324083=3107=GEM4 P9825269=C271=954273=20095300010=079
1128=99=13935=X49=CME34=2037152=2013071418022185475=20130715268=1279=022=848=10432564=2013071283=1107=GEZ3 C9975269=6270=1273=18022100010=131
1128=99=14335=X49=CME34=944152=2013071418012887475=20130715268=1279=022=848=11291364=2013071283=1107=GEH5 C9825269=6270=104.75273=18012800010=075
1128=99=14035=X49=CME34=1710552=2013071418020702475=20130715268=1279=022=848=10036164=2013071283=1107=GEZ4 P0012269=6270=82273=18020700010=161
1128=99=13935=X49=CME34=1117952=2013071418013729475=20130715268=1279=022=848=11215964=2013071283=1107=GEZ3 P9700269=6270=0273=18013700010=149
1128=99=25535=X49=CME34=11991152=2013071513113509275=20130715268=2279=022=848=37100783=89107=GEM4 P9962269=0270=15271=125273=131135000336=2346=11023=1279=222=848=37100783=90107=GEM4 P9962269=0270=14.5271=125273=131135000336=2346=11023=210=182
1128=99=200435=X49=CME34=15492852=2013071513503454675=20130715268=20279=022=848=78551783=858107=GEM5 C9550269=1270=355271=7273=135034000336=2346=11023=1279=222=848=78551783=859107=GEM5 C9550269=1270=355.5271=7273=135034000336=2346=11023=2279=022=848=11949383=652107=GEM5 C9575269=1270=330.5271=7273=135034000336=2346=11023=1279=222=848=11949383=653107=GEM5 C9575269=1270=331271=7273=135034000336=2346=11023=2279=022=848=36022783=816107=GEM5 C9600269=1270=306.5271=7273=135034000336=2346=11023=1279=222=848=36022783=817107=GEM5 C9600269=1270=307271=7273=135034000336=2346=11023=2279=122=848=65500483=578107=GEM5 P9800269=0270=16271=575273=135034000336=2346=21023=1279=222=848=65500483=579107=GEM5 P9800269=0270=15.5271=75273=135034000336=2346=11023=2279=022=848=14003383=668107=GEM5 C9625269=1270=282271=7273=135034000336=2346=11023=1279=222=848=14003383=669107=GEM5 C9625269=1270=282.5271=7273=135034000336=2346=11023=2279=022=848=31862183=746107=GEM5 C9650269=1270=258271=7273=135034000336=2346=11023=1279=222=848=31862183=747107=GEM5 C9650269=1270=258.5271=7273=135034000336=2346=11023=2279=022=848=87547883=834107=GEM5 C9675269=1270=234.5271=7273=135034000336=2346=11023=1279=222=848=87547883=835107=GEM5 C9675269=1270=235271=7273=135034000336=2346=11023=2279=022=848=25674883=748107=GEM5 C9725269=1270=187.5271=7273=135034000336=2346=11023=1279=222=848=25674883=749107=GEM5 C9725269=1270=188271=7273=135034000336=2346=11023=2279=022=848=67915383=766107=GEM5 C9737269=1270=176271=7273=135034000336=2346=11023=1279=222=848=67915383=767107=GEM5 C9737269=1270=176.5271=7273=135034000336=2346=11023=2279=022=848=30078683=558107=GEM5 P9775269=0270=13271=75273=135034000336=2346=11023=1279=122=848=30078683=559107=GEM5 P9775269=0270=12.5271=500273=135034000336=2346=11023=210=153
1128=99=25335=X49=CME34=6597552=2013071512304789175=20130715268=2279=122=848=38742583=117107=GEH5 P9675269=1270=6271=150273=123047000336=2346=11023=1279=022=848=38742583=118107=GEH5 P9675269=1270=6.5271=41273=123047000336=2346=11023=210=116
1128=99=25735=X49=CME34=34885852=2013071518521175775=20130715268=2279=022=848=37100783=305107=GEM4 P9962269=0270=15271=125273=185211000336=2346=11023=1279=222=848=37100783=306107=GEM4 P9962269=0270=14.5271=125273=185211000336=2346=11023=210=049
1128=99=26035=X49=CME34=23914852=2013071515462489075=20130715268=2279=222=848=24341283=2174107=GEH5 C9725269=1270=199271=20273=154624000336=2346=11023=1279=122=848=24341283=2175107=GEH5 C9725269=1270=199.5271=101273=154624000336=2346=21023=110=174
1128=99=44835=X49=CME34=19055352=2013071514313037575=20130715268=4279=222=848=64843083=681107=GEH5 P9787269=0270=9271=150273=143130000336=2346=11023=1279=022=848=64843083=682107=GEH5 P9787269=0270=8.5271=150273=143130000336=2346=11023=1279=022=848=38742583=399107=GEH5 P9675269=1270=5.5271=150273=143130000336=2346=11023=2279=122=848=38742583=400107=GEH5 P9675269=1270=6271=20273=143130000336=2346=11023=310=096
1128=99=25735=X49=CME34=16351252=2013071514013721675=20130715268=2279=222=848=37100783=177107=GEM4 P9962269=1270=21.5271=125273=140137000336=2346=11023=1279=022=848=37100783=178107=GEM4 P9962269=1270=22271=125273=140137000336=2346=11023=110=026
1128=99=460735=X49=CME34=23001652=2013071515262431175=20130715268=46279=122=848=72272783=1829107=GEH5 C9850269=1270=85.5271=80273=152624000336=2346=11023=1279=022=848=72272783=1830107=GEH5 C9850269=1270=86271=150273=152624000336=2346=11023=2279=222=848=4430783=1125107=GEH5 C9525269=1270=394.5271=75273=152624000336=2346=11023=1279=022=848=4430783=1126107=GEH5 C9525269=1270=395271=75273=152624000336=2346=11023=1279=222=848=36716183=1286107=GEH5 C9275269=1270=644271=75273=152624000336=2346=11023=1279=022=848=36716183=1287107=GEH5 C9275269=1270=644.5271=75273=152624000336=2346=11023=1279=222=848=81378183=1286107=GEH5 C9300269=1270=619271=75273=152624000336=2346=11023=1279=022=848=81378183=1287107=GEH5 C9300269=1270=619.5271=75273=152624000336=2346=11023=1279=222=848=69003883=1286107=GEH5 C9325269=1270=594271=75273=152624000336=2346=11023=1279=022=848=69003883=1287107=GEH5 C9325269=1270=594.5271=75273=152624000336=2346=11023=1279=222=848=22104483=1278107=GEH5 C9350269=1270=569271=75273=152624000336=2346=11023=1279=022=848=22104483=1279107=GEH5 C9350269=1270=569.5271=75273=152624000336=2346=11023=1279=222=848=42903383=1270107=GEH5 C9375269=1270=544271=75273=152624000336=2346=11023=1279=022=848=42903383=1271107=GEH5 C9375269=1270=544.5271=75273=152624000336=2346=11023=1279=222=848=28285883=1270107=GEH5 C9400269=1270=519271=75273=152624000336=2346=11023=1279=022=848=28285883=1271107=GEH5 C9400269=1270=519.5271=75273=152624000336=2346=11023=1279=222=848=47804683=1048107=GEH5 C9600269=1270=320.5271=75273=152624000336=2346=11023=1279=022=848=47804683=1049107=GEH5 C9600269=1270=321271=75273=152624000336=2346=11023=1279=222=848=88240983=1267107=GEH5 C9425269=1270=494271=75273=152624000336=2346=11023=1279=022=848=88240983=1268107=GEH5 C9425269=1270=494.5271=75273=152624000336=2346=11023=1279=222=848=66100483=1211107=GEH5 C9450269=1270=469271=75273=152624000336=2346=11023=1279=022=848=66100483=1212107=GEH5 C9450269=1270=469.5271=75273=152624000336=2346=11023=1279=222=848=33797983=1132107=GEH5 C9625269=1270=296271=75273=152624000336=2346=11023=1279=022=848=33797983=1133107=GEH5 C9625269=1270=296.5271=75273=152624000336=2346=11023=1279=222=848=82053483=1247107=GEH5 C9475269=1270=444.5271=75273=152624000336=2346=11023=1279=022=848=82053483=1248107=GEH5 C9475269=1270=445271=75273=152624000336=2346=11023=1279=222=848=8373583=1247107=GEH5 C9500269=1270=419.5271=75273=152624000336=2346=11023=1279=022=848=8373583=1248107=GEH5 C9500269=1270=420271=75273=152624000336=2346=11023=1279=222=848=34473283=1243107=GEH5 C9550269=1270=370271=75273=152624000336=2346=11023=1279=022=848=34473283=1244107=GEH5 C9550269=1270=370.5271=75273=152624000336=2346=11023=1279=222=848=10624283=1167107=GEH5 C9575269=1270=345.5271=75273=152624000336=2346=11023=1279=022=848=10624283=1168107=GEH5 C9575269=1270=346271=75273=152624000336=2346=11023=1279=222=848=30528983=1648107=GEH5 C9875269=1270=65271=150273=152624000336=2346=11023=1279=122=848=30528983=1649107=GEH5 C9875269=1270=65.5271=250273=152624000336=2346=21023=1279=222=848=62816183=980107=GEH5 C9650269=1270=272271=75273=152624000336=2346=11023=1279=022=848=62816183=981107=GEH5 C9650269=1270=272.5271=75273=152624000336=2346=11023=1279=222=848=85323383=1162107=GEH5 C9675269=1270=247.5271=75273=152624000336=2346=11023=1279=022=848=85323383=1163107=GEH5 C9675269=1270=248271=75273=152624000336=2346=11023=1279=222=848=60573483=1190107=GEH5 C9687269=1270=235.5271=75273=152624000336=2346=11023=1279=022=848=60573483=1191107=GEH5 C9687269=1270=236271=75273=152624000336=2346=11023=1279=222=848=29853883=1114107=GEH5 C9700269=1270=223.5271=75273=152624000336=2346=11023=1279=022=848=29853883=1115107=GEH5 C9700269=1270=224271=75273=152624000336=2346=11023=1279=222=848=2319483=1092107=GEH5 C9712269=1270=211.5271=75273=152624000336=2346=11023=1279=022=848=2319483=1093107=GEH5 C9712269=1270=212271=75273=152624000336=2346=11023=1279=122=848=24341283=2074107=GEH5 C9725269=1270=199.5271=50273=152624000336=2346=11023=1279=022=848=24341283=2075107=GEH5 C9725269=1270=200271=75273=152624000336=2346=11023=210=225
1128=99=10535=f49=CME34=1985052=2013071418021970722=848=18252275=20130715107=GEZ4 P9737332=9999900333=0.2510=176
1128=99=54835=X49=CME34=11016052=2013071512574342375=20130715268=5279=122=848=8756483=464107=GEM4 C9875269=0270=79.5271=250273=125743000336=2346=31023=1279=222=848=8756483=465107=GEM4 C9875269=0270=76.5271=125273=125743000336=2346=11023=2279=222=848=87273483=231107=GEM4 P9725269=0270=0.5271=17273=125743000336=2346=11023=1279=222=848=37100783=63107=GEM4 P9962269=1270=21271=125273=125743000336=2346=11023=1279=022=848=37100783=64107=GEM4 P9962269=1270=21.5271=125273=125743000336=2346=11023=110=231
1128=99=16035=X49=CME34=35008852=2013071518575483475=20130715268=1279=122=848=1924783=1656107=GEZ4 P9887269=0270=14.5271=300273=185754000336=2346=31023=110=116
1128=99=180935=X49=CME34=14344252=2013071513375870875=20130715268=18279=222=848=14003383=618107=GEM5 C9625269=0270=275.5271=7273=133758000336=2346=11023=1279=022=848=14003383=619107=GEM5 C9625269=0270=275271=7273=133758000336=2346=11023=1279=222=848=87547883=782107=GEM5 C9675269=0270=227.5271=7273=133758000336=2346=11023=1279=022=848=87547883=783107=GEM5 C9675269=0270=227271=7273=133758000336=2346=11023=1279=222=848=88898983=594107=GEM5 C9700269=0270=204271=7273=133758000336=2346=11023=1279=022=848=88898983=595107=GEM5 C9700269=0270=203.5271=7273=133758000336=2346=11023=1279=122=848=20191983=741107=GEM5 C9937269=0270=15.5271=500273=133758000336=2346=11023=1279=022=848=20191983=742107=GEM5 C9937269=0270=15271=75273=133758000336=2346=11023=2279=222=848=25674883=688107=GEM5 C9725269=0270=180.5271=7273=133758000336=2346=11023=1279=022=848=25674883=689107=GEM5 C9725269=0270=180271=7273=133758000336=2346=11023=1279=222=848=67915383=718107=GEM5 C9737269=0270=169271=7273=133758000336=2346=11023=1279=022=848=67915383=719107=GEM5 C9737269=0270=168.5271=7273=133758000336=2346=11023=1279=222=848=32555383=320107=GEH5 P9737269=1270=8271=150273=133758000336=2346=11023=2279=122=848=32555383=321107=GEH5 P9737269=1270=8.5271=155273=133758000336=2346=21023=2279=022=848=38742583=272107=GEH5 P9675269=0270=3.5271=150273=133758000336=2346=11023=1279=222=848=38742583=273107=GEH5 P9675269=0270=3271=150273=133758000336=2346=11023=2279=222=848=38742583=274107=GEH5 P9675269=1270=5.5271=150273=133758000336=2346=11023=2279=122=848=38742583=275107=GEH5 P9675269=1270=6271=161273=133758000336=2346=21023=210=113
1128=99=153135=X49=CME34=9615352=2013071512435292675=20130715268=15279=122=848=33890283=2199107=GEZ4 C9937269=0270=21.5271=167273=124352000336=2346=21023=1279=122=848=33890283=2200107=GEZ4 C9937269=0270=21271=600273=124352000336=2346=21023=2279=122=848=1924783=688107=GEZ4 P9887269=0270=14.5271=260273=124352000336=2346=21023=1279=122=848=1924783=689107=GEZ4 P9887269=0270=14271=600273=124352000336=2346=21023=2279=122=848=1924783=690107=GEZ4 P9887269=1270=16271=300273=124352000336=2346=31023=1279=122=848=11386283=1228107=GEZ4 P9937269=1270=27.5271=83273=124352000336=2346=21023=1279=122=848=11386283=1229107=GEZ4 P9937269=1270=28271=600273=124352000336=2346=21023=2279=122=848=33890283=2201107=GEZ4 C9937269=1270=23271=1133273=124352000336=2346=41023=1279=222=848=33890283=2202107=GEZ4 C9937269=1270=23.5271=500273=124352000336=2346=11023=2279=122=848=62233683=1778107=GEZ4 C9925269=0270=30271=300273=124352000336=2346=31023=1279=022=848=62233683=1779107=GEZ4 C9925269=0270=29.5271=500273=124352000336=2346=11023=2279=122=848=27027983=444107=GEZ4 P9800269=1270=7.5271=237273=124352000336=2346=31023=1279=022=848=27027983=445107=GEZ4 P9800269=1270=8271=500273=124352000336=2346=11023=2279=122=848=1924783=691107=GEZ4 P9887269=0270=14.5271=760273=124352000336=2346=31023=1279=122=848=1924783=692107=GEZ4 P9887269=0270=14271=100273=124352000336=2346=11023=210=051
1128=99=278735=X49=CME34=3429852=2013071510080334875=20130715268=28279=022=848=13981783=64107=GEZ4 C9875269=0270=68.5271=150273=100803000336=2346=11023=1279=222=848=13981783=65107=GEZ4 C9875269=0270=68271=150273=100803000336=2346=11023=2279=022=848=11386283=226107=GEZ4 P9937269=1270=29.5271=150273=100803000336=2346=11023=2279=222=848=11386283=227107=GEZ4 P9937269=1270=30271=150273=100803000336=2346=11023=3279=022=848=84066783=177107=GEZ4 P9925269=1270=25.5271=150273=100803000336=2346=11023=2279=222=848=84066783=178107=GEZ4 P9925269=1270=26271=150273=100803000336=2346=11023=3279=022=848=69664283=60107=GEZ4 C9912269=0270=38271=150273=100803000336=2346=11023=1279=222=848=69664283=61107=GEZ4 C9912269=0270=37.5271=150273=100803000336=2346=11023=2279=022=848=62233683=475107=GEZ4 C9925269=0270=29271=150273=100803000336=2346=11023=1279=122=848=62233683=476107=GEZ4 C9925269=0270=28.5271=500273=100803000336=2346=11023=2279=022=848=59315083=114107=GEZ4 C9837269=0270=101271=75273=100803000336=2346=11023=1279=222=848=59315083=115107=GEZ4 C9837269=0270=100.5271=75273=100803000336=2346=11023=2279=022=848=10714983=60107=GEZ4 C9862269=0270=79271=75273=100803000336=2346=11023=1279=222=848=10714983=61107=GEZ4 C9862269=0270=78.5271=75273=100803000336=2346=11023=2279=022=848=66177783=94107=GEZ4 C9850269=0270=90271=75273=100803000336=2346=11023=1279=222=848=66177783=95107=GEZ4 C9850269=0270=89.5271=75273=100803000336=2346=11023=2279=022=848=83496983=137107=GEZ4 P9950269=1270=34.5271=75273=100803000336=2346=11023=1279=222=848=83496983=138107=GEZ4 P9950269=1270=35271=75273=100803000336=2346=11023=2279=022=848=33890283=636107=GEZ4 C9937269=0270=20.5271=150273=100803000336=2346=11023=1279=122=848=33890283=637107=GEZ4 C9937269=0270=20271=500273=100803000336=2346=11023=2279=122=848=1924783=102107=GEZ4 P9887269=1270=17271=650273=100803000336=2346=21023=1279=222=848=1924783=103107=GEZ4 P9887269=1270=17.5271=150273=100803000336=2346=11023=2279=122=848=38159883=136107=GEZ4 P9875269=1270=15271=650273=100803000336=2346=21023=1279=222=848=38159883=137107=GEZ4 P9875269=1270=15.5271=150273=100803000336=2346=11023=2279=122=848=19489783=136107=GEZ4 P9850269=1270=12271=650273=100803000336=2346=21023=1279=222=848=19489783=137107=GEZ4 P9850269=1270=12.5271=150273=100803000336=2346=11023=2279=122=848=27027983=107107=GEZ4 P9800269=1270=8271=650273=100803000336=2346=21023=1279=222=848=27027983=108107=GEZ4 P9800269=1270=8.5271=150273=100803000336=2346=11023=210=251
1128=99=84635=X49=CME34=8022552=2013071512353022175=20130715268=8279=122=848=33890283=2115107=GEZ4 C9937269=1270=23271=333273=123530000336=2346=31023=1279=222=848=33890283=2116107=GEZ4 C9937269=1270=26271=125273=123530000336=2346=11023=2279=122=848=69664283=518107=GEZ4 C9912269=1270=41271=167273=123530000336=2346=21023=1279=222=848=69664283=519107=GEZ4 C9912269=1270=45.5271=125273=123530000336=2346=11023=3279=122=848=85416683=518107=GEZ4 C9900269=1270=51271=333273=123530000336=2346=31023=1279=222=848=85416683=519107=GEZ4 C9900269=1270=56271=125273=123530000336=2346=11023=2279=122=848=25677583=1555107=GEZ4 P9900269=0270=16.5271=333273=123530000336=2346=31023=1279=222=848=25677583=1556107=GEZ4 P9900269=0270=11.5271=125273=123530000336=2346=11023=210=013
1128=99=25535=X49=CME34=11987652=2013071513113416875=20130715268=2279=022=848=37100783=81107=GEM4 P9962269=1270=21271=125273=131134000336=2346=11023=1279=222=848=37100783=82107=GEM4 P9962269=1270=21.5271=125273=131134000336=2346=11023=210=183
1128=99=132535=X49=CME34=7664752=2013071512341602775=20130715268=13279=122=848=63199683=306107=GEU4 C9900269=0270=52.5271=167273=123416000336=2346=21023=1279=122=848=63199683=307107=GEU4 C9900269=0270=52271=75273=123416000336=2346=11023=2279=122=848=63199683=308107=GEU4 C9900269=1270=54.5271=167273=123416000336=2346=21023=1279=122=848=63199683=309107=GEU4 C9900269=1270=55271=75273=123416000336=2346=11023=2279=122=848=63875283=389107=GEU4 C9887269=0270=63.5271=167273=123416000336=2346=21023=1279=122=848=63875283=390107=GEU4 C9887269=0270=63271=75273=123416000336=2346=11023=2279=122=848=63875283=391107=GEU4 C9887269=1270=65.5271=167273=123416000336=2346=21023=1279=122=848=63875283=392107=GEU4 C9887269=1270=66271=75273=123416000336=2346=11023=2279=122=848=75682783=529107=GEU4 P9875269=0270=7271=417273=123416000336=2346=31023=1279=122=848=75682783=530107=GEU4 P9875269=1270=9271=417273=123416000336=2346=31023=1279=122=848=31721683=332107=GEU4 P9900269=0270=10271=167273=123416000336=2346=21023=1279=122=848=31721683=333107=GEU4 P9900269=0270=9.5271=150273=123416000336=2346=11023=2279=122=848=31721683=334107=GEU4 P9900269=1270=12271=417273=123416000336=2346=31023=110=244
1128=99=142335=X49=CME34=6357052=2013071512301183775=20130715268=14279=022=848=15620183=464107=GEM4 P9887269=0270=1271=250273=123011000336=2346=11023=1279=022=848=15620183=465107=GEM4 P9887269=1270=9.5271=250273=123011000336=2346=11023=1279=022=848=58255183=352107=GEM4 C9912269=0270=38.5271=250273=123011000336=2346=11023=1279=022=848=58255183=353107=GEM4 C9912269=1270=51.5271=250273=123011000336=2346=11023=1279=022=848=6974783=186107=GEM4 P9912269=0270=2.5271=250273=123011000336=2346=11023=1279=022=848=6974783=187107=GEM4 P9912269=1270=12.5271=250273=123011000336=2346=11023=1279=022=848=56904083=797107=GEM4 C9937269=0270=19271=250273=123011000336=2346=11023=1279=022=848=56904083=798107=GEM4 C9937269=1270=29.5271=250273=123011000336=2346=11023=1279=022=848=27320183=463107=GEM4 P9937269=0270=6271=250273=123011000336=2346=11023=1279=022=848=27320183=464107=GEM4 P9937269=1270=17271=250273=123011000336=2346=11023=1279=022=848=64443183=169107=GEM4 C9962269=0270=4271=250273=123011000336=2346=11023=1279=022=848=64443183=170107=GEM4 C9962269=1270=9271=250273=123011000336=2346=11023=1279=022=848=37100783=21107=GEM4 P9962269=0270=15.5271=125273=123011000336=2346=11023=1279=022=848=37100783=22107=GEM4 P9962269=1270=22271=125273=123011000336=2346=11023=110=136
1128=99=319735=X49=CME34=13979652=2013071513342248075=20130715268=32279=122=848=39402183=766107=GEZ4 C9787269=0270=149271=67273=133422000336=2346=11023=1279=122=848=39402183=767107=GEZ4 C9787269=0270=148.5271=150273=133422000336=2346=21023=2279=122=848=4525583=737107=GEZ4 C9812269=0270=125.5271=133273=133422000336=2346=21023=1279=022=848=4525583=738107=GEZ4 C9812269=0270=125271=100273=133422000336=2346=11023=2279=122=848=78552983=859107=GEZ4 C9825269=0270=114271=67273=133422000336=2346=11023=1279=122=848=78552983=860107=GEZ4 C9825269=0270=113.5271=150273=133422000336=2346=21023=2279=122=848=59315083=1233107=GEZ4 C9837269=0270=102.5271=183273=133422000336=2346=31023=1279=122=848=83496983=1383107=GEZ4 P9950269=0270=31.5271=33273=133422000336=2346=11023=1279=022=848=83496983=1384107=GEZ4 P9950269=0270=31271=100273=133422000336=2346=11023=2279=122=848=83496983=1385107=GEZ4 P9950269=1270=33271=67273=133422000336=2346=11023=1279=122=848=83496983=1386107=GEZ4 P9950269=1270=33.5271=150273=133422000336=2346=21023=2279=122=848=28379683=786107=GEZ4 C9550269=0270=381271=40273=133422000336=2346=11023=1279=022=848=28379683=787107=GEZ4 C9550269=0270=380.5271=50273=133422000336=2346=11023=2279=122=848=75283283=784107=GEZ4 C9600269=0270=331.5271=40273=133422000336=2346=11023=1279=022=848=75283283=785107=GEZ4 C9600269=0270=331271=50273=133422000336=2346=11023=2279=122=848=33215083=702107=GEZ4 C9650269=0270=282271=75273=133422000336=2346=21023=1279=122=848=81470583=757107=GEZ4 C9675269=0270=257.5271=40273=133422000336=2346=11023=1279=022=848=81470583=758107=GEZ4 C9675269=0270=257271=50273=133422000336=2346=11023=2279=122=848=21516583=863107=GEZ4 C9575269=0270=356271=75273=133422000336=2346=21023=1279=122=848=53803483=740107=GEZ4 C9700269=0270=233271=75273=133422000336=2346=21023=1279=122=848=8473683=728107=GEZ4 C9712269=0270=221271=40273=133422000336=2346=11023=1279=022=848=8473683=729107=GEZ4 C9712269=0270=220.5271=50273=133422000336=2346=11023=2279=122=848=84066783=1267107=GEZ4 P9925269=1270=24.5271=965273=133422000336=2346=41023=1279=122=848=33890283=2527107=GEZ4 C9937269=0270=21271=250273=133422000336=2346=31023=1279=122=848=25677583=2000107=GEZ4 P9900269=1270=18.5271=795273=133422000336=2346=21023=1279=122=848=25677583=2001107=GEZ4 P9900269=1270=19271=200273=133422000336=2346=21023=2279=122=848=7827083=787107=GEZ4 C9950269=1270=14.5271=33273=133422000336=2346=11023=1279=122=848=7827083=788107=GEZ4 C9950269=1270=15271=700273=133422000336=2346=31023=2279=122=848=38726583=1473107=GEZ4 P9837269=0270=9271=33273=133422000336=2346=11023=1279=122=848=38726583=1474107=GEZ4 P9837269=0270=8.5271=700273=133422000336=2346=31023=2279=122=848=3855283=425107=GEZ4 P9812269=1270=8.5271=960273=133422000336=2346=41023=1279=122=848=18252283=315107=GEZ4 P9737269=1270=5271=790273=133422000336=2346=41023=110=033
1128=99=280235=X49=CME34=25099052=2013071516003300375=20130715268=28279=222=848=18811483=1518107=GEM5 C9375269=1270=528271=7273=160033000336=2346=11023=1279=022=848=18811483=1519107=GEM5 C9375269=1270=528.5271=7273=160033000336=2346=11023=1279=222=848=46263783=1516107=GEM5 C9400269=1270=503271=7273=160033000336=2346=11023=1279=022=848=46263783=1517107=GEM5 C9400269=1270=503.5271=7273=160033000336=2346=11023=1279=222=848=64149383=1516107=GEM5 C9425269=1270=478271=7273=160033000336=2346=11023=1279=022=848=64149383=1517107=GEM5 C9425269=1270=478.5271=7273=160033000336=2346=11023=1279=222=848=74497883=1498107=GEM5 C9450269=1270=453.5271=7273=160033000336=2346=11023=1279=022=848=74497883=1499107=GEM5 C9450269=1270=454271=7273=160033000336=2346=11023=1279=222=848=5086283=1516107=GEM5 C9475269=1270=428.5271=7273=160033000336=2346=11023=1279=022=848=5086283=1517107=GEM5 C9475269=1270=429271=7273=160033000336=2346=11023=1279=222=848=49073683=1516107=GEM5 C9500269=1270=404271=7273=160033000336=2346=11023=1279=022=848=49073683=1517107=GEM5 C9500269=1270=404.5271=7273=160033000336=2346=11023=1279=222=848=78551783=1456107=GEM5 C9550269=1270=354.5271=7273=160033000336=2346=11023=1279=022=848=78551783=1457107=GEM5 C9550269=1270=355271=7273=160033000336=2346=11023=1279=222=848=31862183=1182107=GEM5 C9650269=1270=257.5271=7273=160033000336=2346=11023=1279=022=848=31862183=1183107=GEM5 C9650269=1270=258271=7273=160033000336=2346=11023=1279=222=848=36022783=1434107=GEM5 C9600269=1270=306271=7273=160033000336=2346=11023=1279=022=848=36022783=1435107=GEM5 C9600269=1270=306.5271=7273=160033000336=2346=11023=1279=122=848=1469183=1080107=GEM5 P9787269=0270=14.5271=500273=160033000336=2346=11023=1279=022=848=1469183=1081107=GEM5 P9787269=0270=14271=75273=160033000336=2346=11023=2279=222=848=87547883=1380107=GEM5 C9675269=1270=234271=7273=160033000336=2346=11023=1279=022=848=87547883=1381107=GEM5 C9675269=1270=234.5271=7273=160033000336=2346=11023=1279=222=848=25674883=1354107=GEM5 C9725269=1270=187271=7273=160033000336=2346=11023=1279=022=848=25674883=1355107=GEM5 C9725269=1270=187.5271=7273=160033000336=2346=11023=1279=222=848=67915383=1308107=GEM5 C9737269=1270=175.5271=7273=160033000336=2346=11023=1279=022=848=67915383=1309107=GEM5 C9737269=1270=176271=7273=160033000336=2346=11023=1279=122=848=30078683=874107=GEM5 P9775269=0270=13271=500273=160033000336=2346=11023=1279=022=848=30078683=875107=GEM5 P9775269=0270=12.5271=75273=160033000336=2346=11023=210=027
1128=99=152335=X49=CME34=3534152=2013071510405095575=20130715268=15279=222=848=33890283=985107=GEZ4 C9937269=0270=20.5271=500273=104050000336=2346=11023=1279=122=848=33890283=986107=GEZ4 C9937269=0270=20271=650273=104050000336=2346=21023=1279=022=848=33890283=987107=GEZ4 C9937269=0270=2271=12273=104050000336=2346=31023=3279=222=848=62233683=749107=GEZ4 C9925269=0270=29271=500273=104050000336=2346=11023=1279=122=848=62233683=750107=GEZ4 C9925269=0270=28.5271=650273=104050000336=2346=21023=1279=222=848=43671583=642107=GEZ4 P9787269=1270=7271=500273=104050000336=2346=11023=1279=122=848=43671583=643107=GEZ4 P9787269=1270=7.5271=650273=104050000336=2346=21023=1279=222=848=12739883=646107=GEZ4 P9825269=1270=9.5271=500273=104050000336=2346=11023=1279=122=848=12739883=647107=GEZ4 P9825269=1270=10271=650273=104050000336=2346=21023=1279=222=848=38726583=646107=GEZ4 P9837269=1270=10.5271=500273=104050000336=2346=11023=1279=122=848=38726583=647107=GEZ4 P9837269=1270=11271=650273=104050000336=2346=21023=1279=222=848=70448783=646107=GEZ4 P9650269=1270=2.5271=500273=104050000336=2346=11023=1279=022=848=70448783=647107=GEZ4 P9650269=1270=3271=500273=104050000336=2346=11023=1279=222=848=25677583=727107=GEZ4 P9900269=1270=19271=500273=104050000336=2346=11023=1279=122=848=25677583=728107=GEZ4 P9900269=1270=19.5271=650273=104050000336=2346=21023=110=115
1128=99=114235=X49=CME34=36399352=2013071519241435875=20130715268=11279=022=848=11386283=3961107=GEZ4 P9937269=1270=27.5271=500273=192414000336=2346=11023=1279=122=848=11386283=3962107=GEZ4 P9937269=1270=28271=333273=192414000336=2346=11023=2279=022=848=88900683=727107=GEZ4 C9962269=0270=7271=500273=192414000336=2346=11023=1279=122=848=88900683=728107=GEZ4 C9962269=0270=6.5271=333273=192414000336=2346=11023=2279=122=848=33890283=3831107=GEZ4 C9937269=0270=21271=633273=192414000336=2346=31023=1279=222=848=33890283=3832107=GEZ4 C9937269=0270=20.5271=500273=192414000336=2346=11023=2279=022=848=33890283=3833107=GEZ4 C9937269=0270=2271=12273=192414000336=2346=31023=3279=122=848=62233683=3758107=GEZ4 C9925269=0270=29.5271=667273=192414000336=2346=31023=1279=222=848=62233683=3759107=GEZ4 C9925269=0270=29271=500273=192414000336=2346=11023=2279=022=848=1924783=1812107=GEZ4 P9887269=1270=16271=500273=192414000336=2346=11023=1279=122=848=1924783=1813107=GEZ4 P9887269=1270=16.5271=500273=192414000336=2346=21023=210=120
1128=99=25535=X49=CME34=21255652=2013071515024540775=20130715268=2279=022=848=38742583=486107=GEH5 P9675269=0270=3.5271=150273=150245000336=2346=11023=1279=122=848=38742583=487107=GEH5 P9675269=0270=3271=100273=150245000336=2346=11023=210=202
1128=99=171835=X49=CME34=4289252=2013071511562596275=20130715268=17279=222=848=40477083=256107=GEU4 C9875269=0270=72.5271=75273=115625000336=2346=11023=1279=122=848=40477083=257107=GEU4 C9875269=0270=72271=225273=115625000336=2346=21023=1279=222=848=40477083=258107=GEU4 C9875269=1270=75271=60273=115625000336=2346=11023=1279=022=848=40477083=259107=GEU4 C9875269=1270=75.5271=75273=115625000336=2346=11023=1279=122=848=44070383=380107=GEU4 P9937269=0270=18271=620273=115625000336=2346=21023=1279=222=848=44070383=381107=GEU4 P9937269=0270=17.5271=150273=115625000336=2346=11023=2279=022=848=44070383=382107=GEU4 P9937269=0270=1271=4273=115625000336=2346=11023=3279=222=848=63875283=216107=GEU4 C9887269=0270=61.5271=75273=115625000336=2346=11023=1279=022=848=63875283=217107=GEU4 C9887269=0270=61271=75273=115625000336=2346=11023=1279=222=848=63875283=218107=GEU4 C9887269=1270=64271=60273=115625000336=2346=11023=1279=022=848=63875283=219107=GEU4 C9887269=1270=64.5271=75273=115625000336=2346=11023=1279=122=848=39801583=437107=GEU4 P9925269=1270=17271=620273=115625000336=2346=21023=1279=222=848=39801583=438107=GEU4 P9925269=1270=17.5271=150273=115625000336=2346=11023=2279=222=848=66578483=296107=GEU4 P9912269=0270=12.5271=150273=115625000336=2346=11023=1279=122=848=66578483=297107=GEU4 P9912269=0270=12271=800273=115625000336=2346=31023=1279=122=848=66578483=298107=GEU4 P9912269=1270=14.5271=620273=115625000336=2346=21023=1279=122=848=31721683=185107=GEU4 P9900269=1270=12.5271=620273=115625000336=2346=21023=110=207
1128=99=25535=X49=CME34=33126652=2013071518151246975=20130715268=2279=122=848=2150383=672107=GEU3 P9550269=1270=0.5271=51273=181512000336=2346=21023=1279=122=848=2150383=673107=GEU3 P9550269=1270=0.75271=550273=181512000336=2346=21023=210=195
1128=99=44835=X49=CME34=32593552=2013071518044254175=20130715268=4279=122=848=72272783=2384107=GEH5 C9850269=1270=86271=250273=180442000336=2346=21023=1279=222=848=72272783=2385107=GEH5 C9850269=1270=94271=125273=180442000336=2346=11023=2279=122=848=38742583=741107=GEH5 P9675269=0270=3271=250273=180442000336=2346=21023=1279=122=848=38742583=742107=GEH5 P9675269=1270=6271=12273=180442000336=2346=11023=310=106
1128=99=45235=X49=CME34=19323152=2013071514324622775=20130715268=4279=222=848=87273483=627107=GEM4 P9725269=0270=0.5271=17273=143246000336=2346=11023=1279=122=848=87273483=628107=GEM4 P9725269=1270=1.5271=740273=143246000336=2346=21023=1279=222=848=37100783=197107=GEM4 P9962269=1270=21.5271=125273=143246000336=2346=11023=1279=022=848=37100783=198107=GEM4 P9962269=1270=22271=125273=143246000336=2346=11023=110=056
1128=99=25535=X49=CME34=38186352=2013071520034930775=20130715268=2279=122=848=2150383=813107=GEU3 P9550269=1270=0.5271=51273=200349000336=2346=21023=1279=122=848=2150383=814107=GEU3 P9550269=1270=0.75271=500273=200349000336=2346=11023=210=182
1128=99=263235=X49=CME34=24654452=2013071515552538575=20130715268=26279=222=848=24341283=2309107=GEH5 C9725269=1270=199.5271=75273=155525000336=2346=11023=1279=122=848=24341283=2310107=GEH5 C9725269=1270=200271=125273=155525000336=2346=21023=1279=222=848=61465183=2188107=GEH5 C9737269=1270=187.5271=75273=155525000336=2346=11023=1279=122=848=61465183=2189107=GEH5 C9737269=1270=188271=125273=155525000336=2346=21023=1279=222=848=27610983=2172107=GEH5 C9762269=1270=164271=75273=155525000336=2346=11023=1279=122=848=27610983=2173107=GEH5 C9762269=1270=164.5271=125273=155525000336=2346=21023=1279=222=848=43579483=2181107=GEH5 C9775269=1270=152.5271=75273=155525000336=2346=11023=1279=122=848=43579483=2182107=GEH5 C9775269=1270=153271=125273=155525000336=2346=21023=1279=222=848=80705883=2060107=GEH5 C9787269=1270=141271=75273=155525000336=2346=11023=1279=122=848=80705883=2061107=GEH5 C9787269=1270=141.5271=125273=155525000336=2346=21023=1279=222=848=2866183=1995107=GEH5 C9800269=1270=129.5271=75273=155525000336=2346=11023=1279=122=848=2866183=1996107=GEH5 C9800269=1270=130271=125273=155525000336=2346=21023=1279=222=848=11291383=1563107=GEH5 C9825269=1270=107271=75273=155525000336=2346=11023=1279=122=848=11291383=1564107=GEH5 C9825269=1270=107.5271=125273=155525000336=2346=21023=1279=222=848=11969183=1248107=GEH5 P9962269=0270=50.5271=75273=155525000336=2346=11023=1279=022=848=11969183=1249107=GEH5 P9962269=0270=50271=75273=155525000336=2346=11023=1279=222=848=27043383=1184107=GEH5 P9950269=0270=43.5271=75273=155525000336=2346=11023=1279=022=848=27043383=1185107=GEH5 P9950269=0270=43271=75273=155525000336=2346=11023=1279=222=848=57304683=1653107=GEH5 P9937269=0270=38271=75273=155525000336=2346=11023=1279=122=848=57304683=1654107=GEH5 P9937269=0270=37.5271=125273=155525000336=2346=21023=1279=222=848=75866783=2672107=GEH5 P9862269=0270=18271=150273=155525000336=2346=11023=1279=122=848=75866783=2673107=GEH5 P9862269=0270=17.5271=750273=155525000336=2346=31023=1279=222=848=25692083=2534107=GEH5 P9850269=0270=16271=150273=155525000336=2346=11023=1279=122=848=25692083=2535107=GEH5 P9850269=0270=15.5271=750273=155525000336=2346=31023=1279=222=848=38742583=628107=GEH5 P9675269=0270=3.5271=150273=155525000336=2346=11023=1279=122=848=38742583=629107=GEH5 P9675269=0270=3271=250273=155525000336=2346=21023=110=017
1128=99=45235=X49=CME34=20046552=2013071514460714175=20130715268=4279=222=848=87273483=665107=GEM4 P9725269=0270=0.5271=33273=144607000336=2346=11023=1279=122=848=87273483=666107=GEM4 P9725269=1270=1.5271=745273=144607000336=2346=21023=1279=222=848=37100783=213107=GEM4 P9962269=1270=21.5271=125273=144607000336=2346=11023=1279=022=848=37100783=214107=GEM4 P9962269=1270=22271=125273=144607000336=2346=11023=110=044
1128=99=25435=X49=CME34=33132652=2013071518151443475=20130715268=2279=122=848=2150383=674107=GEU3 P9550269=1270=0.5271=1273=181514000336=2346=11023=1279=122=848=2150383=675107=GEU3 P9550269=1270=0.75271=600273=181514000336=2346=31023=210=136
1128=99=142835=X49=CME34=3489852=2013071510265826575=20130715268=14279=022=848=33890283=849107=GEZ4 C9937269=0270=20.5271=500273=102658000336=2346=11023=1279=122=848=33890283=850107=GEZ4 C9937269=0270=20271=150273=102658000336=2346=11023=2279=022=848=62233683=639107=GEZ4 C9925269=0270=29271=500273=102658000336=2346=11023=1279=122=848=62233683=640107=GEZ4 C9925269=0270=28.5271=150273=102658000336=2346=11023=2279=022=848=43671583=544107=GEZ4 P9787269=1270=7271=500273=102658000336=2346=11023=1279=122=848=43671583=545107=GEZ4 P9787269=1270=7.5271=150273=102658000336=2346=11023=2279=022=848=12739883=548107=GEZ4 P9825269=1270=9.5271=500273=102658000336=2346=11023=1279=122=848=12739883=549107=GEZ4 P9825269=1270=10271=150273=102658000336=2346=11023=2279=022=848=38726583=548107=GEZ4 P9837269=1270=10.5271=500273=102658000336=2346=11023=1279=122=848=38726583=549107=GEZ4 P9837269=1270=11271=150273=102658000336=2346=11023=2279=022=848=70448783=548107=GEZ4 P9650269=1270=2.5271=500273=102658000336=2346=11023=1279=222=848=70448783=549107=GEZ4 P9650269=1270=3271=500273=102658000336=2346=11023=2279=022=848=25677583=629107=GEZ4 P9900269=1270=19271=500273=102658000336=2346=11023=1279=122=848=25677583=630107=GEZ4 P9900269=1270=19.5271=150273=102658000336=2346=11023=210=120
1128=99=144935=X49=CME34=31554252=2013071517474881075=20130715268=14279=122=848=4525583=1414107=GEZ4 C9812269=0270=125.5271=207273=174748000336=2346=31023=1279=222=848=4525583=1415107=GEZ4 C9812269=0270=125271=50273=174748000336=2346=11023=2279=122=848=53128783=1782107=GEZ4 C9800269=0270=137.5271=83273=174748000336=2346=21023=1279=022=848=53128783=1783107=GEZ4 C9800269=0270=136.5271=50273=174748000336=2346=11023=2279=122=848=53128783=1784107=GEZ4 C9800269=1270=139.5271=160273=174748000336=2346=31023=1279=122=848=66177783=2077107=GEZ4 C9850269=1270=93.5271=243273=174748000336=2346=31023=1279=122=848=13981783=1947107=GEZ4 C9875269=1270=71.5271=217273=174748000336=2346=31023=1279=122=848=83496983=2002107=GEZ4 P9950269=0270=31271=233273=174748000336=2346=31023=1279=222=848=83496983=2003107=GEZ4 P9950269=0270=30.5271=50273=174748000336=2346=11023=2279=022=848=83496983=2004107=GEZ4 P9950269=0270=1271=8273=174748000336=2346=21023=3279=122=848=10714983=2282107=GEZ4 C9862269=1270=82.5271=243273=174748000336=2346=31023=1279=122=848=87658983=2333107=GEZ4 P9912269=0270=19.5271=247273=174748000336=2346=31023=1279=122=848=87658983=2334107=GEZ4 P9912269=0270=19271=500273=174748000336=2346=11023=2279=122=848=1924783=1474107=GEZ4 P9887269=0270=14.5271=333273=174748000336=2346=31023=110=239
1128=99=25535=X49=CME34=25653852=2013071516114927375=20130715268=2279=122=848=2150383=464107=GEU3 P9550269=1270=0.5271=51273=161149000336=2346=21023=1279=122=848=2150383=465107=GEU3 P9550269=1270=0.75271=550273=161149000336=2346=21023=210=206
1128=99=278535=X49=CME34=3428452=2013071510080036275=20130715268=28279=222=848=13981783=62107=GEZ4 C9875269=0270=68.5271=150273=100800000336=2346=11023=1279=022=848=13981783=63107=GEZ4 C9875269=0270=68271=150273=100800000336=2346=11023=1279=222=848=11386283=221107=GEZ4 P9937269=1270=29.5271=150273=100800000336=2346=11023=2279=022=848=11386283=222107=GEZ4 P9937269=1270=30271=150273=100800000336=2346=11023=2279=222=848=69664283=58107=GEZ4 C9912269=0270=38271=150273=100800000336=2346=11023=1279=022=848=69664283=59107=GEZ4 C9912269=0270=37.5271=150273=100800000336=2346=11023=1279=122=848=62233683=471107=GEZ4 C9925269=0270=29271=500273=100800000336=2346=11023=1279=022=848=62233683=472107=GEZ4 C9925269=0270=28.5271=150273=100800000336=2346=11023=2279=222=848=84066783=173107=GEZ4 P9925269=1270=25.5271=150273=100800000336=2346=11023=2279=022=848=84066783=174107=GEZ4 P9925269=1270=26271=150273=100800000336=2346=11023=2279=222=848=59315083=112107=GEZ4 C9837269=0270=101271=75273=100800000336=2346=11023=1279=022=848=59315083=113107=GEZ4 C9837269=0270=100.5271=75273=100800000336=2346=11023=1279=222=848=10714983=58107=GEZ4 C9862269=0270=79271=75273=100800000336=2346=11023=1279=022=848=10714983=59107=GEZ4 C9862269=0270=78.5271=75273=100800000336=2346=11023=1279=222=848=66177783=92107=GEZ4 C9850269=0270=90271=75273=100800000336=2346=11023=1279=022=848=66177783=93107=GEZ4 C9850269=0270=89.5271=75273=100800000336=2346=11023=1279=122=848=33890283=631107=GEZ4 C9937269=0270=20.5271=500273=100800000336=2346=11023=1279=022=848=33890283=632107=GEZ4 C9937269=0270=20271=150273=100800000336=2346=11023=2279=222=848=83496983=135107=GEZ4 P9950269=1270=34.5271=75273=100800000336=2346=11023=1279=022=848=83496983=136107=GEZ4 P9950269=1270=35271=75273=100800000336=2346=11023=1279=122=848=1924783=98107=GEZ4 P9887269=1270=17271=500273=100800000336=2346=11023=1279=022=848=1924783=99107=GEZ4 P9887269=1270=17.5271=150273=100800000336=2346=11023=2279=122=848=38159883=134107=GEZ4 P9875269=1270=15271=500273=100800000336=2346=11023=1279=022=848=38159883=135107=GEZ4 P9875269=1270=15.5271=150273=100800000336=2346=11023=2279=122=848=19489783=134107=GEZ4 P9850269=1270=12271=500273=100800000336=2346=11023=1279=022=848=19489783=135107=GEZ4 P9850269=1270=12.5271=150273=100800000336=2346=11023=2279=122=848=27027983=105107=GEZ4 P9800269=1270=8271=500273=100800000336=2346=11023=1279=022=848=27027983=106107=GEZ4 P9800269=1270=8.5271=150273=100800000336=2346=11023=210=005
1128=99=25735=X49=CME34=35287752=2013071519001881575=20130715268=2279=022=848=37100783=325107=GEM4 P9962269=1270=21271=125273=190018000336=2346=11023=1279=222=848=37100783=326107=GEM4 P9962269=1270=21.5271=125273=190018000336=2346=11023=210=044
1128=99=103535=X49=CME34=3822052=2013071511364622875=20130715268=10279=222=848=59822583=49107=GEZ3 P9962269=1270=7271=500273=113646000336=2346=11023=1279=022=848=59822583=50107=GEZ3 P9962269=1270=7.5271=500273=113646000336=2346=11023=1279=222=848=71521683=97107=GEZ3 P9937269=1270=3.25271=500273=113646000336=2346=11023=1279=022=848=71521683=98107=GEZ3 P9937269=1270=3.5271=500273=113646000336=2346=11023=1279=222=848=62740383=122107=GEZ3 P9950269=1270=4.5271=500273=113646000336=2346=11023=1279=122=848=62740383=123107=GEZ3 P9950269=1270=4.75271=700273=113646000336=2346=21023=1279=222=848=15964483=63107=GEZ3 P9975269=1270=12271=500273=113646000336=2346=11023=1279=022=848=15964483=64107=GEZ3 P9975269=1270=12.5271=500273=113646000336=2346=11023=1279=122=848=10432583=46107=GEZ3 C9975269=0270=0.5271=1000273=113646000336=2346=11023=2279=022=848=10432583=47107=GEZ3 C9975269=0270=0.25271=500273=113646000336=2346=11023=310=061
1128=99=25435=X49=CME34=38361152=2013071520194937175=20130715268=2279=122=848=2150383=825107=GEU3 P9550269=1270=0.5271=1273=201949000336=2346=11023=1279=122=848=2150383=826107=GEU3 P9550269=1270=0.75271=550273=201949000336=2346=21023=210=154
1128=99=461035=X49=CME34=24654352=2013071515552538575=20130715268=46279=222=848=72272783=1948107=GEH5 C9850269=1270=85.5271=150273=155525000336=2346=11023=1279=122=848=72272783=1949107=GEH5 C9850269=1270=86271=250273=155525000336=2346=21023=1279=222=848=40660783=1515107=GEH5 C9862269=1270=75271=150273=155525000336=2346=11023=1279=122=848=40660783=1516107=GEH5 C9862269=1270=75.5271=250273=155525000336=2346=21023=1279=222=848=36716183=1410107=GEH5 C9275269=1270=644271=75273=155525000336=2346=11023=1279=022=848=36716183=1411107=GEH5 C9275269=1270=644.5271=75273=155525000336=2346=11023=1279=222=848=81378183=1410107=GEH5 C9300269=1270=619271=75273=155525000336=2346=11023=1279=022=848=81378183=1411107=GEH5 C9300269=1270=619.5271=75273=155525000336=2346=11023=1279=222=848=69003883=1410107=GEH5 C9325269=1270=594271=75273=155525000336=2346=11023=1279=022=848=69003883=1411107=GEH5 C9325269=1270=594.5271=75273=155525000336=2346=11023=1279=222=848=22104483=1402107=GEH5 C9350269=1270=569271=75273=155525000336=2346=11023=1279=022=848=22104483=1403107=GEH5 C9350269=1270=569.5271=75273=155525000336=2346=11023=1279=222=848=42903383=1394107=GEH5 C9375269=1270=544271=75273=155525000336=2346=11023=1279=022=848=42903383=1395107=GEH5 C9375269=1270=544.5271=75273=155525000336=2346=11023=1279=222=848=28285883=1394107=GEH5 C9400269=1270=519271=75273=155525000336=2346=11023=1279=022=848=28285883=1395107=GEH5 C9400269=1270=519.5271=75273=155525000336=2346=11023=1279=222=848=47804683=1132107=GEH5 C9600269=1270=320.5271=75273=155525000336=2346=11023=1279=022=848=47804683=1133107=GEH5 C9600269=1270=321271=75273=155525000336=2346=11023=1279=222=848=88240983=1391107=GEH5 C9425269=1270=494271=75273=155525000336=2346=11023=1279=022=848=88240983=1392107=GEH5 C9425269=1270=494.5271=75273=155525000336=2346=11023=1279=222=848=66100483=1335107=GEH5 C9450269=1270=469271=75273=155525000336=2346=11023=1279=022=848=66100483=1336107=GEH5 C9450269=1270=469.5271=75273=155525000336=2346=11023=1279=222=848=33797983=1236107=GEH5 C9625269=1270=296271=75273=155525000336=2346=11023=1279=022=848=33797983=1237107=GEH5 C9625269=1270=296.5271=75273=155525000336=2346=11023=1279=222=848=82053483=1371107=GEH5 C9475269=1270=444.5271=75273=155525000336=2346=11023=1279=022=848=82053483=1372107=GEH5 C9475269=1270=445271=75273=155525000336=2346=11023=1279=222=848=8373583=1371107=GEH5 C9500269=1270=419.5271=75273=155525000336=2346=11023=1279=022=848=8373583=1372107=GEH5 C9500269=1270=420271=75273=155525000336=2346=11023=1279=222=848=4430783=1219107=GEH5 C9525269=1270=394.5271=75273=155525000336=2346=11023=1279=022=848=4430783=1220107=GEH5 C9525269=1270=395271=75273=155525000336=2346=11023=1279=222=848=34473283=1367107=GEH5 C9550269=1270=370271=75273=155525000336=2346=11023=1279=022=848=34473283=1368107=GEH5 C9550269=1270=370.5271=75273=155525000336=2346=11023=1279=222=848=10624283=1287107=GEH5 C9575269=1270=345.5271=75273=155525000336=2346=11023=1279=022=848=10624283=1288107=GEH5 C9575269=1270=346271=75273=155525000336=2346=11023=1279=222=848=30528983=1764107=GEH5 C9875269=1270=65271=150273=155525000336=2346=11023=1279=122=848=30528983=1765107=GEH5 C9875269=1270=65.5271=250273=155525000336=2346=21023=1279=222=848=62816183=1100107=GEH5 C9650269=1270=272271=75273=155525000336=2346=11023=1279=022=848=62816183=1101107=GEH5 C9650269=1270=272.5271=75273=155525000336=2346=11023=1279=222=848=85323383=1282107=GEH5 C9675269=1270=247.5271=75273=155525000336=2346=11023=1279=022=848=85323383=1283107=GEH5 C9675269=1270=248271=75273=155525000336=2346=11023=1279=222=848=60573483=1310107=GEH5 C9687269=1270=235.5271=75273=155525000336=2346=11023=1279=022=848=60573483=1311107=GEH5 C9687269=1270=236271=75273=155525000336=2346=11023=1279=222=848=29853883=1234107=GEH5 C9700269=1270=223.5271=75273=155525000336=2346=11023=1279=022=848=29853883=1235107=GEH5 C9700269=1270=224271=75273=155525000336=2346=11023=1279=222=848=2319483=1212107=GEH5 C9712269=1270=211.5271=75273=155525000336=2346=11023=1279=022=848=2319483=1213107=GEH5 C9712269=1270=212271=75273=155525000336=2346=11023=110=217
1128=99=25735=X49=CME34=16427852=2013071514021295875=20130715268=2279=222=848=37100783=181107=GEM4 P9962269=0270=15.5271=125273=140212000336=2346=11023=1279=022=848=37100783=182107=GEM4 P9962269=0270=15271=125273=140212000336=2346=11023=110=024
1128=99=44835=X49=CME34=33138752=2013071518151468275=20130715268=4279=022=848=38742583=804107=GEH5 P9675269=1270=5.5271=150273=181514000336=2346=11023=2279=122=848=38742583=805107=GEH5 P9675269=1270=6271=11273=181514000336=2346=11023=3279=122=848=2150383=676107=GEU3 P9550269=1270=0.5271=51273=181514000336=2346=21023=1279=122=848=2150383=677107=GEU3 P9550269=1270=0.75271=550273=181514000336=2346=21023=210=119
1128=99=25735=X49=CME34=23428552=2013071515364671375=20130715268=2279=022=848=37100783=247107=GEM4 P9962269=1270=21.5271=125273=153646000336=2346=11023=1279=222=848=37100783=248107=GEM4 P9962269=1270=22271=125273=153646000336=2346=11023=210=058
1128=99=332735=X49=CME34=27771152=2013071516434523775=20130715268=33279=222=848=65225983=798107=GEU4 C9812269=0270=133271=100273=164345000336=2346=11023=1279=122=848=65225983=799107=GEU4 C9812269=0270=132.5271=175273=164345000336=2346=21023=1279=222=848=38558383=775107=GEU4 C9787269=0270=157271=100273=164345000336=2346=11023=1279=122=848=38558383=776107=GEU4 C9787269=0270=156.5271=175273=164345000336=2346=21023=1279=222=848=50150483=786107=GEU4 C9800269=0270=145271=100273=164345000336=2346=11023=1279=122=848=50150483=787107=GEU4 C9800269=0270=144.5271=175273=164345000336=2346=21023=1279=222=848=30912183=1187107=GEU4 C9850269=0270=97.5271=100273=164345000336=2346=11023=1279=122=848=30912183=1188107=GEU4 C9850269=0270=97271=292273=164345000336=2346=31023=1279=222=848=26751483=1005107=GEU4 C9862269=0270=86271=100273=164345000336=2346=11023=1279=122=848=26751483=1006107=GEU4 C9862269=0270=85.5271=282273=164345000336=2346=31023=1279=222=848=63875283=1226107=GEU4 C9887269=0270=63.5271=100273=164345000336=2346=11023=1279=122=848=63875283=1227107=GEU4 C9887269=0270=63271=282273=164345000336=2346=31023=1279=222=848=63199683=1108107=GEU4 C9900269=0270=52.5271=100273=164345000336=2346=11023=1279=122=848=63199683=1109107=GEU4 C9900269=0270=52271=322273=164345000336=2346=31023=1279=222=848=48015183=1082107=GEU4 C9912269=0270=42271=100273=164345000336=2346=11023=1279=122=848=48015183=1083107=GEU4 C9912269=0270=41.5271=397273=164345000336=2346=31023=1279=222=848=28101983=686107=GEU4 C9575269=0270=366.5271=50273=164345000336=2346=11023=1279=122=848=28101983=687107=GEU4 C9575269=0270=366271=125273=164345000336=2346=21023=1279=222=848=82437483=1010107=GEU4 C9625269=0270=317271=50273=164345000336=2346=11023=1279=122=848=82437483=1011107=GEU4 C9625269=0270=316.5271=125273=164345000336=2346=21023=1279=222=848=59714083=581107=GEU4 C9650269=0270=292271=50273=164345000336=2346=11023=1279=122=848=59714083=582107=GEU4 C9650269=0270=291.5271=125273=164345000336=2346=21023=1279=222=848=43962583=1038107=GEU4 C9675269=0270=267.5271=50273=164345000336=2346=11023=1279=122=848=43962583=1039107=GEU4 C9675269=0270=267271=125273=164345000336=2346=21023=1279=222=848=19213083=737107=GEU4 C9687269=0270=255271=50273=164345000336=2346=11023=1279=122=848=19213083=738107=GEU4 C9687269=0270=254.5271=125273=164345000336=2346=21023=1279=222=848=37775283=990107=GEU4 C9712269=0270=230.5271=50273=164345000336=2346=11023=1279=122=848=37775283=991107=GEU4 C9712269=0270=230271=125273=164345000336=2346=21023=1279=222=848=21239383=590107=GEU4 C9725269=0270=218271=50273=164345000336=2346=11023=1279=122=848=21239383=591107=GEU4 C9725269=0270=217.5271=125273=164345000336=2346=21023=1279=222=848=88624883=599107=GEU4 C9750269=0270=193.5271=50273=164345000336=2346=11023=1279=122=848=88624883=600107=GEU4 C9750269=0270=193271=125273=164345000336=2346=21023=1279=122=848=31721683=1019107=GEU4 P9900269=1270=11.5271=1037273=164345000336=2346=41023=110=215
1128=99=45235=X49=CME34=23285752=2013071515324717575=20130715268=4279=222=848=87273483=765107=GEM4 P9725269=0270=0.5271=17273=153247000336=2346=11023=1279=122=848=87273483=766107=GEM4 P9725269=1270=1.5271=820273=153247000336=2346=21023=1279=222=848=37100783=241107=GEM4 P9962269=0270=15.5271=125273=153247000336=2346=11023=1279=022=848=37100783=242107=GEM4 P9962269=0270=15271=125273=153247000336=2346=11023=110=064
1128=99=280535=X49=CME34=32587152=2013071518044220475=20130715268=28279=022=848=46263783=1990107=GEM5 C9400269=1270=503271=7273=180442000336=2346=11023=1279=222=848=46263783=1991107=GEM5 C9400269=1270=503.5271=7273=180442000336=2346=11023=2279=022=848=64149383=1990107=GEM5 C9425269=1270=478271=7273=180442000336=2346=11023=1279=222=848=64149383=1991107=GEM5 C9425269=1270=478.5271=7273=180442000336=2346=11023=2279=022=848=74497883=1972107=GEM5 C9450269=1270=453.5271=7273=180442000336=2346=11023=1279=222=848=74497883=1973107=GEM5 C9450269=1270=454271=7273=180442000336=2346=11023=2279=122=848=65500483=1186107=GEM5 P9800269=0270=16271=575273=180442000336=2346=21023=1279=222=848=65500483=1187107=GEM5 P9800269=0270=15.5271=75273=180442000336=2346=11023=2279=022=848=5086283=1990107=GEM5 C9475269=1270=428.5271=7273=180442000336=2346=11023=1279=222=848=5086283=1991107=GEM5 C9475269=1270=429271=7273=180442000336=2346=11023=2279=022=848=49073683=1990107=GEM5 C9500269=1270=404271=7273=180442000336=2346=11023=1279=222=848=49073683=1991107=GEM5 C9500269=1270=404.5271=7273=180442000336=2346=11023=2279=022=848=78551783=1930107=GEM5 C9550269=1270=354.5271=7273=180442000336=2346=11023=1279=222=848=78551783=1931107=GEM5 C9550269=1270=355271=7273=180442000336=2346=11023=2279=022=848=31862183=1624107=GEM5 C9650269=1270=257.5271=7273=180442000336=2346=11023=1279=222=848=31862183=1625107=GEM5 C9650269=1270=258271=7273=180442000336=2346=11023=2279=022=848=36022783=1908107=GEM5 C9600269=1270=306271=7273=180442000336=2346=11023=1279=222=848=36022783=1909107=GEM5 C9600269=1270=306.5271=7273=180442000336=2346=11023=2279=022=848=87547883=1830107=GEM5 C9675269=1270=234271=7273=180442000336=2346=11023=1279=222=848=87547883=1831107=GEM5 C9675269=1270=234.5271=7273=180442000336=2346=11023=2279=122=848=1469183=1498107=GEM5 P9787269=0270=14.5271=575273=180442000336=2346=21023=1279=222=848=1469183=1499107=GEM5 P9787269=0270=14271=75273=180442000336=2346=11023=2279=022=848=25674883=1804107=GEM5 C9725269=1270=187271=7273=180442000336=2346=11023=1279=222=848=25674883=1805107=GEM5 C9725269=1270=187.5271=7273=180442000336=2346=11023=2279=022=848=67915383=1758107=GEM5 C9737269=1270=175.5271=7273=180442000336=2346=11023=1279=222=848=67915383=1759107=GEM5 C9737269=1270=176271=7273=180442000336=2346=11023=2279=122=848=30078683=1172107=GEM5 P9775269=0270=13271=575273=180442000336=2346=21023=1279=222=848=30078683=1173107=GEM5 P9775269=0270=12.5271=75273=180442000336=2346=11023=210=222
1128=99=279035=X49=CME34=4143152=2013071511531641775=20130715268=28279=022=848=76802983=8107=GEQ3 P9925269=1270=0.75271=500273=115316000336=2346=11023=1279=022=848=23251983=12107=GEQ3 P9937269=1270=0.75271=500273=115316000336=2346=11023=1279=022=848=84341283=56107=GEQ3 P9962269=0270=0.5271=500273=115316000336=2346=11023=1279=022=848=84341283=57107=GEQ3 P9962269=1270=1.75271=500273=115316000336=2346=11023=1279=022=848=19481883=12107=GEQ3 P9950269=1270=1271=500273=115316000336=2346=11023=1279=122=848=6627683=13107=GEU3 P9575269=1270=0.75271=550273=115316000336=2346=21023=1279=022=848=68454283=102107=GEQ3 C9962269=0270=8.5271=500273=115316000336=2346=11023=1279=022=848=68454283=103107=GEQ3 C9962269=1270=10.5271=500273=115316000336=2346=11023=1279=022=848=19480483=102107=GEQ3 P9975269=0270=4.25271=500273=115316000336=2346=11023=1279=022=848=19480483=103107=GEQ3 P9975269=1270=6271=500273=115316000336=2346=11023=1279=022=848=36193583=49107=GEQ3 C9975269=1270=1.5271=500273=115316000336=2346=11023=3279=022=848=19470683=13107=GEQ3 C9987269=1270=0.75271=500273=115316000336=2346=11023=2279=122=848=61728283=13107=GEU3 P9350269=1270=0.75271=550273=115316000336=2346=21023=1279=122=848=13126183=13107=GEU3 P9600269=1270=0.75271=550273=115316000336=2346=21023=1279=122=848=53882883=13107=GEU3 P9375269=1270=0.75271=550273=115316000336=2346=21023=1279=122=848=81551783=34107=GEU3 P9625269=1270=0.75271=550273=115316000336=2346=21023=1279=122=848=32051683=36107=GEU3 P9675269=1270=0.75271=550273=115316000336=2346=21023=1279=122=848=71769583=13107=GEU3 P9400269=1270=0.75271=550273=115316000336=2346=21023=1279=122=848=10790783=13107=GEU3 P9450269=1270=0.75271=550273=115316000336=2346=21023=1279=122=848=88412483=9107=GEU3 P9425269=1270=0.75271=550273=115316000336=2346=21023=1279=022=848=47695783=8107=GEU3 C0012269=1270=0.5271=500273=115316000336=2346=11023=1279=022=848=71105983=12107=GEU3 C0000269=1270=0.5271=500273=115316000336=2346=11023=1279=122=848=49937983=9107=GEU3 P9475269=1270=0.75271=550273=115316000336=2346=21023=1279=122=848=69176883=34107=GEU3 P9725269=1270=0.75271=550273=115316000336=2346=21023=1279=122=848=51289383=13107=GEU3 P9500269=1270=0.75271=550273=115316000336=2346=21023=1279=022=848=19481583=8107=GEQ3 P9912269=1270=0.75271=500273=115316000336=2346=11023=1279=122=848=21595583=9107=GEU3 P9525269=1270=0.75271=550273=115316000336=2346=21023=1279=022=848=2150383=26107=GEU3 P9550269=1270=0.75271=500273=115316000336=2346=11023=210=072
1128=99=85735=X49=CME34=24176852=2013071515482320775=20130715268=8279=122=848=59897983=1556107=GEH5 C9812269=0270=114.5271=125273=154823000336=2346=21023=1279=222=848=59897983=1557107=GEH5 C9812269=0270=111271=75273=154823000336=2346=11023=2279=122=848=59897983=1558107=GEH5 C9812269=1270=118271=125273=154823000336=2346=21023=1279=222=848=59897983=1559107=GEH5 C9812269=1270=118.5271=50273=154823000336=2346=11023=2279=122=848=11291383=1492107=GEH5 C9825269=0270=103.5271=125273=154823000336=2346=21023=1279=222=848=11291383=1493107=GEH5 C9825269=0270=100271=75273=154823000336=2346=11023=2279=122=848=11291383=1494107=GEH5 C9825269=1270=107271=125273=154823000336=2346=21023=1279=222=848=11291383=1495107=GEH5 C9825269=1270=107.5271=50273=154823000336=2346=11023=210=008
1128=99=150835=X49=CME34=3199052=2013071508585214975=20130715268=15279=222=848=33890283=400107=GEZ4 C9937269=0270=20.5271=500273=85852000336=2346=11023=1279=122=848=33890283=401107=GEZ4 C9937269=0270=20271=650273=85852000336=2346=21023=1279=022=848=33890283=402107=GEZ4 C9937269=0270=2271=12273=85852000336=2346=31023=3279=222=848=62233683=325107=GEZ4 C9925269=0270=29271=500273=85852000336=2346=11023=1279=122=848=62233683=326107=GEZ4 C9925269=0270=28.5271=650273=85852000336=2346=21023=1279=222=848=43671583=274107=GEZ4 P9787269=1270=7271=500273=85852000336=2346=11023=1279=122=848=43671583=275107=GEZ4 P9787269=1270=7.5271=650273=85852000336=2346=21023=1279=222=848=12739883=278107=GEZ4 P9825269=1270=9.5271=500273=85852000336=2346=11023=1279=122=848=12739883=279107=GEZ4 P9825269=1270=10271=650273=85852000336=2346=21023=1279=222=848=38726583=278107=GEZ4 P9837269=1270=10.5271=500273=85852000336=2346=11023=1279=122=848=38726583=279107=GEZ4 P9837269=1270=11271=650273=85852000336=2346=21023=1279=222=848=70448783=278107=GEZ4 P9650269=1270=2.5271=500273=85852000336=2346=11023=1279=022=848=70448783=279107=GEZ4 P9650269=1270=3271=500273=85852000336=2346=11023=1279=222=848=25677583=359107=GEZ4 P9900269=1270=19271=500273=85852000336=2346=11023=1279=122=848=25677583=360107=GEZ4 P9900269=1270=19.5271=650273=85852000336=2346=21023=110=135
1128=99=104635=X49=CME34=34757352=2013071518481932175=20130715268=10279=122=848=11386283=3621107=GEZ4 P9937269=1270=27.5271=200273=184819000336=2346=11023=1279=122=848=11386283=3622107=GEZ4 P9937269=1270=28271=600273=184819000336=2346=21023=2279=122=848=33890283=3680107=GEZ4 C9937269=0270=21271=647273=184819000336=2346=31023=1279=022=848=33890283=3681107=GEZ4 C9937269=0270=20.5271=500273=184819000336=2346=11023=2279=122=848=62233683=3479107=GEZ4 C9925269=0270=29.5271=667273=184819000336=2346=31023=1279=022=848=62233683=3480107=GEZ4 C9925269=0270=29271=500273=184819000336=2346=11023=2279=122=848=88900683=577107=GEZ4 C9962269=0270=7271=333273=184819000336=2346=11023=1279=022=848=88900683=578107=GEZ4 C9962269=0270=6.5271=500273=184819000336=2346=11023=2279=122=848=1924783=1573107=GEZ4 P9887269=1270=16271=215273=184819000336=2346=11023=1279=122=848=1924783=1574107=GEZ4 P9887269=1270=16.5271=700273=184819000336=2346=31023=210=032
1128=99=85335=X49=CME34=12608052=2013071513193761475=20130715268=8279=122=848=61465183=1010107=GEH5 C9737269=0270=184271=125273=131937000336=2346=21023=1279=222=848=61465183=1011107=GEH5 C9737269=0270=181.5271=75273=131937000336=2346=11023=2279=222=848=61465183=1012107=GEH5 C9737269=1270=187.5271=15273=131937000336=2346=11023=1279=022=848=61465183=1013107=GEH5 C9737269=1270=192.5271=75273=131937000336=2346=11023=2279=122=848=24341283=915107=GEH5 C9725269=0270=196271=125273=131937000336=2346=21023=1279=222=848=24341283=916107=GEH5 C9725269=0270=193.5271=75273=131937000336=2346=11023=2279=222=848=24341283=917107=GEH5 C9725269=1270=199.5271=50273=131937000336=2346=11023=1279=022=848=24341283=918107=GEH5 C9725269=1270=204271=75273=131937000336=2346=11023=210=243
1128=99=25435=X49=CME34=8578852=2013071512385857275=20130715268=2279=022=848=37100783=49107=GEM4 P9962269=0270=15271=125273=123858000336=2346=11023=1279=222=848=37100783=50107=GEM4 P9962269=0270=14.5271=125273=123858000336=2346=11023=210=181
1128=99=45035=X49=CME34=34947852=2013071518555631075=20130715268=4279=222=848=50824983=742107=GEM4 P9737269=0270=0.5271=17273=185556000336=2346=11023=1279=122=848=50824983=743107=GEM4 P9737269=1270=2271=329273=185556000336=2346=31023=2279=222=848=37100783=307107=GEM4 P9962269=0270=15271=125273=185556000336=2346=11023=1279=022=848=37100783=308107=GEM4 P9962269=0270=14.5271=125273=185556000336=2346=11023=110=004
1128=99=123335=X49=CME34=7014152=2013071512314665375=20130715268=12279=122=848=58255183=370107=GEM4 C9912269=0270=44.5271=83273=123146000336=2346=21023=1279=122=848=58255183=371107=GEM4 C9912269=1270=47271=83273=123146000336=2346=21023=1279=122=848=6974783=200107=GEM4 P9912269=0270=6.5271=167273=123146000336=2346=21023=1279=122=848=6974783=201107=GEM4 P9912269=1270=8.5271=167273=123146000336=2346=21023=1279=122=848=56904083=812107=GEM4 C9937269=0270=23.5271=167273=123146000336=2346=21023=1279=122=848=56904083=813107=GEM4 C9937269=1270=25.5271=167273=123146000336=2346=21023=1279=122=848=27320183=480107=GEM4 P9937269=0270=10271=167273=123146000336=2346=21023=1279=122=848=27320183=481107=GEM4 P9937269=1270=12.5271=167273=123146000336=2346=21023=1279=022=848=64443183=181107=GEM4 C9962269=0270=4.5271=250273=123146000336=2346=11023=1279=022=848=64443183=182107=GEM4 C9962269=1270=9.5271=250273=123146000336=2346=11023=1279=022=848=37100783=33107=GEM4 P9962269=0270=15271=125273=123146000336=2346=11023=1279=022=848=37100783=34107=GEM4 P9962269=1270=21.5271=125273=123146000336=2346=11023=110=014
1128=99=143835=X49=CME34=15923852=2013071513570511075=20130715268=14279=222=848=29853883=654107=GEH5 C9700269=0270=221271=75273=135705000336=2346=11023=1279=022=848=29853883=655107=GEH5 C9700269=0270=220.5271=75273=135705000336=2346=11023=1279=022=848=29853883=656107=GEH5 C9700269=1270=224271=75273=135705000336=2346=11023=1279=222=848=29853883=657107=GEH5 C9700269=1270=224.5271=75273=135705000336=2346=11023=2279=222=848=53035583=1054107=GEH5 C9750269=0270=173.5271=75273=135705000336=2346=11023=1279=122=848=53035583=1055107=GEH5 C9750269=0270=173271=125273=135705000336=2346=21023=1279=222=848=2319483=632107=GEH5 C9712269=0270=209271=75273=135705000336=2346=11023=1279=022=848=2319483=633107=GEH5 C9712269=0270=208.5271=75273=135705000336=2346=11023=1279=022=848=2319483=634107=GEH5 C9712269=1270=212271=75273=135705000336=2346=11023=1279=222=848=2319483=635107=GEH5 C9712269=1270=212.5271=75273=135705000336=2346=11023=2279=222=848=24341283=1173107=GEH5 C9725269=0270=197271=75273=135705000336=2346=11023=1279=122=848=24341283=1174107=GEH5 C9725269=0270=196.5271=125273=135705000336=2346=21023=1279=022=848=24341283=1175107=GEH5 C9725269=1270=200271=75273=135705000336=2346=11023=1279=122=848=24341283=1176107=GEH5 C9725269=1270=200.5271=50273=135705000336=2346=11023=210=148
1128=99=35235=X49=CME34=24950652=2013071515584906875=20130715268=3279=122=848=3855283=611107=GEZ4 P9812269=1270=8.5271=800273=155849000336=2346=41023=1279=022=848=38742583=664107=GEH5 P9675269=0270=3.5271=150273=155849000336=2346=11023=1279=122=848=38742583=665107=GEH5 P9675269=0270=3271=100273=155849000336=2346=11023=210=247
1128=99=25735=X49=CME34=34757852=2013071518481933175=20130715268=2279=222=848=1924783=1575107=GEZ4 P9887269=1270=16271=215273=184819000336=2346=11023=1279=022=848=1924783=1576107=GEZ4 P9887269=1270=21.5271=125273=184819000336=2346=11023=210=143
1128=99=25535=X49=CME34=24794052=2013071515570880075=20130715268=2279=222=848=38742583=656107=GEH5 P9675269=0270=3.5271=100273=155708000336=2346=11023=1279=122=848=38742583=657107=GEH5 P9675269=1270=6271=162273=155708000336=2346=21023=210=239
1128=99=84735=X49=CME34=12842552=2013071513211551775=20130715268=8279=022=848=11386283=1628107=GEZ4 P9937269=1270=28.5271=500273=132115000336=2346=11023=1279=122=848=11386283=1629107=GEZ4 P9937269=1270=29271=633273=132115000336=2346=31023=2279=022=848=84066783=1173107=GEZ4 P9925269=1270=24.5271=500273=132115000336=2346=11023=1279=122=848=84066783=1174107=GEZ4 P9925269=1270=25271=500273=132115000336=2346=21023=2279=022=848=29271783=460107=GEZ4 P9862269=1270=13271=500273=132115000336=2346=11023=1279=122=848=29271783=461107=GEZ4 P9862269=1270=13.5271=667273=132115000336=2346=31023=2279=022=848=1924783=930107=GEZ4 P9887269=1270=16.5271=500273=132115000336=2346=11023=1279=122=848=1924783=931107=GEZ4 P9887269=1270=17271=667273=132115000336=2346=31023=210=158
1128=99=134435=X49=CME34=38276052=2013071520050502975=20130715268=13279=122=848=7827083=1918107=GEZ4 C9950269=1270=15.5271=1000273=200505000336=2346=31023=1279=222=848=7827083=1919107=GEZ4 C9950269=1270=17.5271=125273=200505000336=2346=11023=2279=122=848=1924783=1924107=GEZ4 P9887269=0270=14271=1000273=200505000336=2346=31023=1279=222=848=1924783=1925107=GEZ4 P9887269=0270=9271=125273=200505000336=2346=11023=2279=122=848=1924783=1926107=GEZ4 P9887269=1270=16271=1000273=200505000336=2346=31023=1279=122=848=62233683=3851107=GEZ4 C9925269=1270=32271=833273=200505000336=2346=21023=1279=222=848=62233683=3852107=GEZ4 C9925269=1270=35.5271=125273=200505000336=2346=11023=3279=122=848=69664283=2035107=GEZ4 C9912269=1270=42271=167273=200505000336=2346=21023=1279=222=848=69664283=2036107=GEZ4 C9912269=1270=45.5271=125273=200505000336=2346=11023=2279=122=848=25677583=3035107=GEZ4 P9900269=0270=16271=1000273=200505000336=2346=31023=1279=222=848=25677583=3036107=GEZ4 P9900269=0270=11271=125273=200505000336=2346=11023=2279=122=848=25677583=3037107=GEZ4 P9900269=1270=18271=833273=200505000336=2346=21023=1279=122=848=25677583=3038107=GEZ4 P9900269=1270=18.5271=100273=200505000336=2346=11023=210=079
1128=99=15935=X49=CME34=16556352=2013071514030163975=20130715268=1279=122=848=27027983=719107=GEZ4 P9800269=1270=7.5271=133273=140301000336=2346=21023=110=033
1128=99=281035=X49=CME34=29215452=2013071517010220375=20130715268=28279=122=848=71705383=211107=GEH5 P9650269=0270=2.5271=250273=170102000336=2346=21023=1279=022=848=71705383=212107=GEH5 P9650269=1270=5.5271=45273=170102000336=2346=11023=3279=122=848=51118783=549107=GEH5 P9625269=0270=2271=250273=170102000336=2346=21023=1279=122=848=51118783=550107=GEH5 P9625269=1270=4.5271=151273=170102000336=2346=21023=2279=122=848=2866183=2247107=GEH5 C9800269=0270=127271=125273=170102000336=2346=21023=1279=122=848=2866183=2248107=GEH5 C9800269=1270=130.5271=125273=170102000336=2346=21023=1279=122=848=64843083=1300107=GEH5 P9787269=0270=8.5271=250273=170102000336=2346=21023=1279=122=848=64843083=1301107=GEH5 P9787269=1270=11.5271=160273=170102000336=2346=21023=2279=122=848=80705883=2312107=GEH5 C9787269=0270=138.5271=125273=170102000336=2346=21023=1279=122=848=80705883=2313107=GEH5 C9787269=1270=142271=125273=170102000336=2346=21023=1279=122=848=57980183=3349107=GEH5 P9925269=0270=33271=800273=170102000336=2346=21023=1279=122=848=57980183=3350107=GEH5 P9925269=1270=36271=950273=170102000336=2346=31023=1279=122=848=14563083=2911107=GEH5 C9925269=0270=26.5271=833273=170102000336=2346=21023=1279=122=848=14563083=2912107=GEH5 C9925269=1270=29271=1083273=170102000336=2346=31023=1279=122=848=50442283=3272107=GEH5 P9912269=0270=29271=800273=170102000336=2346=21023=1279=122=848=50442283=3273107=GEH5 P9912269=1270=31.5271=765273=170102000336=2346=21023=1279=122=848=55953383=3010107=GEH5 C9912269=0270=34.5271=1083273=170102000336=2346=31023=1279=122=848=55953383=3011107=GEH5 C9912269=1270=37271=250273=170102000336=2346=21023=1279=122=848=44930183=3138107=GEH5 P9900269=0270=25271=1083273=170102000336=2346=31023=1279=122=848=44930183=3139107=GEH5 P9900269=1270=28271=700273=170102000336=2346=21023=1279=122=848=2308583=1378107=GEH5 C9900269=0270=43271=250273=170102000336=2346=21023=1279=122=848=2308583=1379107=GEH5 C9900269=1270=46.5271=250273=170102000336=2346=21023=1279=122=848=19511483=862107=GEH5 P9700269=0270=4271=250273=170102000336=2346=21023=1279=022=848=19511483=863107=GEH5 P9700269=1270=7271=27273=170102000336=2346=11023=3279=122=848=89592083=232107=GEH5 P9687269=0270=3.5271=250273=170102000336=2346=21023=1279=022=848=89592083=233107=GEH5 P9687269=1270=6.5271=28273=170102000336=2346=11023=3279=122=848=38742583=696107=GEH5 P9675269=0270=3271=250273=170102000336=2346=21023=1279=022=848=38742583=697107=GEH5 P9675269=1270=6271=20273=170102000336=2346=11023=310=212
1128=99=25435=X49=CME34=9621552=2013071512435545475=20130715268=2279=122=848=27027983=458107=GEZ4 P9800269=0270=6271=167273=124355000336=2346=21023=1279=122=848=27027983=459107=GEZ4 P9800269=1270=7.5271=217273=124355000336=2346=31023=110=202
1128=99=35535=X49=CME34=7654152=2013071512341522875=20130715268=3279=122=848=11386283=991107=GEZ4 P9937269=0270=26.5271=167273=123415000336=2346=21023=1279=122=848=11386283=992107=GEZ4 P9937269=0270=26271=100273=123415000336=2346=11023=2279=122=848=11386283=993107=GEZ4 P9937269=1270=28.5271=300273=123415000336=2346=31023=110=130
1128=99=45235=X49=CME34=27234852=2013071516402565475=20130715268=4279=122=848=7827083=1491107=GEZ4 C9950269=0270=13271=300273=164025000336=2346=31023=1279=122=848=7827083=1492107=GEZ4 C9950269=1270=14.5271=833273=164025000336=2346=21023=1279=122=848=7827083=1493107=GEZ4 C9950269=1270=15271=200273=164025000336=2346=21023=2279=122=848=27027983=1078107=GEZ4 P9800269=0270=6271=1167273=164025000336=2346=41023=110=068
1128=99=20335=X49=CME34=14802652=2013071513414872975=20130712268=2279=022=848=37100783=157107=GEM4 P9962269=B271=0273=134148000279=022=848=37100783=158107=GEM4 P9962269=C271=87022273=13414800010=215
1128=99=114235=X49=CME34=34759852=2013071518481941175=20130715268=11279=022=848=11386283=3627107=GEZ4 P9937269=1270=27.5271=500273=184819000336=2346=11023=1279=122=848=11386283=3628107=GEZ4 P9937269=1270=28271=200273=184819000336=2346=21023=2279=022=848=88900683=581107=GEZ4 C9962269=0270=7271=500273=184819000336=2346=11023=1279=222=848=88900683=582107=GEZ4 C9962269=0270=6.5271=500273=184819000336=2346=11023=2279=122=848=62233683=3485107=GEZ4 C9925269=0270=29.5271=833273=184819000336=2346=41023=1279=222=848=62233683=3486107=GEZ4 C9925269=0270=29271=500273=184819000336=2346=11023=2279=122=848=33890283=3684107=GEZ4 C9937269=0270=21271=820273=184819000336=2346=41023=1279=222=848=33890283=3685107=GEZ4 C9937269=0270=20.5271=500273=184819000336=2346=11023=2279=022=848=33890283=3686107=GEZ4 C9937269=0270=2271=12273=184819000336=2346=31023=3279=122=848=1924783=1579107=GEZ4 P9887269=1270=16271=580273=184819000336=2346=21023=1279=122=848=1924783=1580107=GEZ4 P9887269=1270=16.5271=100273=184819000336=2346=11023=210=241
1128=99=461035=X49=CME34=26594452=2013071516302378575=20130715268=46279=222=848=36716183=1482107=GEH5 C9275269=1270=644.5271=75273=163023000336=2346=11023=1279=022=848=36716183=1483107=GEH5 C9275269=1270=645271=75273=163023000336=2346=11023=1279=222=848=81378183=1482107=GEH5 C9300269=1270=619.5271=75273=163023000336=2346=11023=1279=022=848=81378183=1483107=GEH5 C9300269=1270=620271=75273=163023000336=2346=11023=1279=222=848=69003883=1482107=GEH5 C9325269=1270=594.5271=75273=163023000336=2346=11023=1279=022=848=69003883=1483107=GEH5 C9325269=1270=595271=75273=163023000336=2346=11023=1279=222=848=22104483=1474107=GEH5 C9350269=1270=569.5271=75273=163023000336=2346=11023=1279=022=848=22104483=1475107=GEH5 C9350269=1270=570271=75273=163023000336=2346=11023=1279=222=848=42903383=1466107=GEH5 C9375269=1270=544.5271=75273=163023000336=2346=11023=1279=022=848=42903383=1467107=GEH5 C9375269=1270=545271=75273=163023000336=2346=11023=1279=222=848=28285883=1466107=GEH5 C9400269=1270=519.5271=75273=163023000336=2346=11023=1279=022=848=28285883=1467107=GEH5 C9400269=1270=520271=75273=163023000336=2346=11023=1279=222=848=88240983=1463107=GEH5 C9425269=1270=494.5271=75273=163023000336=2346=11023=1279=022=848=88240983=1464107=GEH5 C9425269=1270=495271=75273=163023000336=2346=11023=1279=222=848=66100483=1407107=GEH5 C9450269=1270=469.5271=75273=163023000336=2346=11023=1279=022=848=66100483=1408107=GEH5 C9450269=1270=470271=75273=163023000336=2346=11023=1279=222=848=82053483=1443107=GEH5 C9475269=1270=445271=75273=163023000336=2346=11023=1279=022=848=82053483=1444107=GEH5 C9475269=1270=445.5271=75273=163023000336=2346=11023=1279=222=848=8373583=1439107=GEH5 C9500269=0270=417271=75273=163023000336=2346=11023=1279=022=848=8373583=1440107=GEH5 C9500269=0270=416.5271=75273=163023000336=2346=11023=1279=222=848=4430783=1287107=GEH5 C9525269=0270=392271=75273=163023000336=2346=11023=1279=022=848=4430783=1288107=GEH5 C9525269=0270=391.5271=75273=163023000336=2346=11023=1279=222=848=62816183=1150107=GEH5 C9650269=0270=269.5271=75273=163023000336=2346=11023=1279=022=848=62816183=1151107=GEH5 C9650269=0270=269271=75273=163023000336=2346=11023=1279=222=848=34473283=1435107=GEH5 C9550269=0270=367.5271=75273=163023000336=2346=11023=1279=022=848=34473283=1436107=GEH5 C9550269=0270=367271=75273=163023000336=2346=11023=1279=222=848=10624283=1355107=GEH5 C9575269=0270=343271=75273=163023000336=2346=11023=1279=022=848=10624283=1356107=GEH5 C9575269=0270=342.5271=75273=163023000336=2346=11023=1279=222=848=47804683=1190107=GEH5 C9600269=0270=318271=75273=163023000336=2346=11023=1279=022=848=47804683=1191107=GEH5 C9600269=0270=317.5271=75273=163023000336=2346=11023=1279=222=848=33797983=1294107=GEH5 C9625269=0270=293.5271=75273=163023000336=2346=11023=1279=022=848=33797983=1295107=GEH5 C9625269=0270=293271=75273=163023000336=2346=11023=1279=122=848=30528983=1822107=GEH5 C9875269=0270=62.5271=100273=163023000336=2346=11023=1279=022=848=30528983=1823107=GEH5 C9875269=0270=62271=150273=163023000336=2346=11023=2279=222=848=85323383=1350107=GEH5 C9675269=0270=245271=75273=163023000336=2346=11023=1279=022=848=85323383=1351107=GEH5 C9675269=0270=244.5271=75273=163023000336=2346=11023=1279=222=848=60573483=1378107=GEH5 C9687269=0270=233271=75273=163023000336=2346=11023=1279=022=848=60573483=1379107=GEH5 C9687269=0270=232.5271=75273=163023000336=2346=11023=1279=222=848=29853883=1302107=GEH5 C9700269=0270=221271=75273=163023000336=2346=11023=1279=022=848=29853883=1303107=GEH5 C9700269=0270=220.5271=75273=163023000336=2346=11023=1279=122=848=53035583=1922107=GEH5 C9750269=0270=173.5271=50273=163023000336=2346=11023=1279=022=848=53035583=1923107=GEH5 C9750269=0270=173271=75273=163023000336=2346=11023=2279=222=848=2319483=1280107=GEH5 C9712269=0270=209271=75273=163023000336=2346=11023=1279=022=848=2319483=1281107=GEH5 C9712269=0270=208.5271=75273=163023000336=2346=11023=1279=122=848=24341283=2401107=GEH5 C9725269=0270=197271=50273=163023000336=2346=11023=1279=022=848=24341283=2402107=GEH5 C9725269=0270=196.5271=75273=163023000336=2346=11023=210=117
1128=99=84535=X49=CME34=35292452=2013071519003594175=20130715268=8279=122=848=64443183=402107=GEM4 C9962269=1270=7.5271=833273=190035000336=2346=21023=1279=222=848=64443183=403107=GEM4 C9962269=1270=8271=333273=190035000336=2346=11023=2279=122=848=10324083=272107=GEM4 P9825269=0270=1.5271=1167273=190035000336=2346=41023=1279=122=848=29561183=324107=GEM4 P9875269=0270=3.5271=1167273=190035000336=2346=41023=1279=022=848=37100783=327107=GEM4 P9962269=0270=15271=125273=190035000336=2346=11023=1279=222=848=37100783=328107=GEM4 P9962269=0270=14.5271=125273=190035000336=2346=11023=2279=222=848=37100783=329107=GEM4 P9962269=1270=21271=125273=190035000336=2346=11023=1279=022=848=37100783=330107=GEM4 P9962269=1270=21.5271=125273=190035000336=2346=11023=110=131
1128=99=393835=X49=CME34=4141452=2013071511530777475=20130715268=40279=222=848=9143483=68107=GEZ4 C9775269=0270=158271=50273=115307000336=2346=11023=1279=022=848=9143483=69107=GEZ4 C9775269=0270=157.5271=50273=115307000336=2346=11023=1279=222=848=4525583=90107=GEZ4 C9812269=0270=123271=50273=115307000336=2346=11023=1279=022=848=4525583=91107=GEZ4 C9812269=0270=122.5271=50273=115307000336=2346=11023=1279=222=848=39402183=104107=GEZ4 C9787269=0270=146271=50273=115307000336=2346=11023=1279=022=848=39402183=105107=GEZ4 C9787269=0270=145.5271=50273=115307000336=2346=11023=1279=222=848=85416683=292107=GEZ4 C9900269=0270=46.5271=100273=115307000336=2346=11023=1279=122=848=85416683=293107=GEZ4 C9900269=0270=46271=250273=115307000336=2346=21023=1279=222=848=53128783=102107=GEZ4 C9800269=0270=134.5271=50273=115307000336=2346=11023=1279=022=848=53128783=103107=GEZ4 C9800269=0270=134271=50273=115307000336=2346=11023=1279=222=848=78552983=90107=GEZ4 C9825269=0270=111.5271=50273=115307000336=2346=11023=1279=022=848=78552983=91107=GEZ4 C9825269=0270=111271=50273=115307000336=2346=11023=1279=222=848=69664283=296107=GEZ4 C9912269=0270=37271=100273=115307000336=2346=11023=1279=122=848=69664283=297107=GEZ4 C9912269=0270=36.5271=250273=115307000336=2346=21023=1279=222=848=59315083=456107=GEZ4 C9837269=0270=100271=50273=115307000336=2346=11023=1279=022=848=59315083=457107=GEZ4 C9837269=0270=99.5271=50273=115307000336=2346=11023=1279=222=848=83496983=524107=GEZ4 P9950269=1270=35.5271=50273=115307000336=2346=11023=1279=022=848=83496983=525107=GEZ4 P9950269=1270=36271=50273=115307000336=2346=11023=1279=122=848=29271783=227107=GEZ4 P9862269=0270=12271=250273=115307000336=2346=21023=1279=222=848=29271783=228107=GEZ4 P9862269=0270=11.5271=100273=115307000336=2346=11023=2279=222=848=29271783=229107=GEZ4 P9862269=1270=14271=100273=115307000336=2346=11023=1279=122=848=29271783=230107=GEZ4 P9862269=1270=14.5271=250273=115307000336=2346=21023=1279=122=848=19489783=333107=GEZ4 P9850269=0270=10.5271=250273=115307000336=2346=21023=1279=222=848=19489783=334107=GEZ4 P9850269=0270=10271=100273=115307000336=2346=11023=2279=222=848=19489783=335107=GEZ4 P9850269=1270=12.5271=100273=115307000336=2346=11023=1279=122=848=19489783=336107=GEZ4 P9850269=1270=13271=250273=115307000336=2346=21023=1279=222=848=61714383=64107=GEH4 P9887269=1270=3.5271=150273=115307000336=2346=11023=1279=122=848=61714383=65107=GEH4 P9887269=1270=4271=350273=115307000336=2346=21023=1279=222=848=25292883=65107=GEH4 P9875269=1270=3271=150273=115307000336=2346=11023=1279=122=848=25292883=66107=GEH4 P9875269=1270=3.5271=350273=115307000336=2346=21023=1279=122=848=57397283=60107=GEZ4 P9775269=0270=5271=250273=115307000336=2346=21023=1279=222=848=57397283=61107=GEZ4 P9775269=0270=4.5271=100273=115307000336=2346=11023=2279=222=848=57397283=62107=GEZ4 P9775269=1270=7271=100273=115307000336=2346=11023=1279=122=848=57397283=63107=GEZ4 P9775269=1270=7.5271=250273=115307000336=2346=21023=1279=122=848=77202083=58107=GEZ4 P9750269=0270=4271=250273=115307000336=2346=21023=1279=222=848=77202083=59107=GEZ4 P9750269=0270=3.5271=100273=115307000336=2346=11023=2279=222=848=75959183=71107=GEZ4 P9575269=1270=2.5271=40273=115307000336=2346=11023=1279=122=848=75959183=72107=GEZ4 P9575269=1270=3271=200273=115307000336=2346=21023=1279=122=848=2150383=24107=GEU3 P9550269=1270=0.5271=51273=115307000336=2346=21023=1279=222=848=2150383=25107=GEU3 P9550269=1270=0.75271=50273=115307000336=2346=11023=210=009
1128=99=238535=X49=CME34=8064752=2013071512353454775=20130715268=24279=022=848=5086283=326107=GEM5 C9475269=0270=422.5271=7273=123534000336=2346=11023=1279=222=848=5086283=327107=GEM5 C9475269=0270=422271=7273=123534000336=2346=11023=2279=022=848=49073683=326107=GEM5 C9500269=0270=398271=7273=123534000336=2346=11023=1279=222=848=49073683=327107=GEM5 C9500269=0270=397.5271=7273=123534000336=2346=11023=2279=022=848=76523983=306107=GEM5 C9525269=0270=373271=7273=123534000336=2346=11023=1279=222=848=76523983=307107=GEM5 C9525269=0270=372.5271=7273=123534000336=2346=11023=2279=022=848=78551783=302107=GEM5 C9550269=0270=348.5271=7273=123534000336=2346=11023=1279=222=848=78551783=303107=GEM5 C9550269=0270=348271=7273=123534000336=2346=11023=2279=022=848=65500483=274107=GEM5 P9800269=1270=19271=75273=123534000336=2346=11023=1279=222=848=65500483=275107=GEM5 P9800269=1270=19.5271=75273=123534000336=2346=11023=2279=022=848=36022783=244107=GEM5 C9600269=0270=300271=7273=123534000336=2346=11023=1279=222=848=36022783=245107=GEM5 C9600269=0270=299.5271=7273=123534000336=2346=11023=2279=022=848=31862183=266107=GEM5 C9650269=0270=251.5271=7273=123534000336=2346=11023=1279=222=848=31862183=267107=GEM5 C9650269=0270=251271=7273=123534000336=2346=11023=2279=022=848=87547883=310107=GEM5 C9675269=0270=228271=7273=123534000336=2346=11023=1279=222=848=87547883=311107=GEM5 C9675269=0270=227.5271=7273=123534000336=2346=11023=2279=022=848=25674883=220107=GEM5 C9725269=0270=181271=7273=123534000336=2346=11023=1279=222=848=25674883=221107=GEM5 C9725269=0270=180.5271=7273=123534000336=2346=11023=2279=022=848=1469183=280107=GEM5 P9787269=1270=17.5271=75273=123534000336=2346=11023=1279=222=848=1469183=281107=GEM5 P9787269=1270=18271=75273=123534000336=2346=11023=2279=022=848=67915383=258107=GEM5 C9737269=0270=169.5271=7273=123534000336=2346=11023=1279=222=848=67915383=259107=GEM5 C9737269=0270=169271=7273=123534000336=2346=11023=2279=022=848=30078683=200107=GEM5 P9775269=1270=16271=75273=123534000336=2346=11023=1279=222=848=30078683=201107=GEM5 P9775269=1270=16.5271=75273=123534000336=2346=11023=210=125
1128=99=322135=X49=CME34=21446052=2013071515031671875=20130715268=32279=022=848=65502783=753107=GEZ4 C9475269=1270=458271=50273=150316000336=2346=11023=1279=222=848=65502783=754107=GEZ4 C9475269=1270=458.5271=50273=150316000336=2346=11023=2279=122=848=77877483=1101107=GEZ4 C9737269=1270=199271=150273=150316000336=2346=21023=1279=122=848=27637283=1226107=GEZ4 C9687269=1270=247.5271=100273=150316000336=2346=21023=1279=222=848=27637283=1227107=GEZ4 C9687269=1270=248271=50273=150316000336=2346=11023=2279=122=848=84740383=1044107=GEZ4 C9725269=1270=211271=100273=150316000336=2346=21023=1279=222=848=84740383=1045107=GEZ4 C9725269=1270=211.5271=50273=150316000336=2346=11023=2279=122=848=69664283=1329107=GEZ4 C9912269=1270=40.5271=300273=150316000336=2346=31023=1279=222=848=69664283=1330107=GEZ4 C9912269=1270=41271=100273=150316000336=2346=11023=2279=122=848=4525583=1007107=GEZ4 C9812269=1270=127.5271=250273=150316000336=2346=31023=1279=122=848=62233683=2676107=GEZ4 C9925269=1270=31271=1000273=150316000336=2346=41023=1279=222=848=62233683=2677107=GEZ4 C9925269=1270=31.5271=100273=150316000336=2346=11023=2279=122=848=53128783=1274107=GEZ4 C9800269=1270=139.5271=150273=150316000336=2346=21023=2279=222=848=53128783=1275107=GEZ4 C9800269=1270=140271=50273=150316000336=2346=11023=3279=122=848=84066783=1909107=GEZ4 P9925269=0270=23271=300273=150316000336=2346=31023=1279=222=848=84066783=1910107=GEZ4 P9925269=0270=22.5271=100273=150316000336=2346=11023=2279=022=848=84066783=1911107=GEZ4 P9925269=0270=0.5271=4273=150316000336=2346=11023=3279=122=848=39402183=1036107=GEZ4 C9787269=1270=151271=250273=150316000336=2346=31023=1279=122=848=87658983=1644107=GEZ4 P9912269=0270=19.5271=233273=150316000336=2346=21023=2279=122=848=10714983=1696107=GEZ4 C9862269=1270=82271=243273=150316000336=2346=31023=1279=122=848=66177783=1459107=GEZ4 C9850269=1270=93271=250273=150316000336=2346=31023=1279=222=848=66177783=1460107=GEZ4 C9850269=1270=93.5271=50273=150316000336=2346=11023=2279=122=848=78552983=1293107=GEZ4 C9825269=1270=116271=243273=150316000336=2346=31023=1279=022=848=59315083=1553107=GEZ4 C9837269=1270=104.5271=50273=150316000336=2346=11023=2279=222=848=59315083=1554107=GEZ4 C9837269=1270=105271=50273=150316000336=2346=11023=3279=122=848=25677583=2253107=GEZ4 P9900269=0270=17271=333273=150316000336=2346=31023=1279=122=848=1924783=1192107=GEZ4 P9887269=0270=15271=300273=150316000336=2346=31023=1279=122=848=1924783=1193107=GEZ4 P9887269=0270=14.5271=500273=150316000336=2346=11023=2279=122=848=38159883=1073107=GEZ4 P9875269=0270=13271=333273=150316000336=2346=31023=1279=122=848=29271783=838107=GEZ4 P9862269=0270=11.5271=300273=150316000336=2346=31023=1279=122=848=29271783=839107=GEZ4 P9862269=0270=11271=500273=150316000336=2346=11023=2279=122=848=27027983=863107=GEZ4 P9800269=0270=6271=333273=150316000336=2346=31023=110=087
1128=99=290935=X49=CME34=12810552=2013071513210864775=20130715268=29279=122=848=11386283=1611107=GEZ4 P9937269=0270=27271=100273=132108000336=2346=11023=1279=122=848=11386283=1612107=GEZ4 P9937269=0270=26.5271=600273=132108000336=2346=21023=2279=122=848=59315083=1131107=GEZ4 C9837269=1270=104271=140273=132108000336=2346=21023=1279=122=848=62233683=2039107=GEZ4 C9925269=1270=31271=100273=132108000336=2346=11023=2279=022=848=62233683=2040107=GEZ4 C9925269=1270=31.5271=100273=132108000336=2346=11023=3279=122=848=84066783=1164107=GEZ4 P9925269=0270=23271=180273=132108000336=2346=21023=1279=122=848=87658983=1070107=GEZ4 P9912269=0270=20271=100273=132108000336=2346=11023=1279=122=848=87658983=1071107=GEZ4 P9912269=0270=19.5271=600273=132108000336=2346=21023=2279=122=848=83496983=1240107=GEZ4 P9950269=0270=31.5271=140273=132108000336=2346=21023=1279=122=848=1924783=921107=GEZ4 P9887269=0270=15271=180273=132108000336=2346=21023=1279=122=848=38159883=817107=GEZ4 P9875269=0270=13271=680273=132108000336=2346=31023=1279=122=848=29271783=451107=GEZ4 P9862269=0270=11.5271=180273=132108000336=2346=21023=1279=122=848=19489783=608107=GEZ4 P9850269=0270=10271=680273=132108000336=2346=31023=1279=122=848=70448783=1420107=GEZ4 P9650269=0270=1.5271=180273=132108000336=2346=21023=1279=122=848=44913883=176107=GEZ4 P9625269=0270=1271=90273=132108000336=2346=21023=1279=222=848=33890283=2408107=GEZ4 C9937269=1270=22271=500273=132108000336=2346=11023=1279=122=848=33890283=2409107=GEZ4 C9937269=1270=22.5271=700273=132108000336=2346=31023=1279=222=848=62233683=2041107=GEZ4 C9925269=1270=30.5271=500273=132108000336=2346=11023=1279=122=848=62233683=2042107=GEZ4 C9925269=1270=31271=600273=132108000336=2346=21023=1279=222=848=2976083=140107=GEZ4 C9987269=1270=2271=500273=132108000336=2346=11023=1279=022=848=2976083=141107=GEZ4 C9987269=1270=2.5271=500273=132108000336=2346=11023=1279=222=848=37484883=1132107=GEZ4 P9700269=0270=2271=500273=132108000336=2346=11023=2279=022=848=37484883=1133107=GEZ4 P9700269=0270=1.5271=500273=132108000336=2346=11023=2279=122=848=19489783=609107=GEZ4 P9850269=0270=10271=180273=132108000336=2346=21023=1279=022=848=19489783=610107=GEZ4 P9850269=0270=9.5271=500273=132108000336=2346=11023=2279=122=848=38159883=818107=GEZ4 P9875269=0270=13271=180273=132108000336=2346=21023=1279=022=848=38159883=819107=GEZ4 P9875269=0270=12.5271=500273=132108000336=2346=11023=2279=122=848=25677583=1869107=GEZ4 P9900269=0270=17271=200273=132108000336=2346=21023=1279=022=848=25677583=1870107=GEZ4 P9900269=0270=16.5271=500273=132108000336=2346=11023=210=150
1128=99=15735=X49=CME34=8060052=2013071512353392775=20130715268=1279=122=848=31721683=342107=GEU4 P9900269=0270=10271=290273=123533000336=2346=31023=110=171
1128=99=25935=X49=CME34=36958052=2013071519443696475=20130715268=2279=222=848=31721683=1307107=GEU4 P9900269=1270=11271=225273=194436000336=2346=11023=1279=022=848=31721683=1308107=GEU4 P9900269=1270=15.5271=125273=194436000336=2346=11023=310=180
1128=99=25735=X49=CME34=30536252=2013071517233365475=20130715268=2279=222=848=37100783=285107=GEM4 P9962269=1270=21.5271=125273=172333000336=2346=11023=1279=022=848=37100783=286107=GEM4 P9962269=1270=22271=125273=172333000336=2346=11023=110=042
1128=99=35535=X49=CME34=14523252=2013071513391713175=20130715268=3279=222=848=31721683=556107=GEU4 P9900269=0270=10.5271=33273=133917000336=2346=11023=1279=022=848=31721683=557107=GEU4 P9900269=0270=8.5271=10273=133917000336=2346=11023=3279=122=848=31721683=558107=GEU4 P9900269=1270=11.5271=730273=133917000336=2346=21023=110=078
1128=99=84835=X49=CME34=27733952=2013071516432548575=20130715268=8279=122=848=27027983=1095107=GEZ4 P9800269=1270=7.5271=735273=164325000336=2346=31023=1279=122=848=27027983=1096107=GEZ4 P9800269=1270=8271=100273=164325000336=2346=11023=2279=122=848=33890283=3271107=GEZ4 C9937269=1270=22.5271=83273=164325000336=2346=21023=1279=122=848=7827083=1514107=GEZ4 C9950269=0270=13271=1167273=164325000336=2346=41023=1279=222=848=7827083=1515107=GEZ4 C9950269=1270=14.5271=33273=164325000336=2346=11023=1279=022=848=7827083=1516107=GEZ4 C9950269=1270=17271=125273=164325000336=2346=11023=2279=122=848=1924783=1359107=GEZ4 P9887269=0270=14.5271=300273=164325000336=2346=31023=1279=122=848=1924783=1360107=GEZ4 P9887269=1270=16.5271=1167273=164325000336=2346=41023=110=205
1128=99=74435=X49=CME34=11982452=2013071513113374975=20130715268=7279=122=848=30804883=564107=GEM4 C9887269=0270=68271=208273=131133000336=2346=31023=1279=122=848=30804883=565107=GEM4 C9887269=1270=70.5271=250273=131133000336=2346=31023=1279=222=848=30804883=566107=GEM4 C9887269=1270=72.5271=125273=131133000336=2346=11023=2279=122=848=81762683=232107=GEM4 P9812269=1270=2.5271=530273=131133000336=2346=21023=1279=122=848=81762683=233107=GEM4 P9812269=1270=3271=200273=131133000336=2346=21023=2279=022=848=37100783=77107=GEM4 P9962269=1270=21271=125273=131133000336=2346=11023=1279=222=848=37100783=78107=GEM4 P9962269=1270=21.5271=125273=131133000336=2346=11023=210=219
1128=99=44835=X49=CME34=12003852=2013071513120070775=20130715268=4279=222=848=81870783=443107=GEU4 P9650269=0270=0.5271=33273=131200000336=2346=11023=1279=122=848=81870783=444107=GEU4 P9650269=1270=2271=220273=131200000336=2346=31023=2279=122=848=31721683=413107=GEU4 P9900269=0270=10271=367273=131200000336=2346=31023=1279=122=848=31721683=414107=GEU4 P9900269=1270=11271=730273=131200000336=2346=21023=110=042
1128=99=84935=X49=CME34=22150152=2013071515111274975=20130715268=8279=222=848=29853883=1086107=GEH5 C9700269=0270=220.5271=75273=151112000336=2346=11023=1279=022=848=29853883=1087107=GEH5 C9700269=0270=220271=75273=151112000336=2346=11023=1279=022=848=29853883=1088107=GEH5 C9700269=1270=223.5271=75273=151112000336=2346=11023=1279=222=848=29853883=1089107=GEH5 C9700269=1270=224271=75273=151112000336=2346=11023=2279=222=848=2319483=1064107=GEH5 C9712269=0270=208.5271=75273=151112000336=2346=11023=1279=022=848=2319483=1065107=GEH5 C9712269=0270=208271=75273=151112000336=2346=11023=1279=022=848=2319483=1066107=GEH5 C9712269=1270=211.5271=75273=151112000336=2346=11023=1279=222=848=2319483=1067107=GEH5 C9712269=1270=212271=75273=151112000336=2346=11023=210=197
1128=99=180735=X49=CME34=10352952=2013071512494893975=20130715268=18279=022=848=87547883=484107=GEM5 C9675269=1270=235271=7273=124948000336=2346=11023=1279=222=848=87547883=485107=GEM5 C9675269=1270=235.5271=7273=124948000336=2346=11023=2279=022=848=31862183=434107=GEM5 C9650269=1270=259271=7273=124948000336=2346=11023=1279=222=848=31862183=435107=GEM5 C9650269=1270=259.5271=7273=124948000336=2346=11023=2279=022=848=25674883=394107=GEM5 C9725269=1270=188271=7273=124948000336=2346=11023=1279=222=848=25674883=395107=GEM5 C9725269=1270=188.5271=7273=124948000336=2346=11023=2279=022=848=88898983=426107=GEM5 C9700269=1270=211.5271=7273=124948000336=2346=11023=1279=222=848=88898983=427107=GEM5 C9700269=1270=212271=7273=124948000336=2346=11023=2279=022=848=67915383=428107=GEM5 C9737269=1270=176.5271=7273=124948000336=2346=11023=1279=222=848=67915383=429107=GEM5 C9737269=1270=177271=7273=124948000336=2346=11023=2279=122=848=1469183=412107=GEM5 P9787269=0270=14271=575273=124948000336=2346=21023=1279=222=848=1469183=413107=GEM5 P9787269=0270=13.5271=75273=124948000336=2346=11023=2279=022=848=20191983=581107=GEM5 C9937269=1270=19271=75273=124948000336=2346=11023=1279=222=848=20191983=582107=GEM5 C9937269=1270=19.5271=75273=124948000336=2346=11023=2279=122=848=25917983=300107=GEM5 P9762269=0270=11.5271=575273=124948000336=2346=21023=1279=222=848=25917983=301107=GEM5 P9762269=0270=11271=75273=124948000336=2346=11023=2279=022=848=10841283=326107=GEM5 P9725269=0270=8.5271=75273=124948000336=2346=11023=1279=122=848=10841283=327107=GEM5 P9725269=0270=8271=500273=124948000336=2346=11023=210=080
1128=99=320835=X49=CME34=16447952=2013071514023059275=20130715268=32279=022=848=38558383=499107=GEU4 C9787269=0270=157271=100273=140230000336=2346=11023=1279=122=848=38558383=500107=GEU4 C9787269=0270=156.5271=75273=140230000336=2346=11023=2279=022=848=50150483=485107=GEU4 C9800269=0270=145271=100273=140230000336=2346=11023=1279=122=848=50150483=486107=GEU4 C9800269=0270=144.5271=75273=140230000336=2346=11023=2279=122=848=26751483=680107=GEU4 C9862269=0270=86271=227273=140230000336=2346=31023=1279=022=848=65225983=503107=GEU4 C9812269=0270=133271=100273=140230000336=2346=11023=1279=122=848=65225983=504107=GEU4 C9812269=0270=132.5271=75273=140230000336=2346=11023=2279=122=848=63875283=793107=GEU4 C9887269=0270=63.5271=227273=140230000336=2346=31023=1279=122=848=48015183=645107=GEU4 C9912269=0270=42271=287273=140230000336=2346=31023=1279=122=848=28101983=459107=GEU4 C9575269=0270=366.5271=125273=140230000336=2346=21023=1279=022=848=82437483=597107=GEU4 C9625269=0270=317271=50273=140230000336=2346=11023=1279=122=848=82437483=598107=GEU4 C9625269=0270=316.5271=75273=140230000336=2346=11023=2279=022=848=59714083=401107=GEU4 C9650269=0270=292271=50273=140230000336=2346=11023=1279=122=848=59714083=402107=GEU4 C9650269=0270=291.5271=75273=140230000336=2346=11023=2279=022=848=43962583=619107=GEU4 C9675269=0270=267.5271=50273=140230000336=2346=11023=1279=122=848=43962583=620107=GEU4 C9675269=0270=267271=75273=140230000336=2346=11023=2279=022=848=19213083=454107=GEU4 C9687269=0270=255271=50273=140230000336=2346=11023=1279=122=848=19213083=455107=GEU4 C9687269=0270=254.5271=75273=140230000336=2346=11023=2279=022=848=37775283=570107=GEU4 C9712269=0270=230.5271=50273=140230000336=2346=11023=1279=122=848=37775283=571107=GEU4 C9712269=0270=230271=75273=140230000336=2346=11023=2279=022=848=21239383=414107=GEU4 C9725269=0270=218271=50273=140230000336=2346=11023=1279=122=848=21239383=415107=GEU4 C9725269=0270=217.5271=75273=140230000336=2346=11023=2279=022=848=88624883=423107=GEU4 C9750269=0270=193.5271=50273=140230000336=2346=11023=1279=122=848=88624883=424107=GEU4 C9750269=0270=193271=75273=140230000336=2346=11023=2279=022=848=89300283=501107=GEU4 C9762269=0270=181.5271=50273=140230000336=2346=11023=1279=122=848=89300283=502107=GEU4 C9762269=0270=181271=75273=140230000336=2346=11023=2279=122=848=30912183=886107=GEU4 C9850269=0270=97.5271=227273=140230000336=2346=31023=1279=122=848=89976083=1293107=GEU4 C9937269=0270=22.5271=287273=140230000336=2346=31023=1279=122=848=89976083=1294107=GEU4 C9937269=0270=22271=500273=140230000336=2346=11023=2279=122=848=66578483=778107=GEU4 P9912269=1270=13.5271=1087273=140230000336=2346=41023=1279=122=848=31721683=644107=GEU4 P9900269=1270=11.5271=1053273=140230000336=2346=41023=1279=222=848=31721683=645107=GEU4 P9900269=1270=12271=100273=140230000336=2346=11023=210=070
1128=99=64535=X49=CME34=4010552=2013071511495023375=20130715268=6279=222=848=33890283=1826107=GEZ4 C9937269=1270=22271=100273=114950000336=2346=11023=1279=122=848=33890283=1827107=GEZ4 C9937269=1270=22.5271=250273=114950000336=2346=21023=1279=022=848=1924783=387107=GEZ4 P9887269=0270=15.5271=80273=114950000336=2346=11023=1279=122=848=1924783=388107=GEZ4 P9887269=0270=15271=150273=114950000336=2346=11023=2279=122=848=1924783=389107=GEZ4 P9887269=1270=17.5271=250273=114950000336=2346=21023=1279=222=848=1924783=390107=GEZ4 P9887269=1270=18271=100273=114950000336=2346=11023=210=046
1128=99=25735=X49=CME34=23421152=2013071515362780575=20130715268=2279=222=848=37100783=245107=GEM4 P9962269=1270=21.5271=125273=153627000336=2346=11023=1279=022=848=37100783=246107=GEM4 P9962269=1270=22271=125273=153627000336=2346=11023=110=041
1128=99=163235=X49=CME34=33113552=2013071518150666775=20130715268=16279=122=848=52467883=2954107=GEH5 P9875269=1270=22.5271=725273=181506000336=2346=31023=1279=222=848=52467883=2955107=GEH5 P9875269=1270=23271=150273=181506000336=2346=11023=2279=222=848=75866783=3172107=GEH5 P9862269=0270=18271=150273=181506000336=2346=11023=1279=122=848=75866783=3173107=GEH5 P9862269=0270=17.5271=650273=181506000336=2346=21023=1279=122=848=14563083=3148107=GEH5 C9925269=0270=26271=983273=181506000336=2346=31023=1279=222=848=14563083=3149107=GEH5 C9925269=0270=25.5271=150273=181506000336=2346=11023=2279=222=848=25692083=2944107=GEH5 P9850269=0270=16271=150273=181506000336=2346=11023=1279=122=848=25692083=2945107=GEH5 P9850269=0270=15.5271=650273=181506000336=2346=21023=1279=222=848=54386083=2079107=GEH5 C9937269=1270=20.5271=150273=181506000336=2346=11023=1279=122=848=54386083=2080107=GEH5 C9937269=1270=21271=650273=181506000336=2346=21023=1279=022=848=32555383=611107=GEH5 P9737269=1270=8271=150273=181506000336=2346=11023=2279=122=848=32555383=612107=GEH5 P9737269=1270=8.5271=17273=181506000336=2346=11023=3279=222=848=38742583=792107=GEH5 P9675269=0270=3.5271=150273=181506000336=2346=11023=1279=022=848=38742583=793107=GEH5 P9675269=0270=3271=150273=181506000336=2346=11023=1279=022=848=38742583=794107=GEH5 P9675269=1270=5.5271=150273=181506000336=2346=11023=2279=122=848=38742583=795107=GEH5 P9675269=1270=6271=12273=181506000336=2346=11023=310=124
1128=99=25735=X49=CME34=16372552=2013071514020525875=20130715268=2279=022=848=37100783=179107=GEM4 P9962269=1270=21.5271=125273=140205000336=2346=11023=1279=222=848=37100783=180107=GEM4 P9962269=1270=22271=125273=140205000336=2346=11023=210=022
1128=99=466335=X49=CME34=14663752=2013071513401687275=20130715268=47279=022=848=36716183=764107=GEH5 C9275269=0270=641.5271=75273=134016000336=2346=11023=1279=222=848=36716183=765107=GEH5 C9275269=0270=641271=75273=134016000336=2346=11023=2279=022=848=81378183=764107=GEH5 C9300269=0270=616.5271=75273=134016000336=2346=11023=1279=222=848=81378183=765107=GEH5 C9300269=0270=616271=75273=134016000336=2346=11023=2279=022=848=69003883=764107=GEH5 C9325269=0270=591.5271=75273=134016000336=2346=11023=1279=222=848=69003883=765107=GEH5 C9325269=0270=591271=75273=134016000336=2346=11023=2279=022=848=22104483=764107=GEH5 C9350269=0270=566.5271=75273=134016000336=2346=11023=1279=222=848=22104483=765107=GEH5 C9350269=0270=566271=75273=134016000336=2346=11023=2279=022=848=42903383=756107=GEH5 C9375269=0270=541.5271=75273=134016000336=2346=11023=1279=222=848=42903383=757107=GEH5 C9375269=0270=541271=75273=134016000336=2346=11023=2279=022=848=28285883=756107=GEH5 C9400269=0270=516.5271=75273=134016000336=2346=11023=1279=222=848=28285883=757107=GEH5 C9400269=0270=516271=75273=134016000336=2346=11023=2279=022=848=88240983=753107=GEH5 C9425269=0270=491.5271=75273=134016000336=2346=11023=1279=222=848=88240983=754107=GEH5 C9425269=0270=491271=75273=134016000336=2346=11023=2279=022=848=66100483=697107=GEH5 C9450269=0270=466.5271=75273=134016000336=2346=11023=1279=222=848=66100483=698107=GEH5 C9450269=0270=466271=75273=134016000336=2346=11023=2279=022=848=82053483=741107=GEH5 C9475269=0270=442271=75273=134016000336=2346=11023=1279=222=848=82053483=742107=GEH5 C9475269=0270=441.5271=75273=134016000336=2346=11023=2279=022=848=72272783=901107=GEH5 C9850269=0270=83271=75273=134016000336=2346=11023=1279=122=848=72272783=902107=GEH5 C9850269=0270=82.5271=100273=134016000336=2346=11023=2279=122=848=72272783=903107=GEH5 C9850269=1270=86.5271=75273=134016000336=2346=11023=1279=022=848=8373583=741107=GEH5 C9500269=0270=417271=75273=134016000336=2346=11023=1279=222=848=8373583=742107=GEH5 C9500269=0270=416.5271=75273=134016000336=2346=11023=2279=022=848=4430783=677107=GEH5 C9525269=0270=392271=75273=134016000336=2346=11023=1279=222=848=4430783=678107=GEH5 C9525269=0270=391.5271=75273=134016000336=2346=11023=2279=022=848=62816183=628107=GEH5 C9650269=0270=269.5271=75273=134016000336=2346=11023=1279=222=848=62816183=629107=GEH5 C9650269=0270=269271=75273=134016000336=2346=11023=2279=022=848=34473283=737107=GEH5 C9550269=0270=367.5271=75273=134016000336=2346=11023=1279=222=848=34473283=738107=GEH5 C9550269=0270=367271=75273=134016000336=2346=11023=2279=022=848=10624283=661107=GEH5 C9575269=0270=343271=75273=134016000336=2346=11023=1279=222=848=10624283=662107=GEH5 C9575269=0270=342.5271=75273=134016000336=2346=11023=2279=022=848=47804683=680107=GEH5 C9600269=0270=318271=75273=134016000336=2346=11023=1279=222=848=47804683=681107=GEH5 C9600269=0270=317.5271=75273=134016000336=2346=11023=2279=022=848=33797983=684107=GEH5 C9625269=0270=293.5271=75273=134016000336=2346=11023=1279=222=848=33797983=685107=GEH5 C9625269=0270=293271=75273=134016000336=2346=11023=2279=022=848=30528983=832107=GEH5 C9875269=0270=62.5271=150273=134016000336=2346=11023=1279=122=848=30528983=833107=GEH5 C9875269=0270=62271=100273=134016000336=2346=11023=2279=022=848=85323383=656107=GEH5 C9675269=0270=245271=75273=134016000336=2346=11023=1279=222=848=85323383=657107=GEH5 C9675269=0270=244.5271=75273=134016000336=2346=11023=2279=022=848=60573483=684107=GEH5 C9687269=0270=233271=75273=134016000336=2346=11023=1279=222=848=60573483=685107=GEH5 C9687269=0270=232.5271=75273=134016000336=2346=11023=2279=022=848=29853883=608107=GEH5 C9700269=0270=221271=75273=134016000336=2346=11023=1279=222=848=29853883=609107=GEH5 C9700269=0270=220.5271=75273=134016000336=2346=11023=2279=022=848=53035583=1003107=GEH5 C9750269=0270=173.5271=75273=134016000336=2346=11023=1279=122=848=53035583=1004107=GEH5 C9750269=0270=173271=50273=134016000336=2346=11023=2279=022=848=2319483=586107=GEH5 C9712269=0270=209271=75273=134016000336=2346=11023=1279=222=848=2319483=587107=GEH5 C9712269=0270=208.5271=75273=134016000336=2346=11023=210=111
1128=99=165035=X49=CME34=24705352=2013071515555263575=20130715268=16279=122=848=11386283=2622107=GEZ4 P9937269=1270=28.5271=1053273=155552000336=2346=31023=1279=022=848=11386283=2623107=GEZ4 P9937269=1270=29271=100273=155552000336=2346=11023=2279=122=848=62233683=2824107=GEZ4 C9925269=0270=29.5271=233273=155552000336=2346=21023=1279=122=848=62233683=2825107=GEZ4 C9925269=0270=29271=600273=155552000336=2346=21023=2279=122=848=53128783=1408107=GEZ4 C9800269=0270=137271=167273=155552000336=2346=21023=1279=022=848=53128783=1409107=GEZ4 C9800269=0270=136271=50273=155552000336=2346=11023=2279=122=848=84066783=2184107=GEZ4 P9925269=1270=24.5271=805273=155552000336=2346=31023=1279=022=848=84066783=2185107=GEZ4 P9925269=1270=25.5271=100273=155552000336=2346=11023=2279=122=848=4525583=1177107=GEZ4 C9812269=0270=125.5271=67273=155552000336=2346=11023=1279=022=848=4525583=1178107=GEZ4 C9812269=0270=124.5271=50273=155552000336=2346=11023=3279=122=848=59315083=1814107=GEZ4 C9837269=0270=102.5271=117273=155552000336=2346=21023=1279=022=848=59315083=1815107=GEZ4 C9837269=0270=101.5271=50273=155552000336=2346=11023=2279=122=848=66177783=1576107=GEZ4 C9850269=0270=91271=167273=155552000336=2346=21023=1279=022=848=66177783=1577107=GEZ4 C9850269=0270=90.5271=50273=155552000336=2346=11023=2279=122=848=13981783=1517107=GEZ4 C9875269=0270=69271=300273=155552000336=2346=31023=1279=122=848=13981783=1518107=GEZ4 C9875269=1270=71.5271=100273=155552000336=2346=11023=210=115
1128=99=25735=X49=CME34=35261552=2013071518595857375=20130715268=2279=222=848=37100783=319107=GEM4 P9962269=1270=21271=125273=185958000336=2346=11023=1279=022=848=37100783=320107=GEM4 P9962269=1270=21.5271=125273=185958000336=2346=11023=110=082
1128=99=277735=X49=CME34=13784052=2013071513303844775=20130715268=28279=022=848=46263783=822107=GEM5 C9400269=1270=503271=7273=133038000336=2346=11023=1279=222=848=46263783=823107=GEM5 C9400269=1270=503.5271=7273=133038000336=2346=11023=2279=022=848=64149383=822107=GEM5 C9425269=1270=478271=7273=133038000336=2346=11023=1279=222=848=64149383=823107=GEM5 C9425269=1270=478.5271=7273=133038000336=2346=11023=2279=022=848=74497883=812107=GEM5 C9450269=1270=453.5271=7273=133038000336=2346=11023=1279=222=848=74497883=813107=GEM5 C9450269=1270=454271=7273=133038000336=2346=11023=2279=122=848=65500483=528107=GEM5 P9800269=0270=16271=575273=133038000336=2346=21023=1279=222=848=65500483=529107=GEM5 P9800269=0270=15.5271=75273=133038000336=2346=11023=2279=022=848=5086283=822107=GEM5 C9475269=1270=428.5271=7273=133038000336=2346=11023=1279=222=848=5086283=823107=GEM5 C9475269=1270=429271=7273=133038000336=2346=11023=2279=022=848=49073683=822107=GEM5 C9500269=1270=404271=7273=133038000336=2346=11023=1279=222=848=49073683=823107=GEM5 C9500269=1270=404.5271=7273=133038000336=2346=11023=2279=022=848=78551783=782107=GEM5 C9550269=1270=354.5271=7273=133038000336=2346=11023=1279=222=848=78551783=783107=GEM5 C9550269=1270=355271=7273=133038000336=2346=11023=2279=022=848=31862183=680107=GEM5 C9650269=1270=257.5271=7273=133038000336=2346=11023=1279=222=848=31862183=681107=GEM5 C9650269=1270=258271=7273=133038000336=2346=11023=2279=022=848=36022783=740107=GEM5 C9600269=1270=306271=7273=133038000336=2346=11023=1279=222=848=36022783=741107=GEM5 C9600269=1270=306.5271=7273=133038000336=2346=11023=2279=022=848=87547883=766107=GEM5 C9675269=1270=234271=7273=133038000336=2346=11023=1279=222=848=87547883=767107=GEM5 C9675269=1270=234.5271=7273=133038000336=2346=11023=2279=122=848=1469183=618107=GEM5 P9787269=0270=14.5271=575273=133038000336=2346=21023=1279=222=848=1469183=619107=GEM5 P9787269=0270=14271=75273=133038000336=2346=11023=2279=022=848=25674883=672107=GEM5 C9725269=1270=187271=7273=133038000336=2346=11023=1279=222=848=25674883=673107=GEM5 C9725269=1270=187.5271=7273=133038000336=2346=11023=2279=022=848=67915383=702107=GEM5 C9737269=1270=175.5271=7273=133038000336=2346=11023=1279=222=848=67915383=703107=GEM5 C9737269=1270=176271=7273=133038000336=2346=11023=2279=122=848=30078683=494107=GEM5 P9775269=0270=13271=575273=133038000336=2346=21023=1279=222=848=30078683=495107=GEM5 P9775269=0270=12.5271=75273=133038000336=2346=11023=210=057
1128=99=45235=X49=CME34=9616052=2013071512435305475=20130715268=4279=122=848=33890283=2203107=GEZ4 C9937269=1270=23271=633273=124353000336=2346=31023=1279=022=848=33890283=2204107=GEZ4 C9937269=1270=23.5271=500273=124353000336=2346=11023=2279=122=848=1924783=695107=GEZ4 P9887269=0270=14.5271=180273=124353000336=2346=11023=1279=122=848=1924783=696107=GEZ4 P9887269=0270=14271=700273=124353000336=2346=31023=210=092
1128=99=35135=X49=CME34=8018852=2013071512353019575=20130715268=3279=222=848=50824983=186107=GEM4 P9737269=0270=0.5271=67273=123530000336=2346=11023=1279=022=848=37100783=37107=GEM4 P9962269=1270=21271=125273=123530000336=2346=11023=1279=222=848=37100783=38107=GEM4 P9962269=1270=21.5271=125273=123530000336=2346=11023=210=109
1128=99=104635=X49=CME34=34766952=2013071518482357275=20130715268=10279=122=848=11386283=3634107=GEZ4 P9937269=1270=27.5271=325273=184823000336=2346=11023=1279=122=848=11386283=3635107=GEZ4 P9937269=1270=28271=600273=184823000336=2346=21023=2279=122=848=88900683=585107=GEZ4 C9962269=0270=7271=333273=184823000336=2346=11023=1279=022=848=88900683=586107=GEZ4 C9962269=0270=6.5271=500273=184823000336=2346=11023=2279=122=848=62233683=3491107=GEZ4 C9925269=0270=29.5271=667273=184823000336=2346=31023=1279=022=848=62233683=3492107=GEZ4 C9925269=0270=29271=500273=184823000336=2346=11023=2279=122=848=33890283=3689107=GEZ4 C9937269=0270=21271=647273=184823000336=2346=31023=1279=022=848=33890283=3690107=GEZ4 C9937269=0270=20.5271=500273=184823000336=2346=11023=2279=122=848=1924783=1585107=GEZ4 P9887269=1270=16271=210273=184823000336=2346=11023=1279=122=848=1924783=1586107=GEZ4 P9887269=1270=16.5271=700273=184823000336=2346=31023=210=012
1128=99=25735=X49=CME34=15337952=2013071513480645475=20130715268=2279=022=848=37100783=159107=GEM4 P9962269=1270=21.5271=125273=134806000336=2346=11023=1279=222=848=37100783=160107=GEM4 P9962269=1270=22271=125273=134806000336=2346=11023=210=050
1128=99=275835=X49=CME34=3411252=2013071509564554475=20130715268=28279=222=848=11386283=192107=GEZ4 P9937269=0270=27271=500273=95645000336=2346=11023=1279=022=848=11386283=193107=GEZ4 P9937269=0270=26.5271=500273=95645000336=2346=11023=1279=222=848=84066783=161107=GEZ4 P9925269=0270=23271=500273=95645000336=2346=11023=1279=122=848=84066783=162107=GEZ4 P9925269=0270=22.5271=650273=95645000336=2346=21023=1279=022=848=33890283=604107=GEZ4 C9937269=0270=20.5271=500273=95645000336=2346=11023=1279=122=848=33890283=605107=GEZ4 C9937269=0270=20271=150273=95645000336=2346=11023=2279=222=848=7827083=153107=GEZ4 C9950269=1270=14.5271=500273=95645000336=2346=11023=1279=122=848=7827083=154107=GEZ4 C9950269=1270=15271=650273=95645000336=2346=21023=1279=022=848=62233683=459107=GEZ4 C9925269=0270=29271=500273=95645000336=2346=11023=1279=122=848=62233683=460107=GEZ4 C9925269=0270=28.5271=150273=95645000336=2346=11023=2279=022=848=43671583=400107=GEZ4 P9787269=1270=7271=500273=95645000336=2346=11023=1279=122=848=43671583=401107=GEZ4 P9787269=1270=7.5271=150273=95645000336=2346=11023=2279=222=848=3855283=68107=GEZ4 P9812269=0270=7271=500273=95645000336=2346=11023=1279=122=848=3855283=69107=GEZ4 P9812269=0270=6.5271=650273=95645000336=2346=21023=1279=022=848=12739883=404107=GEZ4 P9825269=1270=9.5271=500273=95645000336=2346=11023=1279=122=848=12739883=405107=GEZ4 P9825269=1270=10271=150273=95645000336=2346=11023=2279=222=848=29271783=68107=GEZ4 P9862269=0270=11.5271=500273=95645000336=2346=11023=1279=122=848=29271783=69107=GEZ4 P9862269=0270=11271=650273=95645000336=2346=21023=1279=022=848=38726583=404107=GEZ4 P9837269=1270=10.5271=500273=95645000336=2346=11023=1279=122=848=38726583=405107=GEZ4 P9837269=1270=11271=150273=95645000336=2346=11023=2279=222=848=1924783=86107=GEZ4 P9887269=0270=15271=500273=95645000336=2346=11023=1279=122=848=1924783=87107=GEZ4 P9887269=0270=14.5271=650273=95645000336=2346=21023=1279=222=848=87658983=170107=GEZ4 P9912269=0270=20271=500273=95645000336=2346=11023=1279=022=848=87658983=171107=GEZ4 P9912269=0270=19.5271=500273=95645000336=2346=11023=1279=022=848=70448783=404107=GEZ4 P9650269=1270=2.5271=500273=95645000336=2346=11023=1279=222=848=70448783=405107=GEZ4 P9650269=1270=3271=500273=95645000336=2346=11023=2279=022=848=25677583=485107=GEZ4 P9900269=1270=19271=500273=95645000336=2346=11023=1279=122=848=25677583=486107=GEZ4 P9900269=1270=19.5271=150273=95645000336=2346=11023=210=039
1128=99=359635=X49=CME34=16786752=2013071514062654075=20130715268=36279=222=848=69099683=577107=GEZ4 C9500269=0270=431271=50273=140626000336=2346=11023=1279=022=848=69099683=578107=GEZ4 C9500269=0270=430.5271=50273=140626000336=2346=11023=1279=122=848=24325683=935107=GEZ4 C9525269=0270=406271=90273=140626000336=2346=21023=1279=122=848=28379683=934107=GEZ4 C9550269=0270=381271=90273=140626000336=2346=21023=1279=122=848=75283283=932107=GEZ4 C9600269=0270=331.5271=90273=140626000336=2346=21023=1279=122=848=60665983=1111107=GEZ4 C9887269=0270=59271=220273=140626000336=2346=21023=1279=022=848=60665983=1112107=GEZ4 C9887269=0270=58.5271=100273=140626000336=2346=11023=2279=222=848=58640483=627107=GEZ4 C9325269=0270=605.5271=50273=140626000336=2346=11023=1279=022=848=58640483=628107=GEZ4 C9325269=0270=605271=50273=140626000336=2346=11023=1279=222=848=64826883=623107=GEZ4 C9300269=0270=630.5271=50273=140626000336=2346=11023=1279=022=848=64826883=624107=GEZ4 C9300269=0270=630271=50273=140626000336=2346=11023=1279=222=848=20848883=623107=GEZ4 C9350269=0270=580.5271=50273=140626000336=2346=11023=1279=022=848=20848883=624107=GEZ4 C9350269=0270=580271=50273=140626000336=2346=11023=1279=222=848=56613483=619107=GEZ4 C9375269=0270=555.5271=50273=140626000336=2346=11023=1279=022=848=56613483=620107=GEZ4 C9375269=0270=555271=50273=140626000336=2346=11023=1279=222=848=22192183=619107=GEZ4 C9400269=0270=530.5271=50273=140626000336=2346=11023=1279=022=848=22192183=620107=GEZ4 C9400269=0270=530271=50273=140626000336=2346=11023=1279=222=848=11956783=620107=GEZ4 C9425269=0270=505.5271=50273=140626000336=2346=11023=1279=022=848=11956783=621107=GEZ4 C9425269=0270=505271=50273=140626000336=2346=11023=1279=222=848=59991683=619107=GEZ4 C9450269=0270=480.5271=50273=140626000336=2346=11023=1279=022=848=59991683=620107=GEZ4 C9450269=0270=480271=50273=140626000336=2346=11023=1279=122=848=85416683=1126107=GEZ4 C9900269=0270=48.5271=100273=140626000336=2346=11023=1279=022=848=85416683=1127107=GEZ4 C9900269=0270=48271=100273=140626000336=2346=11023=2279=122=848=77877483=824107=GEZ4 C9737269=0270=197271=100273=140626000336=2346=11023=1279=022=848=77877483=825107=GEZ4 C9737269=0270=196.5271=50273=140626000336=2346=11023=2279=222=848=65502783=619107=GEZ4 C9475269=0270=455.5271=50273=140626000336=2346=11023=1279=022=848=65502783=620107=GEZ4 C9475269=0270=455271=50273=140626000336=2346=11023=1279=122=848=27637283=935107=GEZ4 C9687269=0270=245.5271=90273=140626000336=2346=21023=1279=122=848=8473683=833107=GEZ4 C9712269=0270=221271=90273=140626000336=2346=21023=1279=122=848=84740383=843107=GEZ4 C9725269=0270=209271=90273=140626000336=2346=21023=1279=122=848=9143483=1088107=GEZ4 C9775269=0270=161271=167273=140626000336=2346=21023=1279=022=848=9143483=1089107=GEZ4 C9775269=0270=160.5271=50273=140626000336=2346=11023=2279=122=848=39402183=888107=GEZ4 C9787269=0270=149271=100273=140626000336=2346=11023=1279=022=848=39402183=889107=GEZ4 C9787269=0270=148.5271=50273=140626000336=2346=11023=2279=122=848=11386283=1921107=GEZ4 P9937269=1270=28.5271=100273=140626000336=2346=11023=2279=022=848=11386283=1922107=GEZ4 P9937269=1270=29271=100273=140626000336=2346=11023=310=120
1128=99=19835=X49=CME34=4219352=2013071511545859175=20130712268=2279=022=848=37100783=7107=GEM4 P9962269=B271=0273=115458000279=022=848=37100783=8107=GEM4 P9962269=C271=87022273=11545800010=236
1128=99=65035=X49=CME34=9033752=2013071512412938975=20130715268=6279=122=848=11386283=1174107=GEZ4 P9937269=0270=26271=647273=124129000336=2346=31023=1279=022=848=11386283=1175107=GEZ4 P9937269=0270=25.5271=500273=124129000336=2346=11023=2279=122=848=62233683=1744107=GEZ4 C9925269=1270=31.5271=553273=124129000336=2346=21023=1279=122=848=62233683=1745107=GEZ4 C9925269=1270=32271=600273=124129000336=2346=21023=2279=122=848=27027983=406107=GEZ4 P9800269=0270=6271=633273=124129000336=2346=31023=1279=122=848=27027983=407107=GEZ4 P9800269=0270=5.5271=520273=124129000336=2346=21023=210=004
1128=99=45035=X49=CME34=36823952=2013071519321910675=20130715268=4279=222=848=70062883=291107=GEM4 P9787269=0270=1271=33273=193219000336=2346=11023=1279=122=848=70062883=292107=GEM4 P9787269=1270=2.5271=252273=193219000336=2346=21023=2279=022=848=37100783=353107=GEM4 P9962269=0270=15271=125273=193219000336=2346=11023=1279=222=848=37100783=354107=GEM4 P9962269=0270=14.5271=125273=193219000336=2346=11023=210=228
1128=99=222435=X49=CME34=32361052=2013071518004097275=20130715268=22279=122=848=55953383=3127107=GEH5 C9912269=0270=34.5271=100273=180040000336=2346=11023=1279=122=848=55953383=3128107=GEH5 C9912269=0270=34271=650273=180040000336=2346=21023=2279=122=848=47523583=2003107=GEH5 C9837269=0270=93.5271=50273=180040000336=2346=11023=1279=022=848=47523583=2004107=GEH5 C9837269=0270=93271=75273=180040000336=2346=11023=2279=222=848=11969183=1492107=GEH5 P9962269=1270=53.5271=75273=180040000336=2346=11023=1279=022=848=11969183=1493107=GEH5 P9962269=1270=54271=75273=180040000336=2346=11023=1279=122=848=44930183=3285107=GEH5 P9900269=1270=28.5271=790273=180040000336=2346=21023=1279=022=848=44930183=3286107=GEH5 P9900269=1270=29271=150273=180040000336=2346=11023=2279=222=848=27043383=1344107=GEH5 P9950269=1270=46.5271=75273=180040000336=2346=11023=1279=022=848=27043383=1345107=GEH5 P9950269=1270=47271=75273=180040000336=2346=11023=1279=122=848=14563083=3083107=GEH5 C9925269=0270=26271=933273=180040000336=2346=21023=1279=022=848=14563083=3084107=GEH5 C9925269=0270=25.5271=150273=180040000336=2346=11023=2279=122=848=52467883=2871107=GEH5 P9875269=1270=22.5271=640273=180040000336=2346=21023=1279=022=848=52467883=2872107=GEH5 P9875269=1270=23271=150273=180040000336=2346=11023=2279=122=848=54386083=1986107=GEH5 C9937269=0270=18.5271=933273=180040000336=2346=21023=1279=022=848=54386083=1987107=GEH5 C9937269=0270=18271=150273=180040000336=2346=11023=2279=222=848=9332383=1156107=GEH5 P9812269=1270=13.5271=150273=180040000336=2346=11023=2279=122=848=9332383=1157107=GEH5 P9812269=1270=14271=175273=180040000336=2346=21023=2279=222=848=32555383=581107=GEH5 P9737269=1270=8271=150273=180040000336=2346=11023=2279=122=848=32555383=582107=GEH5 P9737269=1270=8.5271=167273=180040000336=2346=21023=2279=222=848=38742583=710107=GEH5 P9675269=1270=5.5271=150273=180040000336=2346=11023=2279=122=848=38742583=711107=GEH5 P9675269=1270=6271=170273=180040000336=2346=21023=210=189
1128=99=278535=X49=CME34=3426752=2013071510080020075=20130715268=28279=022=848=13981783=60107=GEZ4 C9875269=0270=68.5271=150273=100800000336=2346=11023=1279=222=848=13981783=61107=GEZ4 C9875269=0270=68271=150273=100800000336=2346=11023=2279=022=848=11386283=217107=GEZ4 P9937269=1270=29.5271=150273=100800000336=2346=11023=2279=222=848=11386283=218107=GEZ4 P9937269=1270=30271=150273=100800000336=2346=11023=3279=022=848=84066783=169107=GEZ4 P9925269=1270=25.5271=150273=100800000336=2346=11023=2279=222=848=84066783=170107=GEZ4 P9925269=1270=26271=150273=100800000336=2346=11023=3279=022=848=69664283=56107=GEZ4 C9912269=0270=38271=150273=100800000336=2346=11023=1279=222=848=69664283=57107=GEZ4 C9912269=0270=37.5271=150273=100800000336=2346=11023=2279=022=848=62233683=467107=GEZ4 C9925269=0270=29271=150273=100800000336=2346=11023=1279=122=848=62233683=468107=GEZ4 C9925269=0270=28.5271=500273=100800000336=2346=11023=2279=022=848=59315083=110107=GEZ4 C9837269=0270=101271=75273=100800000336=2346=11023=1279=222=848=59315083=111107=GEZ4 C9837269=0270=100.5271=75273=100800000336=2346=11023=2279=022=848=10714983=56107=GEZ4 C9862269=0270=79271=75273=100800000336=2346=11023=1279=222=848=10714983=57107=GEZ4 C9862269=0270=78.5271=75273=100800000336=2346=11023=2279=022=848=66177783=90107=GEZ4 C9850269=0270=90271=75273=100800000336=2346=11023=1279=222=848=66177783=91107=GEZ4 C9850269=0270=89.5271=75273=100800000336=2346=11023=2279=022=848=83496983=133107=GEZ4 P9950269=1270=34.5271=75273=100800000336=2346=11023=1279=222=848=83496983=134107=GEZ4 P9950269=1270=35271=75273=100800000336=2346=11023=2279=022=848=33890283=626107=GEZ4 C9937269=0270=20.5271=150273=100800000336=2346=11023=1279=122=848=33890283=627107=GEZ4 C9937269=0270=20271=500273=100800000336=2346=11023=2279=122=848=1924783=94107=GEZ4 P9887269=1270=17271=650273=100800000336=2346=21023=1279=222=848=1924783=95107=GEZ4 P9887269=1270=17.5271=150273=100800000336=2346=11023=2279=122=848=38159883=132107=GEZ4 P9875269=1270=15271=650273=100800000336=2346=21023=1279=222=848=38159883=133107=GEZ4 P9875269=1270=15.5271=150273=100800000336=2346=11023=2279=122=848=19489783=132107=GEZ4 P9850269=1270=12271=650273=100800000336=2346=21023=1279=222=848=19489783=133107=GEZ4 P9850269=1270=12.5271=150273=100800000336=2346=11023=2279=122=848=27027983=103107=GEZ4 P9800269=1270=8271=650273=100800000336=2346=21023=1279=222=848=27027983=104107=GEZ4 P9800269=1270=8.5271=150273=100800000336=2346=11023=210=026
1128=99=25735=X49=CME34=27143152=2013071516393207775=20130715268=2279=022=848=37100783=267107=GEM4 P9962269=0270=15.5271=125273=163932000336=2346=11023=1279=222=848=37100783=268107=GEM4 P9962269=0270=15271=125273=163932000336=2346=11023=210=059
1128=99=211135=X49=CME34=38355452=2013071520185526875=20130715268=21279=022=848=33506583=907107=GEM4 C9712269=0270=238.5271=50273=201855000336=2346=11023=1279=022=848=33506583=908107=GEM4 C9712269=1270=241271=50273=201855000336=2346=11023=1279=022=848=79519983=919107=GEM4 C9700269=0270=251271=50273=201855000336=2346=11023=1279=022=848=79519983=920107=GEM4 C9700269=1270=253.5271=50273=201855000336=2346=11023=1279=022=848=12624783=1680107=GEM5 C9912269=0270=29.5271=75273=201855000336=2346=11023=2279=122=848=12624783=1681107=GEM5 C9912269=1270=33.5271=575273=201855000336=2346=21023=1279=022=848=19213083=977107=GEU4 C9687269=0270=255.5271=75273=201855000336=2346=11023=1279=022=848=19213083=978107=GEU4 C9687269=1270=258.5271=75273=201855000336=2346=11023=1279=022=848=84355283=907107=GEM4 C9750269=0270=201271=50273=201855000336=2346=11023=1279=022=848=84355283=908107=GEM4 C9750269=1270=204271=50273=201855000336=2346=11023=1279=022=848=6971883=578107=GEH4 C9375269=0270=582271=75273=201855000336=2346=11023=1279=022=848=6971883=579107=GEH4 C9375269=1270=584.5271=75273=201855000336=2346=11023=1279=122=848=55661283=120107=GEM4 P9600269=1270=1271=550273=201855000336=2346=21023=1279=122=848=15620183=778107=GEM4 P9887269=0270=4271=600273=201855000336=2346=21023=1279=022=848=15620183=779107=GEM4 P9887269=1270=6271=100273=201855000336=2346=11023=2279=122=848=61728283=49107=GEU3 P9350269=1270=0.75271=550273=201855000336=2346=21023=1279=022=848=48663783=1145107=GEH4 C9737269=0270=219.5271=75273=201855000336=2346=11023=1279=022=848=48663783=1146107=GEH4 C9737269=1270=222271=75273=201855000336=2346=11023=1279=122=848=49367183=429107=GEH4 P9900269=0270=2271=650273=201855000336=2346=21023=2279=022=848=49367183=430107=GEH4 P9900269=1270=4271=150273=201855000336=2346=11023=2279=122=848=2150383=824107=GEU3 P9550269=1270=0.5271=51273=201855000336=2346=21023=110=099
1128=99=114235=X49=CME34=35744452=2013071519071530875=20130715268=11279=022=848=11386283=3853107=GEZ4 P9937269=1270=27.5271=500273=190715000336=2346=11023=1279=122=848=11386283=3854107=GEZ4 P9937269=1270=28271=600273=190715000336=2346=31023=2279=022=848=88900683=679107=GEZ4 C9962269=0270=7271=500273=190715000336=2346=11023=1279=122=848=88900683=680107=GEZ4 C9962269=0270=6.5271=333273=190715000336=2346=11023=2279=122=848=33890283=3777107=GEZ4 C9937269=0270=21271=800273=190715000336=2346=41023=1279=222=848=33890283=3778107=GEZ4 C9937269=0270=20.5271=500273=190715000336=2346=11023=2279=022=848=33890283=3779107=GEZ4 C9937269=0270=2271=12273=190715000336=2346=31023=3279=122=848=62233683=3677107=GEZ4 C9925269=0270=29.5271=833273=190715000336=2346=41023=1279=222=848=62233683=3678107=GEZ4 C9925269=0270=29271=500273=190715000336=2346=11023=2279=122=848=1924783=1730107=GEZ4 P9887269=1270=16271=667273=190715000336=2346=31023=1279=122=848=1924783=1731107=GEZ4 P9887269=1270=16.5271=100273=190715000336=2346=11023=210=165
1128=99=45135=X49=CME34=35548052=2013071519032482875=20130715268=4279=122=848=81762683=369107=GEM4 P9812269=1270=2.5271=505273=190324000336=2346=21023=1279=122=848=81762683=370107=GEM4 P9812269=1270=3271=200273=190324000336=2346=21023=2279=022=848=37100783=341107=GEM4 P9962269=1270=21271=125273=190324000336=2346=11023=1279=222=848=37100783=342107=GEM4 P9962269=1270=21.5271=125273=190324000336=2346=11023=210=238
1128=99=105235=X49=CME34=24791252=2013071515570879175=20130715268=10279=022=848=80705883=2088107=GEH5 C9787269=1270=141271=50273=155708000336=2346=11023=1279=122=848=80705883=2089107=GEH5 C9787269=1270=141.5271=75273=155708000336=2346=11023=2279=022=848=27610983=2194107=GEH5 C9762269=1270=164271=50273=155708000336=2346=11023=1279=122=848=27610983=2195107=GEH5 C9762269=1270=164.5271=75273=155708000336=2346=11023=2279=022=848=43579483=2209107=GEH5 C9775269=1270=152.5271=50273=155708000336=2346=11023=1279=122=848=43579483=2210107=GEH5 C9775269=1270=153271=75273=155708000336=2346=11023=2279=022=848=61465183=2216107=GEH5 C9737269=1270=187.5271=50273=155708000336=2346=11023=1279=122=848=61465183=2217107=GEH5 C9737269=1270=188271=75273=155708000336=2346=11023=2279=022=848=24341283=2337107=GEH5 C9725269=1270=199.5271=50273=155708000336=2346=11023=1279=122=848=24341283=2338107=GEH5 C9725269=1270=200271=75273=155708000336=2346=11023=210=040
1128=99=25735=X49=CME34=21171352=2013071515021642275=20130715268=2279=022=848=37100783=231107=GEM4 P9962269=1270=21.5271=125273=150216000336=2346=11023=1279=222=848=37100783=232107=GEM4 P9962269=1270=22271=125273=150216000336=2346=11023=210=002
1128=99=326635=X49=CME34=12776852=2013071513210467275=20130715268=33279=122=848=36315883=135107=GEH4 P9800269=1270=1.5271=75273=132104000336=2346=11023=2279=122=848=6975383=819107=GEM4 P9950269=0270=13.5271=700273=132104000336=2346=31023=1279=222=848=6975383=820107=GEM4 P9950269=1270=15271=467273=132104000336=2346=11023=1279=222=848=64443183=251107=GEM4 C9962269=0270=6271=333273=132104000336=2346=11023=1279=122=848=64443183=252107=GEM4 C9962269=1270=7.5271=500273=132104000336=2346=11023=1279=122=848=61557983=395107=GEZ4 P9525269=1270=2271=50273=132104000336=2346=11023=2279=122=848=80807783=317107=GEZ4 P9712269=0270=2.5271=200273=132104000336=2346=21023=1279=122=848=80807783=318107=GEZ4 P9712269=1270=4.5271=200273=132104000336=2346=21023=2279=222=848=63199683=494107=GEU4 C9900269=0270=52271=40273=132104000336=2346=11023=2279=122=848=63199683=495107=GEU4 C9900269=1270=54271=100273=132104000336=2346=11023=1279=222=848=63875283=588107=GEU4 C9887269=0270=63271=40273=132104000336=2346=11023=2279=122=848=63875283=589107=GEU4 C9887269=1270=65271=100273=132104000336=2346=11023=1279=122=848=85707383=341107=GEM4 P9850269=0270=2.5271=200273=132104000336=2346=21023=1279=222=848=85707383=342107=GEM4 P9850269=1270=4271=144273=132104000336=2346=11023=2279=122=848=83405383=50107=GEH5 P9450269=1270=2.5271=75273=132104000336=2346=11023=2279=122=848=43286583=202107=GEM4 P9862269=0270=3271=200273=132104000336=2346=21023=1279=122=848=43286583=203107=GEM4 P9862269=1270=4.5271=500273=132104000336=2346=11023=1279=122=848=89192383=362107=GEH4 P9912269=0270=3271=250273=132104000336=2346=21023=1279=122=848=89192383=363107=GEH4 P9912269=1270=4271=500273=132104000336=2346=11023=1279=222=848=87273483=300107=GEM4 P9725269=0270=0.5271=33273=132104000336=2346=11023=1279=122=848=87273483=301107=GEM4 P9725269=1270=1.5271=500273=132104000336=2346=11023=1279=222=848=46848383=251107=GEH5 C9975269=0270=2271=125273=132104000336=2346=11023=2279=222=848=46848383=252107=GEH5 C9975269=1270=4271=125273=132104000336=2346=11023=1279=122=848=70354483=529107=GEH5 P9750269=0270=6.5271=150273=132104000336=2346=11023=1279=222=848=70354483=530107=GEH5 P9750269=1270=9.5271=32273=132104000336=2346=11023=3279=122=848=47231383=807107=GEM4 C9950269=0270=14271=700273=132104000336=2346=31023=1279=122=848=47231383=808107=GEM4 C9950269=1270=16271=100273=132104000336=2346=11023=2279=122=848=25692083=1678107=GEH5 P9850269=0270=16271=150273=132104000336=2346=11023=1279=122=848=25692083=1679107=GEH5 P9850269=1270=18.5271=150273=132104000336=2346=11023=2279=122=848=48691383=162107=GEH4 P9812269=0270=0.5271=120273=132104000336=2346=11023=1279=122=848=48691383=163107=GEH4 P9812269=1270=1.5271=620273=132104000336=2346=21023=1279=122=848=31721683=454107=GEU4 P9900269=0270=10271=250273=132104000336=2346=21023=1279=122=848=31721683=455107=GEU4 P9900269=1270=11.5271=500273=132104000336=2346=11023=110=013
1128=99=25735=X49=CME34=37255352=2013071519520359675=20130715268=2279=222=848=37100783=363107=GEM4 P9962269=0270=15271=125273=195203000336=2346=11023=1279=022=848=37100783=364107=GEM4 P9962269=0270=14.5271=125273=195203000336=2346=11023=110=052
1128=99=25735=X49=CME34=34767552=2013071518482359075=20130715268=2279=222=848=1924783=1587107=GEZ4 P9887269=1270=16271=210273=184823000336=2346=11023=1279=022=848=1924783=1588107=GEZ4 P9887269=1270=21.5271=125273=184823000336=2346=11023=210=134
1128=99=238535=X49=CME34=8112752=2013071512354476875=20130715268=24279=222=848=74497883=336107=GEM5 C9450269=0270=447.5271=7273=123544000336=2346=11023=1279=022=848=74497883=337107=GEM5 C9450269=0270=447271=7273=123544000336=2346=11023=1279=222=848=5086283=336107=GEM5 C9475269=0270=422.5271=7273=123544000336=2346=11023=1279=022=848=5086283=337107=GEM5 C9475269=0270=422271=7273=123544000336=2346=11023=1279=222=848=49073683=336107=GEM5 C9500269=0270=398271=7273=123544000336=2346=11023=1279=022=848=49073683=337107=GEM5 C9500269=0270=397.5271=7273=123544000336=2346=11023=1279=222=848=76523983=316107=GEM5 C9525269=0270=373271=7273=123544000336=2346=11023=1279=022=848=76523983=317107=GEM5 C9525269=0270=372.5271=7273=123544000336=2346=11023=1279=222=848=78551783=312107=GEM5 C9550269=0270=348.5271=7273=123544000336=2346=11023=1279=022=848=78551783=313107=GEM5 C9550269=0270=348271=7273=123544000336=2346=11023=1279=222=848=36022783=254107=GEM5 C9600269=0270=300271=7273=123544000336=2346=11023=1279=022=848=36022783=255107=GEM5 C9600269=0270=299.5271=7273=123544000336=2346=11023=1279=222=848=31862183=276107=GEM5 C9650269=0270=251.5271=7273=123544000336=2346=11023=1279=022=848=31862183=277107=GEM5 C9650269=0270=251271=7273=123544000336=2346=11023=1279=222=848=87547883=320107=GEM5 C9675269=0270=228271=7273=123544000336=2346=11023=1279=022=848=87547883=321107=GEM5 C9675269=0270=227.5271=7273=123544000336=2346=11023=1279=222=848=1469183=290107=GEM5 P9787269=1270=17.5271=75273=123544000336=2346=11023=1279=022=848=1469183=291107=GEM5 P9787269=1270=18271=75273=123544000336=2346=11023=1279=222=848=25674883=230107=GEM5 C9725269=0270=181271=7273=123544000336=2346=11023=1279=022=848=25674883=231107=GEM5 C9725269=0270=180.5271=7273=123544000336=2346=11023=1279=222=848=67915383=264107=GEM5 C9737269=0270=169.5271=7273=123544000336=2346=11023=1279=022=848=67915383=265107=GEM5 C9737269=0270=169271=7273=123544000336=2346=11023=1279=222=848=30078683=206107=GEM5 P9775269=1270=16271=75273=123544000336=2346=11023=1279=022=848=30078683=207107=GEM5 P9775269=1270=16.5271=75273=123544000336=2346=11023=110=171
1128=99=25735=X49=CME34=20457752=2013071514515106575=20130715268=2279=022=848=37100783=223107=GEM4 P9962269=1270=21.5271=125273=145151000336=2346=11023=1279=222=848=37100783=224107=GEM4 P9962269=1270=22271=125273=145151000336=2346=11023=210=023
1128=99=15835=X49=CME34=34988152=2013071518574661475=20130715268=1279=122=848=1924783=1653107=GEZ4 P9887269=1270=16271=167273=185746000336=2346=21023=110=041
1128=99=25535=X49=CME34=11986552=2013071513113412375=20130715268=2279=222=848=37100783=79107=GEM4 P9962269=1270=21271=125273=131134000336=2346=11023=1279=022=848=37100783=80107=GEM4 P9962269=1270=21.5271=125273=131134000336=2346=11023=110=176
1128=99=456535=X49=CME34=8496352=2013071512380029275=20130715268=46279=022=848=36716183=388107=GEH5 C9275269=1270=644.5271=75273=123800000336=2346=11023=1279=222=848=36716183=389107=GEH5 C9275269=1270=645271=75273=123800000336=2346=11023=2279=022=848=81378183=388107=GEH5 C9300269=1270=619.5271=75273=123800000336=2346=11023=1279=222=848=81378183=389107=GEH5 C9300269=1270=620271=75273=123800000336=2346=11023=2279=022=848=69003883=388107=GEH5 C9325269=1270=594.5271=75273=123800000336=2346=11023=1279=222=848=69003883=389107=GEH5 C9325269=1270=595271=75273=123800000336=2346=11023=2279=022=848=22104483=388107=GEH5 C9350269=1270=569.5271=75273=123800000336=2346=11023=1279=222=848=22104483=389107=GEH5 C9350269=1270=570271=75273=123800000336=2346=11023=2279=022=848=42903383=388107=GEH5 C9375269=1270=544.5271=75273=123800000336=2346=11023=1279=222=848=42903383=389107=GEH5 C9375269=1270=545271=75273=123800000336=2346=11023=2279=022=848=28285883=388107=GEH5 C9400269=1270=519.5271=75273=123800000336=2346=11023=1279=222=848=28285883=389107=GEH5 C9400269=1270=520271=75273=123800000336=2346=11023=2279=022=848=88240983=389107=GEH5 C9425269=1270=494.5271=75273=123800000336=2346=11023=1279=222=848=88240983=390107=GEH5 C9425269=1270=495271=75273=123800000336=2346=11023=2279=022=848=66100483=341107=GEH5 C9450269=1270=469.5271=75273=123800000336=2346=11023=1279=222=848=66100483=342107=GEH5 C9450269=1270=470271=75273=123800000336=2346=11023=2279=022=848=82053483=385107=GEH5 C9475269=1270=445271=75273=123800000336=2346=11023=1279=222=848=82053483=386107=GEH5 C9475269=1270=445.5271=75273=123800000336=2346=11023=2279=022=848=40660783=356107=GEH5 C9862269=1270=75.5271=150273=123800000336=2346=11023=1279=122=848=40660783=357107=GEH5 C9862269=1270=76271=100273=123800000336=2346=11023=2279=022=848=8373583=385107=GEH5 C9500269=1270=420271=75273=123800000336=2346=11023=1279=222=848=8373583=386107=GEH5 C9500269=1270=420.5271=75273=123800000336=2346=11023=2279=022=848=72272783=438107=GEH5 C9850269=1270=86271=150273=123800000336=2346=11023=1279=122=848=72272783=439107=GEH5 C9850269=1270=86.5271=100273=123800000336=2346=11023=2279=022=848=4430783=349107=GEH5 C9525269=1270=395271=75273=123800000336=2346=11023=1279=222=848=4430783=350107=GEH5 C9525269=1270=395.5271=75273=123800000336=2346=11023=2279=022=848=34473283=385107=GEH5 C9550269=1270=370.5271=75273=123800000336=2346=11023=1279=222=848=34473283=386107=GEH5 C9550269=1270=371271=75273=123800000336=2346=11023=2279=022=848=10624283=381107=GEH5 C9575269=1270=346271=75273=123800000336=2346=11023=1279=222=848=10624283=382107=GEH5 C9575269=1270=346.5271=75273=123800000336=2346=11023=2279=022=848=47804683=368107=GEH5 C9600269=1270=321271=75273=123800000336=2346=11023=1279=222=848=47804683=369107=GEH5 C9600269=1270=321.5271=75273=123800000336=2346=11023=2279=022=848=33797983=368107=GEH5 C9625269=1270=296.5271=75273=123800000336=2346=11023=1279=222=848=33797983=369107=GEH5 C9625269=1270=297271=75273=123800000336=2346=11023=2279=022=848=57980183=1634107=GEH5 P9925269=0270=33271=150273=123800000336=2346=11023=1279=122=848=57980183=1635107=GEH5 P9925269=0270=32.5271=100273=123800000336=2346=11023=2279=022=848=85323383=304107=GEH5 C9675269=1270=248271=75273=123800000336=2346=11023=1279=222=848=85323383=305107=GEH5 C9675269=1270=248.5271=75273=123800000336=2346=11023=2279=022=848=60573483=332107=GEH5 C9687269=1270=236271=75273=123800000336=2346=11023=1279=222=848=60573483=333107=GEH5 C9687269=1270=236.5271=75273=123800000336=2346=11023=2279=022=848=29853883=332107=GEH5 C9700269=1270=224271=75273=123800000336=2346=11023=1279=222=848=29853883=333107=GEH5 C9700269=1270=224.5271=75273=123800000336=2346=11023=2279=022=848=2319483=310107=GEH5 C9712269=1270=212271=75273=123800000336=2346=11023=1279=222=848=2319483=311107=GEH5 C9712269=1270=212.5271=75273=123800000336=2346=11023=2279=022=848=24341283=513107=GEH5 C9725269=1270=200271=75273=123800000336=2346=11023=1279=122=848=24341283=514107=GEH5 C9725269=1270=200.5271=50273=123800000336=2346=11023=210=022
1128=99=104635=X49=CME34=34987052=2013071518574657575=20130715268=10279=122=848=11386283=3733107=GEZ4 P9937269=1270=27.5271=230273=185746000336=2346=11023=1279=122=848=11386283=3734107=GEZ4 P9937269=1270=28271=600273=185746000336=2346=21023=2279=122=848=88900683=629107=GEZ4 C9962269=0270=7271=333273=185746000336=2346=11023=1279=022=848=88900683=630107=GEZ4 C9962269=0270=6.5271=500273=185746000336=2346=11023=2279=122=848=33890283=3732107=GEZ4 C9937269=0270=21271=647273=185746000336=2346=31023=1279=022=848=33890283=3733107=GEZ4 C9937269=0270=20.5271=500273=185746000336=2346=11023=2279=122=848=62233683=3575107=GEZ4 C9925269=0270=29.5271=667273=185746000336=2346=31023=1279=022=848=62233683=3576107=GEZ4 C9925269=0270=29271=500273=185746000336=2346=11023=2279=122=848=1924783=1651107=GEZ4 P9887269=1270=16271=330273=185746000336=2346=21023=1279=122=848=1924783=1652107=GEZ4 P9887269=1270=16.5271=600273=185746000336=2346=21023=210=033
1128=99=25735=X49=CME34=27199752=2013071516400277175=20130715268=2279=022=848=37100783=271107=GEM4 P9962269=0270=15.5271=125273=164002000336=2346=11023=1279=222=848=37100783=272107=GEM4 P9962269=0270=15271=125273=164002000336=2346=11023=210=034
1128=99=44935=X49=CME34=24785052=2013071515565337575=20130715268=4279=222=848=32555383=541107=GEH5 P9737269=1270=8271=150273=155653000336=2346=11023=2279=122=848=32555383=542107=GEH5 P9737269=1270=8.5271=155273=155653000336=2346=21023=2279=222=848=38742583=645107=GEH5 P9675269=1270=5.5271=150273=155653000336=2346=11023=2279=122=848=38742583=646107=GEH5 P9675269=1270=6271=162273=155653000336=2346=21023=210=214
1128=99=64535=X49=CME34=7646952=2013071512341311475=20130715268=6279=122=848=17186583=381107=GEM4 P9925269=0270=8271=267273=123413000336=2346=31023=1279=122=848=17186583=382107=GEM4 P9925269=1270=10271=267273=123413000336=2346=31023=1279=122=848=1924783=586107=GEZ4 P9887269=0270=14.5271=253273=123413000336=2346=31023=1279=122=848=1924783=587107=GEZ4 P9887269=1270=16.5271=247273=123413000336=2346=31023=1279=022=848=25677583=1501107=GEZ4 P9900269=0270=17271=100273=123413000336=2346=11023=1279=122=848=25677583=1502107=GEZ4 P9900269=1270=19271=267273=123413000336=2346=31023=110=030
1128=99=25435=X49=CME34=33140552=2013071518151473075=20130715268=2279=122=848=2150383=678107=GEU3 P9550269=1270=0.5271=1273=181514000336=2346=11023=1279=122=848=2150383=679107=GEU3 P9550269=1270=0.75271=600273=181514000336=2346=31023=210=141
1128=99=44835=X49=CME34=8839652=2013071512401461375=20130715268=4279=022=848=37100783=55107=GEM4 P9962269=0270=15271=125273=124014000336=2346=11023=1279=222=848=37100783=56107=GEM4 P9962269=0270=14.5271=125273=124014000336=2346=11023=2279=222=848=37100783=57107=GEM4 P9962269=1270=21271=125273=124014000336=2346=11023=1279=022=848=37100783=58107=GEM4 P9962269=1270=21.5271=125273=124014000336=2346=11023=110=060
1128=99=458935=X49=CME34=14342952=2013071513375858275=20130715268=46279=222=848=24341283=1063107=GEH5 C9725269=0270=196.5271=75273=133758000336=2346=11023=1279=122=848=24341283=1064107=GEH5 C9725269=0270=196271=125273=133758000336=2346=21023=1279=022=848=24341283=1065107=GEH5 C9725269=1270=199.5271=75273=133758000336=2346=11023=1279=222=848=24341283=1066107=GEH5 C9725269=1270=200271=75273=133758000336=2346=11023=2279=222=848=61465183=1127107=GEH5 C9737269=0270=184.5271=75273=133758000336=2346=11023=1279=122=848=61465183=1128107=GEH5 C9737269=0270=184271=125273=133758000336=2346=21023=1279=022=848=61465183=1129107=GEH5 C9737269=1270=187.5271=75273=133758000336=2346=11023=1279=222=848=61465183=1130107=GEH5 C9737269=1270=188271=75273=133758000336=2346=11023=2279=022=848=30528983=822107=GEH5 C9875269=1270=65271=150273=133758000336=2346=11023=1279=222=848=30528983=823107=GEH5 C9875269=1270=65.5271=150273=133758000336=2346=11023=2279=122=848=50442283=2103107=GEH5 P9912269=1270=32271=800273=133758000336=2346=21023=1279=022=848=50442283=2104107=GEH5 P9912269=1270=32.5271=150273=133758000336=2346=11023=2279=222=848=9049283=630107=GEH5 C9887269=0270=52.5271=150273=133758000336=2346=11023=1279=122=848=9049283=631107=GEH5 C9887269=0270=52271=250273=133758000336=2346=21023=1279=222=848=53035583=988107=GEH5 C9750269=0270=173271=75273=133758000336=2346=11023=1279=122=848=53035583=989107=GEH5 C9750269=0270=172.5271=125273=133758000336=2346=21023=1279=022=848=53035583=990107=GEH5 C9750269=1270=176271=75273=133758000336=2346=11023=1279=222=848=53035583=991107=GEH5 C9750269=1270=176.5271=75273=133758000336=2346=11023=2279=222=848=27610983=1078107=GEH5 C9762269=0270=161271=75273=133758000336=2346=11023=1279=122=848=27610983=1079107=GEH5 C9762269=0270=160.5271=125273=133758000336=2346=21023=1279=022=848=27610983=1080107=GEH5 C9762269=1270=164271=75273=133758000336=2346=11023=1279=222=848=27610983=1081107=GEH5 C9762269=1270=164.5271=75273=133758000336=2346=11023=2279=222=848=43579483=1001107=GEH5 C9775269=0270=149.5271=75273=133758000336=2346=11023=1279=122=848=43579483=1002107=GEH5 C9775269=0270=149271=125273=133758000336=2346=21023=1279=022=848=43579483=1003107=GEH5 C9775269=1270=152.5271=75273=133758000336=2346=11023=1279=222=848=43579483=1004107=GEH5 C9775269=1270=153271=75273=133758000336=2346=11023=2279=222=848=80705883=950107=GEH5 C9787269=0270=138271=75273=133758000336=2346=11023=1279=122=848=80705883=951107=GEH5 C9787269=0270=137.5271=125273=133758000336=2346=21023=1279=022=848=80705883=952107=GEH5 C9787269=1270=141271=75273=133758000336=2346=11023=1279=222=848=80705883=953107=GEH5 C9787269=1270=141.5271=75273=133758000336=2346=11023=2279=222=848=59897983=921107=GEH5 C9812269=0270=115.5271=75273=133758000336=2346=11023=1279=122=848=59897983=922107=GEH5 C9812269=0270=115271=125273=133758000336=2346=21023=1279=022=848=11969183=638107=GEH5 P9962269=0270=50.5271=75273=133758000336=2346=11023=1279=222=848=11969183=639107=GEH5 P9962269=0270=50271=75273=133758000336=2346=11023=2279=222=848=11969183=640107=GEH5 P9962269=1270=53.5271=75273=133758000336=2346=11023=1279=022=848=11969183=641107=GEH5 P9962269=1270=54271=75273=133758000336=2346=11023=1279=222=848=2866183=893107=GEH5 C9800269=0270=126.5271=75273=133758000336=2346=11023=1279=122=848=2866183=894107=GEH5 C9800269=0270=126271=125273=133758000336=2346=21023=1279=022=848=2866183=895107=GEH5 C9800269=1270=129.5271=75273=133758000336=2346=11023=1279=222=848=2866183=896107=GEH5 C9800269=1270=130271=75273=133758000336=2346=11023=2279=122=848=44930183=1808107=GEH5 P9900269=1270=28.5271=260273=133758000336=2346=11023=2279=022=848=44930183=1809107=GEH5 P9900269=1270=29271=150273=133758000336=2346=11023=3279=222=848=11291383=778107=GEH5 C9825269=0270=104.5271=75273=133758000336=2346=11023=1279=122=848=11291383=779107=GEH5 C9825269=0270=104271=125273=133758000336=2346=21023=1279=022=848=11291383=780107=GEH5 C9825269=1270=107271=75273=133758000336=2346=11023=1279=222=848=11291383=781107=GEH5 C9825269=1270=107.5271=75273=133758000336=2346=11023=210=080
1128=99=45035=X49=CME34=32890752=2013071518125441975=20130715268=4279=222=848=54667183=2690107=GEH5 P9500269=0270=0.5271=50273=181254000336=2346=11023=1279=122=848=54667183=2691107=GEH5 P9500269=1270=3271=136273=181254000336=2346=21023=2279=222=848=38742583=761107=GEH5 P9675269=0270=3.5271=100273=181254000336=2346=11023=1279=122=848=38742583=762107=GEH5 P9675269=1270=6271=162273=181254000336=2346=21023=210=210
1128=99=25535=X49=CME34=33144852=2013071518151505275=20130715268=2279=122=848=2150383=680107=GEU3 P9550269=1270=0.5271=51273=181515000336=2346=21023=1279=122=848=2150383=681107=GEU3 P9550269=1270=0.75271=550273=181515000336=2346=21023=210=192
1128=99=45235=X49=CME34=16740252=2013071514053136175=20130715268=4279=222=848=87273483=581107=GEM4 P9725269=0270=0.5271=33273=140531000336=2346=11023=1279=122=848=87273483=582107=GEM4 P9725269=1270=1.5271=830273=140531000336=2346=21023=1279=222=848=37100783=189107=GEM4 P9962269=0270=15.5271=125273=140531000336=2346=11023=1279=022=848=37100783=190107=GEM4 P9962269=0270=15271=125273=140531000336=2346=11023=110=018
1128=99=25535=X49=CME34=12527852=2013071513192431975=20130715268=2279=122=848=2150383=268107=GEU3 P9550269=1270=0.5271=51273=131924000336=2346=21023=1279=122=848=2150383=269107=GEU3 P9550269=1270=0.75271=550273=131924000336=2346=21023=210=201
1128=99=123735=X49=CME34=11930752=2013071513112828775=20130715268=12279=022=848=11386283=1535107=GEZ4 P9937269=1270=27.5271=500273=131128000336=2346=11023=1279=122=848=11386283=1536107=GEZ4 P9937269=1270=28271=500273=131128000336=2346=21023=2279=022=848=88900683=238107=GEZ4 C9962269=0270=7271=500273=131128000336=2346=11023=1279=122=848=88900683=239107=GEZ4 C9962269=0270=6.5271=333273=131128000336=2346=11023=2279=122=848=33890283=2364107=GEZ4 C9937269=0270=21271=833273=131128000336=2346=41023=1279=222=848=33890283=2365107=GEZ4 C9937269=0270=20.5271=500273=131128000336=2346=11023=2279=022=848=33890283=2366107=GEZ4 C9937269=0270=2271=12273=131128000336=2346=31023=3279=122=848=62233683=1978107=GEZ4 C9925269=0270=29.5271=733273=131128000336=2346=31023=2279=222=848=62233683=1979107=GEZ4 C9925269=0270=29271=500273=131128000336=2346=11023=3279=022=848=62233683=1980107=GEZ4 C9925269=0270=0.5271=4273=131128000336=2346=11023=3279=122=848=1924783=873107=GEZ4 P9887269=1270=16271=600273=131128000336=2346=21023=1279=122=848=1924783=874107=GEZ4 P9887269=1270=16.5271=567273=131128000336=2346=21023=210=194
1128=99=150835=X49=CME34=3190752=2013071508585077275=20130715268=15279=222=848=33890283=330107=GEZ4 C9937269=0270=20.5271=500273=85850000336=2346=11023=1279=122=848=33890283=331107=GEZ4 C9937269=0270=20271=650273=85850000336=2346=21023=1279=022=848=33890283=332107=GEZ4 C9937269=0270=2271=12273=85850000336=2346=31023=3279=222=848=62233683=269107=GEZ4 C9925269=0270=29271=500273=85850000336=2346=11023=1279=122=848=62233683=270107=GEZ4 C9925269=0270=28.5271=650273=85850000336=2346=21023=1279=222=848=43671583=218107=GEZ4 P9787269=1270=7271=500273=85850000336=2346=11023=1279=122=848=43671583=219107=GEZ4 P9787269=1270=7.5271=650273=85850000336=2346=21023=1279=222=848=12739883=222107=GEZ4 P9825269=1270=9.5271=500273=85850000336=2346=11023=1279=122=848=12739883=223107=GEZ4 P9825269=1270=10271=650273=85850000336=2346=21023=1279=222=848=38726583=222107=GEZ4 P9837269=1270=10.5271=500273=85850000336=2346=11023=1279=122=848=38726583=223107=GEZ4 P9837269=1270=11271=650273=85850000336=2346=21023=1279=222=848=70448783=222107=GEZ4 P9650269=1270=2.5271=500273=85850000336=2346=11023=1279=022=848=70448783=223107=GEZ4 P9650269=1270=3271=500273=85850000336=2346=11023=1279=222=848=25677583=303107=GEZ4 P9900269=1270=19271=500273=85850000336=2346=11023=1279=122=848=25677583=304107=GEZ4 P9900269=1270=19.5271=650273=85850000336=2346=21023=110=031
1128=99=36035=X49=CME34=19940452=2013071514431153575=20130715268=3279=122=848=62233683=2523107=GEZ4 C9925269=1270=31.5271=1000273=144311000336=2346=31023=1279=222=848=62233683=2524107=GEZ4 C9925269=1270=35.5271=125273=144311000336=2346=11023=3279=122=848=27027983=809107=GEZ4 P9800269=1270=7.5271=133273=144311000336=2346=21023=110=052
1128=99=460435=X49=CME34=21099352=2013071515012971875=20130715268=46279=022=848=72272783=1693107=GEH5 C9850269=1270=85.5271=150273=150129000336=2346=11023=1279=122=848=72272783=1694107=GEH5 C9850269=1270=86271=100273=150129000336=2346=11023=2279=022=848=4430783=1055107=GEH5 C9525269=1270=394.5271=75273=150129000336=2346=11023=1279=222=848=4430783=1056107=GEH5 C9525269=1270=395271=75273=150129000336=2346=11023=2279=022=848=36716183=1164107=GEH5 C9275269=1270=644271=75273=150129000336=2346=11023=1279=222=848=36716183=1165107=GEH5 C9275269=1270=644.5271=75273=150129000336=2346=11023=2279=022=848=81378183=1164107=GEH5 C9300269=1270=619271=75273=150129000336=2346=11023=1279=222=848=81378183=1165107=GEH5 C9300269=1270=619.5271=75273=150129000336=2346=11023=2279=022=848=69003883=1164107=GEH5 C9325269=1270=594271=75273=150129000336=2346=11023=1279=222=848=69003883=1165107=GEH5 C9325269=1270=594.5271=75273=150129000336=2346=11023=2279=022=848=22104483=1160107=GEH5 C9350269=1270=569271=75273=150129000336=2346=11023=1279=222=848=22104483=1161107=GEH5 C9350269=1270=569.5271=75273=150129000336=2346=11023=2279=022=848=42903383=1152107=GEH5 C9375269=1270=544271=75273=150129000336=2346=11023=1279=222=848=42903383=1153107=GEH5 C9375269=1270=544.5271=75273=150129000336=2346=11023=2279=022=848=28285883=1152107=GEH5 C9400269=1270=519271=75273=150129000336=2346=11023=1279=222=848=28285883=1153107=GEH5 C9400269=1270=519.5271=75273=150129000336=2346=11023=2279=022=848=47804683=942107=GEH5 C9600269=1270=320.5271=75273=150129000336=2346=11023=1279=222=848=47804683=943107=GEH5 C9600269=1270=321271=75273=150129000336=2346=11023=2279=022=848=88240983=1149107=GEH5 C9425269=1270=494271=75273=150129000336=2346=11023=1279=222=848=88240983=1150107=GEH5 C9425269=1270=494.5271=75273=150129000336=2346=11023=2279=022=848=66100483=1093107=GEH5 C9450269=1270=469271=75273=150129000336=2346=11023=1279=222=848=66100483=1094107=GEH5 C9450269=1270=469.5271=75273=150129000336=2346=11023=2279=022=848=82053483=1137107=GEH5 C9475269=1270=444.5271=75273=150129000336=2346=11023=1279=222=848=82053483=1138107=GEH5 C9475269=1270=445271=75273=150129000336=2346=11023=2279=022=848=33797983=1062107=GEH5 C9625269=1270=296271=75273=150129000336=2346=11023=1279=222=848=33797983=1063107=GEH5 C9625269=1270=296.5271=75273=150129000336=2346=11023=2279=022=848=8373583=1137107=GEH5 C9500269=1270=419.5271=75273=150129000336=2346=11023=1279=222=848=8373583=1138107=GEH5 C9500269=1270=420271=75273=150129000336=2346=11023=2279=022=848=34473283=1133107=GEH5 C9550269=1270=370271=75273=150129000336=2346=11023=1279=222=848=34473283=1134107=GEH5 C9550269=1270=370.5271=75273=150129000336=2346=11023=2279=022=848=10624283=1057107=GEH5 C9575269=1270=345.5271=75273=150129000336=2346=11023=1279=222=848=10624283=1058107=GEH5 C9575269=1270=346271=75273=150129000336=2346=11023=2279=022=848=62816183=870107=GEH5 C9650269=1270=272271=75273=150129000336=2346=11023=1279=222=848=62816183=871107=GEH5 C9650269=1270=272.5271=75273=150129000336=2346=11023=2279=022=848=85323383=1052107=GEH5 C9675269=1270=247.5271=75273=150129000336=2346=11023=1279=222=848=85323383=1053107=GEH5 C9675269=1270=248271=75273=150129000336=2346=11023=2279=022=848=60573483=1080107=GEH5 C9687269=1270=235.5271=75273=150129000336=2346=11023=1279=222=848=60573483=1081107=GEH5 C9687269=1270=236271=75273=150129000336=2346=11023=2279=022=848=61465183=1894107=GEH5 C9737269=1270=187.5271=75273=150129000336=2346=11023=1279=122=848=61465183=1895107=GEH5 C9737269=1270=188271=50273=150129000336=2346=11023=2279=022=848=30528983=1510107=GEH5 C9875269=1270=65271=150273=150129000336=2346=11023=1279=122=848=30528983=1511107=GEH5 C9875269=1270=65.5271=100273=150129000336=2346=11023=2279=022=848=29853883=1004107=GEH5 C9700269=1270=223.5271=75273=150129000336=2346=11023=1279=222=848=29853883=1005107=GEH5 C9700269=1270=224271=75273=150129000336=2346=11023=2279=022=848=2319483=982107=GEH5 C9712269=1270=211.5271=75273=150129000336=2346=11023=1279=222=848=2319483=983107=GEH5 C9712269=1270=212271=75273=150129000336=2346=11023=210=246
1128=99=84635=X49=CME34=17831052=2013071514194602975=20130715268=8279=022=848=57304683=1051107=GEH5 P9937269=1270=40.5271=75273=141946000336=2346=11023=1279=122=848=57304683=1052107=GEH5 P9937269=1270=41271=50273=141946000336=2346=11023=2279=122=848=75866783=2125107=GEH5 P9862269=1270=20271=730273=141946000336=2346=31023=1279=222=848=75866783=2126107=GEH5 P9862269=1270=20.5271=150273=141946000336=2346=11023=2279=122=848=25692083=2001107=GEH5 P9850269=1270=18271=660273=141946000336=2346=31023=1279=222=848=25692083=2002107=GEH5 P9850269=1270=18.5271=150273=141946000336=2346=11023=2279=022=848=38742583=363107=GEH5 P9675269=1270=5.5271=150273=141946000336=2346=11023=2279=122=848=38742583=364107=GEH5 P9675269=1270=6271=20273=141946000336=2346=11023=310=023
1128=99=181835=X49=CME34=33149852=2013071518151517375=20130715268=18279=022=848=80275783=1090107=GEH4 C9800269=0270=157.5271=75273=181515000336=2346=11023=1279=122=848=80275783=1091107=GEH4 C9800269=0270=157271=50273=181515000336=2346=11023=2279=022=848=22563283=1129107=GEH4 C9825269=0270=133271=75273=181515000336=2346=11023=1279=122=848=22563283=1130107=GEH4 C9825269=0270=132.5271=50273=181515000336=2346=11023=2279=122=848=43151683=911107=GEH4 C9875269=0270=84271=175273=181515000336=2346=21023=1279=022=848=21887783=985107=GEH4 C9837269=0270=120.5271=75273=181515000336=2346=11023=1279=122=848=21887783=986107=GEH4 C9837269=0270=120271=50273=181515000336=2346=11023=2279=022=848=46637183=1109107=GEH4 C9850269=0270=108.5271=75273=181515000336=2346=11023=1279=122=848=46637183=1110107=GEH4 C9850269=0270=108271=50273=181515000336=2346=11023=2279=122=848=78924783=916107=GEH4 C9900269=0270=60271=282273=181515000336=2346=31023=1279=122=848=79600983=832107=GEH4 C9887269=0270=72271=232273=181515000336=2346=31023=1279=022=848=89192383=613107=GEH4 P9912269=1270=4.5271=150273=181515000336=2346=11023=2279=122=848=89192383=614107=GEH4 P9912269=1270=5271=100273=181515000336=2346=11023=3279=122=848=6972783=514107=GEH4 P9825269=1270=1.5271=953273=181515000336=2346=31023=1279=122=848=6972783=515107=GEH4 P9825269=1270=2271=100273=181515000336=2346=11023=2279=122=848=17756683=205107=GEH4 P9737269=1270=1271=990273=181515000336=2346=41023=1279=122=848=2150383=682107=GEU3 P9550269=1270=0.5271=1273=181515000336=2346=11023=1279=122=848=2150383=683107=GEU3 P9550269=1270=0.75271=600273=181515000336=2346=31023=210=254
1128=99=45235=X49=CME34=21097052=2013071515012797675=20130715268=4279=022=848=87273483=723107=GEM4 P9725269=0270=0.5271=17273=150127000336=2346=11023=1279=122=848=87273483=724107=GEM4 P9725269=1270=1.5271=745273=150127000336=2346=21023=1279=222=848=37100783=229107=GEM4 P9962269=1270=21.5271=125273=150127000336=2346=11023=1279=022=848=37100783=230107=GEM4 P9962269=1270=22271=125273=150127000336=2346=11023=110=027
1128=99=210535=X49=CME34=4348252=2013071511583358875=20130715268=21279=222=848=10714983=424107=GEZ4 C9862269=0270=78271=50273=115833000336=2346=11023=1279=022=848=10714983=425107=GEZ4 C9862269=0270=77.5271=50273=115833000336=2346=11023=1279=022=848=10714983=426107=GEZ4 C9862269=1270=81271=50273=115833000336=2346=11023=1279=222=848=10714983=427107=GEZ4 C9862269=1270=81.5271=50273=115833000336=2346=11023=2279=222=848=33890283=1929107=GEZ4 C9937269=0270=20271=100273=115833000336=2346=11023=1279=122=848=33890283=1930107=GEZ4 C9937269=0270=19.5271=600273=115833000336=2346=21023=1279=022=848=33890283=1931107=GEZ4 C9937269=0270=2271=12273=115833000336=2346=31023=3279=122=848=38159883=458107=GEZ4 P9875269=0270=13.5271=600273=115833000336=2346=21023=1279=122=848=38159883=459107=GEZ4 P9875269=1270=15.5271=580273=115833000336=2346=21023=1279=222=848=7827083=373107=GEZ4 C9950269=0270=12.5271=100273=115833000336=2346=11023=1279=122=848=7827083=374107=GEZ4 C9950269=0270=12271=600273=115833000336=2346=21023=1279=022=848=7827083=375107=GEZ4 C9950269=0270=1271=8273=115833000336=2346=21023=3279=122=848=19489783=372107=GEZ4 P9850269=0270=10.5271=600273=115833000336=2346=21023=1279=122=848=29271783=274107=GEZ4 P9862269=0270=12271=580273=115833000336=2346=21023=1279=222=848=29271783=275107=GEZ4 P9862269=0270=11.5271=100273=115833000336=2346=11023=2279=122=848=38726583=1275107=GEZ4 P9837269=1270=11271=580273=115833000336=2346=21023=1279=222=848=49367183=161107=GEH4 P9900269=1270=4271=150273=115833000336=2346=11023=2279=022=848=49367183=162107=GEH4 P9900269=1270=4.5271=150273=115833000336=2346=11023=2279=122=848=27027983=313107=GEZ4 P9800269=0270=6.5271=580273=115833000336=2346=21023=1279=222=848=27027983=314107=GEZ4 P9800269=0270=6271=100273=115833000336=2346=11023=2279=022=848=27027983=315107=GEZ4 P9800269=0270=2.5271=1273=115833000336=2346=11023=310=006
1128=99=13935=X49=CME34=1461952=2013071418015624675=20130715268=1279=022=848=13126164=2013071283=1107=GEU3 P9600269=6270=0273=18015600010=139
1128=99=25735=X49=CME34=16791152=2013071514062735975=20130715268=2279=222=848=37100783=193107=GEM4 P9962269=1270=21.5271=125273=140627000336=2346=11023=1279=022=848=37100783=194107=GEM4 P9962269=1270=22271=125273=140627000336=2346=11023=110=049
1128=99=181335=X49=CME34=18589152=2013071514281483375=20130715268=18279=222=848=78551783=1068107=GEM5 C9550269=1270=355271=7273=142814000336=2346=11023=1279=022=848=78551783=1069107=GEM5 C9550269=1270=355.5271=7273=142814000336=2346=11023=1279=222=848=14003383=806107=GEM5 C9625269=1270=282271=7273=142814000336=2346=11023=1279=022=848=14003383=807107=GEM5 C9625269=1270=282.5271=7273=142814000336=2346=11023=1279=222=848=36022783=1026107=GEM5 C9600269=1270=306.5271=7273=142814000336=2346=11023=1279=022=848=36022783=1027107=GEM5 C9600269=1270=307271=7273=142814000336=2346=11023=1279=222=848=31862183=944107=GEM5 C9650269=1270=258271=7273=142814000336=2346=11023=1279=022=848=31862183=945107=GEM5 C9650269=1270=258.5271=7273=142814000336=2346=11023=1279=222=848=88898983=758107=GEM5 C9700269=1270=210.5271=7273=142814000336=2346=11023=1279=022=848=88898983=759107=GEM5 C9700269=1270=211271=7273=142814000336=2346=11023=1279=222=848=87547883=992107=GEM5 C9675269=1270=234.5271=7273=142814000336=2346=11023=1279=022=848=87547883=993107=GEM5 C9675269=1270=235271=7273=142814000336=2346=11023=1279=222=848=25674883=950107=GEM5 C9725269=1270=187.5271=7273=142814000336=2346=11023=1279=022=848=25674883=951107=GEM5 C9725269=1270=188271=7273=142814000336=2346=11023=1279=222=848=67915383=924107=GEM5 C9737269=1270=176271=7273=142814000336=2346=11023=1279=022=848=67915383=925107=GEM5 C9737269=1270=176.5271=7273=142814000336=2346=11023=1279=122=848=30078683=718107=GEM5 P9775269=0270=13271=500273=142814000336=2346=11023=1279=022=848=30078683=719107=GEM5 P9775269=0270=12.5271=75273=142814000336=2346=11023=210=158
1128=99=15735=X49=CME34=21136652=2013071515020586175=20130715268=1279=122=848=38742583=467107=GEH5 P9675269=0270=3271=250273=150205000336=2346=21023=110=176
1128=99=25435=X49=CME34=8563852=2013071512385797275=20130715268=2279=222=848=37100783=47107=GEM4 P9962269=1270=21271=125273=123857000336=2346=11023=1279=022=848=37100783=48107=GEM4 P9962269=1270=21.5271=125273=123857000336=2346=11023=110=177
1128=99=35135=X49=CME34=32497052=2013071518021079875=20130715268=3279=122=848=38742583=733107=GEH5 P9675269=0270=3.5271=250273=180210000336=2346=21023=1279=222=848=38742583=734107=GEH5 P9675269=0270=3271=100273=180210000336=2346=11023=2279=122=848=38742583=735107=GEH5 P9675269=1270=6271=163273=180210000336=2346=21023=210=124
1128=99=45335=X49=CME34=10154252=2013071512465089775=20130715268=4279=122=848=33890283=2247107=GEZ4 C9937269=1270=23271=800273=124650000336=2346=41023=1279=222=848=33890283=2248107=GEZ4 C9937269=1270=23.5271=500273=124650000336=2346=11023=2279=022=848=1924783=754107=GEZ4 P9887269=0270=14.5271=500273=124650000336=2346=11023=1279=122=848=1924783=755107=GEZ4 P9887269=0270=14271=667273=124650000336=2346=31023=210=161
1128=99=64435=X49=CME34=35294652=2013071519003968275=20130715268=6279=222=848=50824983=777107=GEM4 P9737269=0270=0.5271=33273=190039000336=2346=11023=1279=122=848=50824983=778107=GEM4 P9737269=1270=2271=333273=190039000336=2346=31023=2279=122=848=81762683=365107=GEM4 P9812269=1270=2.5271=530273=190039000336=2346=21023=1279=122=848=81762683=366107=GEM4 P9812269=1270=3271=200273=190039000336=2346=21023=2279=022=848=37100783=337107=GEM4 P9962269=1270=21271=125273=190039000336=2346=11023=1279=222=848=37100783=338107=GEM4 P9962269=1270=21.5271=125273=190039000336=2346=11023=210=198
1128=99=321835=X49=CME34=16537052=2013071514025947075=20130715268=32279=222=848=38558383=501107=GEU4 C9787269=0270=157271=100273=140259000336=2346=11023=1279=122=848=38558383=502107=GEU4 C9787269=0270=156.5271=175273=140259000336=2346=21023=1279=222=848=50150483=487107=GEU4 C9800269=0270=145271=100273=140259000336=2346=11023=1279=122=848=50150483=488107=GEU4 C9800269=0270=144.5271=175273=140259000336=2346=21023=1279=222=848=65225983=505107=GEU4 C9812269=0270=133271=100273=140259000336=2346=11023=1279=122=848=65225983=506107=GEU4 C9812269=0270=132.5271=175273=140259000336=2346=21023=1279=122=848=30912183=888107=GEU4 C9850269=0270=97.5271=217273=140259000336=2346=31023=1279=122=848=26751483=682107=GEU4 C9862269=0270=86271=217273=140259000336=2346=31023=1279=122=848=63875283=794107=GEU4 C9887269=0270=63.5271=177273=140259000336=2346=31023=1279=122=848=48015183=647107=GEU4 C9912269=0270=42271=290273=140259000336=2346=31023=1279=122=848=28101983=460107=GEU4 C9575269=0270=366.5271=100273=140259000336=2346=21023=1279=222=848=82437483=599107=GEU4 C9625269=0270=317271=50273=140259000336=2346=11023=1279=122=848=82437483=600107=GEU4 C9625269=0270=316.5271=125273=140259000336=2346=21023=1279=222=848=59714083=403107=GEU4 C9650269=0270=292271=50273=140259000336=2346=11023=1279=122=848=59714083=404107=GEU4 C9650269=0270=291.5271=125273=140259000336=2346=21023=1279=222=848=43962583=621107=GEU4 C9675269=0270=267.5271=50273=140259000336=2346=11023=1279=122=848=43962583=622107=GEU4 C9675269=0270=267271=125273=140259000336=2346=21023=1279=222=848=19213083=456107=GEU4 C9687269=0270=255271=50273=140259000336=2346=11023=1279=122=848=19213083=457107=GEU4 C9687269=0270=254.5271=125273=140259000336=2346=21023=1279=222=848=37775283=572107=GEU4 C9712269=0270=230.5271=50273=140259000336=2346=11023=1279=122=848=37775283=573107=GEU4 C9712269=0270=230271=125273=140259000336=2346=21023=1279=222=848=21239383=416107=GEU4 C9725269=0270=218271=50273=140259000336=2346=11023=1279=122=848=21239383=417107=GEU4 C9725269=0270=217.5271=125273=140259000336=2346=21023=1279=222=848=88624883=425107=GEU4 C9750269=0270=193.5271=50273=140259000336=2346=11023=1279=122=848=88624883=426107=GEU4 C9750269=0270=193271=125273=140259000336=2346=21023=1279=222=848=89300283=503107=GEU4 C9762269=0270=181.5271=50273=140259000336=2346=11023=1279=122=848=89300283=504107=GEU4 C9762269=0270=181271=125273=140259000336=2346=21023=1279=122=848=89976083=1296107=GEU4 C9937269=0270=22.5271=245273=140259000336=2346=21023=1279=122=848=89976083=1297107=GEU4 C9937269=0270=22271=600273=140259000336=2346=21023=2279=122=848=66578483=779107=GEU4 P9912269=1270=13.5271=1037273=140259000336=2346=41023=1279=122=848=31721683=646107=GEU4 P9900269=1270=11.5271=953273=140259000336=2346=31023=1279=022=848=31721683=647107=GEU4 P9900269=1270=12271=100273=140259000336=2346=11023=210=118
1128=99=152635=X49=CME34=3542252=2013071510405182975=20130715268=15279=222=848=33890283=1050107=GEZ4 C9937269=0270=20.5271=500273=104051000336=2346=11023=1279=122=848=33890283=1051107=GEZ4 C9937269=0270=20271=650273=104051000336=2346=21023=1279=022=848=33890283=1052107=GEZ4 C9937269=0270=2271=12273=104051000336=2346=31023=3279=222=848=62233683=801107=GEZ4 C9925269=0270=29271=500273=104051000336=2346=11023=1279=122=848=62233683=802107=GEZ4 C9925269=0270=28.5271=650273=104051000336=2346=21023=1279=222=848=43671583=694107=GEZ4 P9787269=1270=7271=500273=104051000336=2346=11023=1279=122=848=43671583=695107=GEZ4 P9787269=1270=7.5271=650273=104051000336=2346=21023=1279=222=848=12739883=698107=GEZ4 P9825269=1270=9.5271=500273=104051000336=2346=11023=1279=122=848=12739883=699107=GEZ4 P9825269=1270=10271=650273=104051000336=2346=21023=1279=222=848=38726583=698107=GEZ4 P9837269=1270=10.5271=500273=104051000336=2346=11023=1279=122=848=38726583=699107=GEZ4 P9837269=1270=11271=650273=104051000336=2346=21023=1279=222=848=70448783=698107=GEZ4 P9650269=1270=2.5271=500273=104051000336=2346=11023=1279=022=848=70448783=699107=GEZ4 P9650269=1270=3271=500273=104051000336=2346=11023=1279=222=848=25677583=779107=GEZ4 P9900269=1270=19271=500273=104051000336=2346=11023=1279=122=848=25677583=780107=GEZ4 P9900269=1270=19.5271=650273=104051000336=2346=21023=110=022
1128=99=44935=X49=CME34=18422252=2013071514235388875=20130715268=4279=122=848=64843083=645107=GEH5 P9787269=0270=9271=250273=142353000336=2346=21023=1279=222=848=64843083=646107=GEH5 P9787269=0270=8.5271=150273=142353000336=2346=11023=2279=222=848=38742583=389107=GEH5 P9675269=1270=5.5271=150273=142353000336=2346=11023=2279=122=848=38742583=390107=GEH5 P9675269=1270=6271=170273=142353000336=2346=21023=210=199
1128=99=200435=X49=CME34=4012552=2013071511495054375=20130715268=20279=222=848=47523583=40107=GEH5 C9837269=1270=94.5271=75273=114950000336=2346=11023=1279=022=848=47523583=41107=GEH5 C9837269=1270=95271=75273=114950000336=2346=11023=1279=022=848=11291383=28107=GEH5 C9825269=0270=102.5271=75273=114950000336=2346=11023=1279=222=848=11291383=29107=GEH5 C9825269=0270=102271=75273=114950000336=2346=11023=2279=222=848=11291383=30107=GEH5 C9825269=1270=105.5271=75273=114950000336=2346=11023=1279=022=848=11291383=31107=GEH5 C9825269=1270=106271=75273=114950000336=2346=11023=1279=022=848=2308583=18107=GEH5 C9900269=0270=42271=150273=114950000336=2346=11023=1279=222=848=2308583=19107=GEH5 C9900269=0270=41.5271=150273=114950000336=2346=11023=2279=022=848=57304683=32107=GEH5 P9937269=1270=42.5271=75273=114950000336=2346=11023=1279=222=848=57304683=33107=GEH5 P9937269=1270=43271=75273=114950000336=2346=11023=2279=022=848=3759483=304107=GEH5 P9887269=1270=26.5271=150273=114950000336=2346=11023=1279=222=848=3759483=305107=GEH5 P9887269=1270=27271=150273=114950000336=2346=11023=2279=022=848=55953383=1156107=GEH5 C9912269=0270=33.5271=150273=114950000336=2346=11023=1279=222=848=55953383=1157107=GEH5 C9912269=0270=33271=150273=114950000336=2346=11023=2279=222=848=75866783=1082107=GEH5 P9862269=0270=19271=150273=114950000336=2346=11023=1279=022=848=75866783=1083107=GEH5 P9862269=0270=18.5271=150273=114950000336=2346=11023=1279=022=848=52467883=922107=GEH5 P9875269=1270=23.5271=150273=114950000336=2346=11023=1279=222=848=52467883=923107=GEH5 P9875269=1270=24271=150273=114950000336=2346=11023=2279=222=848=1924783=391107=GEZ4 P9887269=0270=15.5271=80273=114950000336=2346=11023=1279=122=848=1924783=392107=GEZ4 P9887269=0270=15271=250273=114950000336=2346=21023=110=052
1128=99=242235=X49=CME34=21237352=2013071515024170875=20130715268=24279=222=848=27610983=1872107=GEH5 C9762269=1270=164271=75273=150241000336=2346=11023=1279=122=848=27610983=1873107=GEH5 C9762269=1270=164.5271=98273=150241000336=2346=21023=1279=222=848=53035583=1452107=GEH5 C9750269=1270=176271=75273=150241000336=2346=11023=1279=022=848=53035583=1453107=GEH5 C9750269=1270=176.5271=75273=150241000336=2346=11023=1279=222=848=43579483=1787107=GEH5 C9775269=1270=152.5271=75273=150241000336=2346=11023=1279=022=848=43579483=1788107=GEH5 C9775269=1270=153271=75273=150241000336=2346=11023=1279=222=848=2866183=1691107=GEH5 C9800269=1270=129.5271=75273=150241000336=2346=11023=1279=022=848=2866183=1692107=GEH5 C9800269=1270=130271=75273=150241000336=2346=11023=1279=222=848=80705883=1732107=GEH5 C9787269=1270=141271=75273=150241000336=2346=11023=1279=022=848=80705883=1733107=GEH5 C9787269=1270=141.5271=75273=150241000336=2346=11023=1279=222=848=2308583=1030107=GEH5 C9900269=1270=46271=150273=150241000336=2346=11023=1279=022=848=2308583=1031107=GEH5 C9900269=1270=46.5271=150273=150241000336=2346=11023=1279=222=848=11969183=1048107=GEH5 P9962269=0270=50.5271=75273=150241000336=2346=11023=1279=022=848=11969183=1049107=GEH5 P9962269=0270=50271=75273=150241000336=2346=11023=1279=222=848=27043383=984107=GEH5 P9950269=0270=43.5271=75273=150241000336=2346=11023=1279=022=848=27043383=985107=GEH5 P9950269=0270=43271=75273=150241000336=2346=11023=1279=222=848=57304683=1303107=GEH5 P9937269=0270=38271=75273=150241000336=2346=11023=1279=022=848=57304683=1304107=GEH5 P9937269=0270=37.5271=75273=150241000336=2346=11023=1279=222=848=75866783=2395107=GEH5 P9862269=0270=18271=150273=150241000336=2346=11023=1279=122=848=75866783=2396107=GEH5 P9862269=0270=17.5271=650273=150241000336=2346=21023=1279=222=848=25692083=2264107=GEH5 P9850269=0270=16271=150273=150241000336=2346=11023=1279=122=848=25692083=2265107=GEH5 P9850269=0270=15.5271=650273=150241000336=2346=21023=1279=222=848=38742583=478107=GEH5 P9675269=0270=3.5271=150273=150241000336=2346=11023=1279=022=848=38742583=479107=GEH5 P9675269=0270=3271=150273=150241000336=2346=11023=110=071
1128=99=64335=X49=CME34=11992652=2013071513113518875=20130715268=6279=122=848=64443183=221107=GEM4 C9962269=1270=7.5271=833273=131135000336=2346=21023=1279=222=848=64443183=222107=GEM4 C9962269=1270=8271=333273=131135000336=2346=11023=2279=022=848=37100783=95107=GEM4 P9962269=0270=15271=125273=131135000336=2346=11023=1279=222=848=37100783=96107=GEM4 P9962269=0270=14.5271=125273=131135000336=2346=11023=2279=222=848=37100783=97107=GEM4 P9962269=1270=21271=125273=131135000336=2346=11023=1279=022=848=37100783=98107=GEM4 P9962269=1270=21.5271=125273=131135000336=2346=11023=110=045
1128=99=25435=X49=CME34=12522952=2013071513192014575=20130715268=2279=122=848=2150383=266107=GEU3 P9550269=1270=0.5271=1273=131920000336=2346=11023=1279=122=848=2150383=267107=GEU3 P9550269=1270=0.75271=600273=131920000336=2346=31023=210=120
1128=99=25535=X49=CME34=12522552=2013071513192012375=20130715268=2279=122=848=2150383=264107=GEU3 P9550269=1270=0.5271=51273=131920000336=2346=21023=1279=122=848=2150383=265107=GEU3 P9550269=1270=0.75271=550273=131920000336=2346=21023=210=166
1128=99=16035=X49=CME34=30465352=2013071517231167375=20130715268=1279=122=848=27027983=1157107=GEZ4 P9800269=1270=7.5271=133273=172311000336=2346=21023=110=075
1128=99=73735=X49=CME34=33152352=2013071518151535475=20130715268=7279=222=848=89192383=615107=GEH4 P9912269=1270=4.5271=150273=181515000336=2346=11023=2279=122=848=89192383=616107=GEH4 P9912269=1270=5271=250273=181515000336=2346=21023=2279=122=848=6972783=516107=GEH4 P9825269=1270=1.5271=833273=181515000336=2346=21023=1279=122=848=6972783=517107=GEH4 P9825269=1270=2271=250273=181515000336=2346=21023=2279=122=848=17756683=206107=GEH4 P9737269=1270=1271=975273=181515000336=2346=41023=1279=122=848=2150383=684107=GEU3 P9550269=1270=0.5271=51273=181515000336=2346=21023=1279=122=848=2150383=685107=GEU3 P9550269=1270=0.75271=550273=181515000336=2346=21023=210=212
1128=99=25735=X49=CME34=35549552=2013071519032895675=20130715268=2279=022=848=37100783=345107=GEM4 P9962269=1270=21271=125273=190328000336=2346=11023=1279=222=848=37100783=346107=GEM4 P9962269=1270=21.5271=125273=190328000336=2346=11023=210=065
1128=99=15835=X49=CME34=23723152=2013071515424325375=20130715268=1279=122=848=27027983=985107=GEZ4 P9800269=0270=6271=1167273=154243000336=2346=41023=110=254
1128=99=182135=X49=CME34=20001752=2013071514450231575=20130715268=18279=222=848=76523983=1100107=GEM5 C9525269=1270=379.5271=7273=144502000336=2346=11023=1279=022=848=76523983=1101107=GEM5 C9525269=1270=380271=7273=144502000336=2346=11023=1279=222=848=78551783=1148107=GEM5 C9550269=1270=355271=7273=144502000336=2346=11023=1279=022=848=78551783=1149107=GEM5 C9550269=1270=355.5271=7273=144502000336=2346=11023=1279=222=848=14003383=862107=GEM5 C9625269=1270=282271=7273=144502000336=2346=11023=1279=022=848=14003383=863107=GEM5 C9625269=1270=282.5271=7273=144502000336=2346=11023=1279=222=848=31862183=1022107=GEM5 C9650269=1270=258271=7273=144502000336=2346=11023=1279=022=848=31862183=1023107=GEM5 C9650269=1270=258.5271=7273=144502000336=2346=11023=1279=222=848=36022783=1106107=GEM5 C9600269=1270=306.5271=7273=144502000336=2346=11023=1279=022=848=36022783=1107107=GEM5 C9600269=1270=307271=7273=144502000336=2346=11023=1279=222=848=87547883=1052107=GEM5 C9675269=1270=234.5271=7273=144502000336=2346=11023=1279=022=848=87547883=1053107=GEM5 C9675269=1270=235271=7273=144502000336=2346=11023=1279=222=848=25674883=1030107=GEM5 C9725269=1270=187.5271=7273=144502000336=2346=11023=1279=022=848=25674883=1031107=GEM5 C9725269=1270=188271=7273=144502000336=2346=11023=1279=222=848=67915383=984107=GEM5 C9737269=1270=176271=7273=144502000336=2346=11023=1279=022=848=67915383=985107=GEM5 C9737269=1270=176.5271=7273=144502000336=2346=11023=1279=122=848=30078683=790107=GEM5 P9775269=0270=13271=500273=144502000336=2346=11023=1279=022=848=30078683=791107=GEM5 P9775269=0270=12.5271=75273=144502000336=2346=11023=210=087
1128=99=65335=X49=CME34=10262852=2013071512481616575=20130715268=6279=122=848=11386283=1387107=GEZ4 P9937269=1270=27.5271=1003273=124816000336=2346=31023=1279=122=848=11386283=1388107=GEZ4 P9937269=1270=28271=100273=124816000336=2346=11023=2279=122=848=62233683=1848107=GEZ4 C9925269=0270=30271=1125273=124816000336=2346=41023=1279=222=848=62233683=1849107=GEZ4 C9925269=0270=29.5271=500273=124816000336=2346=11023=2279=122=848=27027983=553107=GEZ4 P9800269=1270=7.5271=965273=124816000336=2346=41023=1279=222=848=27027983=554107=GEZ4 P9800269=1270=8271=500273=124816000336=2346=11023=210=192
1128=99=25435=X49=CME34=5644652=2013071512235509875=20130715268=2279=022=848=37100783=17107=GEM4 P9962269=1270=22.5271=125273=122355000336=2346=11023=1279=222=848=37100783=18107=GEM4 P9962269=1270=23271=125273=122355000336=2346=11023=210=145
1128=99=144335=X49=CME34=27229852=2013071516401507575=20130715268=14279=122=848=33890283=3252107=GEZ4 C9937269=0270=20.5271=100273=164015000336=2346=11023=2279=022=848=33890283=3253107=GEZ4 C9937269=0270=20271=500273=164015000336=2346=11023=3279=122=848=62233683=2928107=GEZ4 C9925269=0270=29271=100273=164015000336=2346=11023=2279=022=848=62233683=2929107=GEZ4 C9925269=0270=28.5271=500273=164015000336=2346=11023=3279=222=848=2976083=258107=GEZ4 C9987269=0270=0.5271=500273=164015000336=2346=11023=1279=022=848=2976083=259107=GEZ4 C9987269=0270=0.25271=500273=164015000336=2346=11023=1279=222=848=37484883=1371107=GEZ4 P9700269=1270=3.5271=500273=164015000336=2346=11023=1279=122=848=37484883=1372107=GEZ4 P9700269=1270=4271=623273=164015000336=2346=31023=1279=122=848=19489783=1014107=GEZ4 P9850269=1270=11.5271=395273=164015000336=2346=31023=1279=022=848=19489783=1015107=GEZ4 P9850269=1270=12271=500273=164015000336=2346=11023=2279=122=848=38159883=1365107=GEZ4 P9875269=1270=14.5271=380273=164015000336=2346=21023=1279=122=848=38159883=1366107=GEZ4 P9875269=1270=15271=600273=164015000336=2346=21023=2279=122=848=25677583=2563107=GEZ4 P9900269=1270=18.5271=225273=164015000336=2346=11023=1279=122=848=25677583=2564107=GEZ4 P9900269=1270=19271=700273=164015000336=2346=31023=210=248
1128=99=25535=X49=CME34=11988952=2013071513113431375=20130715268=2279=222=848=37100783=83107=GEM4 P9962269=1270=21271=125273=131134000336=2346=11023=1279=022=848=37100783=84107=GEM4 P9962269=1270=21.5271=125273=131134000336=2346=11023=110=182
1128=99=25535=X49=CME34=38322552=2013071520114927875=20130715268=2279=122=848=2150383=821107=GEU3 P9550269=1270=0.5271=51273=201149000336=2346=21023=1279=122=848=2150383=822107=GEU3 P9550269=1270=0.75271=500273=201149000336=2346=11023=210=178
1128=99=84735=X49=CME34=10016152=2013071512452947875=20130715268=8279=122=848=50442283=1673107=GEH5 P9912269=1270=31271=250273=124529000336=2346=21023=1279=222=848=50442283=1674107=GEH5 P9912269=1270=35271=75273=124529000336=2346=11023=3279=122=848=53035583=620107=GEH5 C9750269=0270=174271=125273=124529000336=2346=21023=1279=222=848=53035583=621107=GEH5 C9750269=0270=170.5271=75273=124529000336=2346=11023=2279=122=848=61465183=702107=GEH5 C9737269=0270=186271=125273=124529000336=2346=21023=1279=222=848=61465183=703107=GEH5 C9737269=0270=182.5271=75273=124529000336=2346=11023=2279=122=848=24341283=625107=GEH5 C9725269=0270=198271=125273=124529000336=2346=21023=1279=222=848=24341283=626107=GEH5 C9725269=0270=194.5271=75273=124529000336=2346=11023=210=219
1128=99=25735=X49=CME34=35066952=2013071518580132475=20130715268=2279=022=848=37100783=309107=GEM4 P9962269=0270=15271=125273=185801000336=2346=11023=1279=222=848=37100783=310107=GEM4 P9962269=0270=14.5271=125273=185801000336=2346=11023=210=046
1128=99=172735=X49=CME34=9807852=2013071512450225675=20130715268=17279=122=848=59315083=891107=GEZ4 C9837269=0270=103.5271=143273=124502000336=2346=21023=1279=022=848=59315083=892107=GEZ4 C9837269=0270=102.5271=50273=124502000336=2346=11023=2279=122=848=13981783=792107=GEZ4 C9875269=0270=70271=233273=124502000336=2346=31023=1279=122=848=10714983=853107=GEZ4 C9862269=0270=81271=193273=124502000336=2346=21023=1279=022=848=10714983=854107=GEZ4 C9862269=0270=80.5271=50273=124502000336=2346=11023=2279=122=848=33890283=2233107=GEZ4 C9937269=0270=21.5271=220273=124502000336=2346=21023=1279=122=848=33890283=2234107=GEZ4 C9937269=0270=21271=600273=124502000336=2346=21023=2279=122=848=87658983=851107=GEZ4 P9912269=1270=21271=1133273=124502000336=2346=41023=1279=122=848=25677583=1679107=GEZ4 P9900269=1270=18271=170273=124502000336=2346=21023=1279=122=848=25677583=1680107=GEZ4 P9900269=1270=18.5271=600273=124502000336=2346=21023=2279=122=848=83496983=981107=GEZ4 P9950269=1270=32271=27273=124502000336=2346=11023=1279=022=848=83496983=982107=GEZ4 P9950269=1270=33271=50273=124502000336=2346=11023=3279=122=848=1924783=739107=GEZ4 P9887269=1270=16271=313273=124502000336=2346=31023=1279=122=848=7827083=616107=GEZ4 C9950269=0270=13.5271=1147273=124502000336=2346=41023=1279=122=848=38159883=715107=GEZ4 P9875269=1270=14271=220273=124502000336=2346=21023=1279=122=848=38159883=716107=GEZ4 P9875269=1270=14.5271=600273=124502000336=2346=21023=2279=122=848=27027983=482107=GEZ4 P9800269=1270=7.5271=985273=124502000336=2346=41023=110=134
1128=99=25435=X49=CME34=38209552=2013071520042036975=20130715268=2279=122=848=2150383=815107=GEU3 P9550269=1270=0.5271=1273=200420000336=2346=11023=1279=122=848=2150383=816107=GEU3 P9550269=1270=0.75271=550273=200420000336=2346=21023=210=113
1128=99=104435=X49=CME34=11933952=2013071513112836875=20130715268=10279=222=848=84740383=537107=GEZ4 C9725269=0270=209.5271=50273=131128000336=2346=11023=1279=122=848=84740383=538107=GEZ4 C9725269=0270=209271=100273=131128000336=2346=21023=1279=122=848=84740383=539107=GEZ4 C9725269=1270=212271=90273=131128000336=2346=21023=1279=222=848=84740383=540107=GEZ4 C9725269=1270=212.5271=50273=131128000336=2346=11023=2279=122=848=84066783=1112107=GEZ4 P9925269=1270=24271=917273=131128000336=2346=31023=1279=222=848=62233683=1981107=GEZ4 C9925269=0270=30271=100273=131128000336=2346=11023=1279=122=848=62233683=1982107=GEZ4 C9925269=0270=29.5271=833273=131128000336=2346=41023=1279=122=848=87658983=1013107=GEZ4 P9912269=0270=19.5271=33273=131128000336=2346=11023=1279=022=848=87658983=1014107=GEZ4 P9912269=0270=19271=100273=131128000336=2346=11023=2279=122=848=1924783=875107=GEZ4 P9887269=1270=16271=550273=131128000336=2346=21023=110=250
1128=99=25735=X49=CME34=35079552=2013071518580999275=20130715268=2279=222=848=37100783=311107=GEM4 P9962269=0270=15271=125273=185809000336=2346=11023=1279=022=848=37100783=312107=GEM4 P9962269=0270=14.5271=125273=185809000336=2346=11023=110=075
1128=99=93035=X49=CME34=33154752=2013071518151559575=20130715268=9279=122=848=87841383=651107=GEH4 P9937269=1270=6.5271=620273=181515000336=2346=21023=1279=222=848=87841383=652107=GEH4 P9937269=1270=7271=150273=181515000336=2346=11023=2279=022=848=89192383=617107=GEH4 P9912269=1270=4.5271=150273=181515000336=2346=11023=2279=122=848=89192383=618107=GEH4 P9912269=1270=5271=100273=181515000336=2346=11023=3279=122=848=6972783=518107=GEH4 P9825269=1270=1.5271=953273=181515000336=2346=31023=1279=122=848=6972783=519107=GEH4 P9825269=1270=2271=100273=181515000336=2346=11023=2279=122=848=17756683=207107=GEH4 P9737269=1270=1271=990273=181515000336=2346=41023=1279=122=848=2150383=686107=GEU3 P9550269=1270=0.5271=1273=181515000336=2346=11023=1279=122=848=2150383=687107=GEU3 P9550269=1270=0.75271=600273=181515000336=2346=31023=210=130
1128=99=25735=X49=CME34=36889352=2013071519384698075=20130715268=2279=222=848=37100783=355107=GEM4 P9962269=0270=15271=125273=193846000336=2346=11023=1279=022=848=37100783=356107=GEM4 P9962269=0270=14.5271=125273=193846000336=2346=11023=110=096
1128=99=85935=X49=CME34=23399652=2013071515362175775=20130715268=8279=122=848=53035583=1636107=GEH5 C9750269=0270=172.5271=125273=153621000336=2346=21023=1279=222=848=53035583=1637107=GEH5 C9750269=0270=169.5271=75273=153621000336=2346=11023=2279=122=848=53035583=1638107=GEH5 C9750269=1270=176271=125273=153621000336=2346=21023=1279=222=848=53035583=1639107=GEH5 C9750269=1270=176.5271=50273=153621000336=2346=11023=2279=122=848=24341283=2090107=GEH5 C9725269=0270=196271=125273=153621000336=2346=21023=1279=222=848=24341283=2091107=GEH5 C9725269=0270=193.5271=75273=153621000336=2346=11023=2279=122=848=24341283=2092107=GEH5 C9725269=1270=199.5271=125273=153621000336=2346=21023=1279=222=848=24341283=2093107=GEH5 C9725269=1270=200271=50273=153621000336=2346=11023=210=000
1128=99=25735=X49=CME34=35833652=2013071519082478775=20130715268=2279=222=848=37100783=347107=GEM4 P9962269=1270=21271=125273=190824000336=2346=11023=1279=022=848=37100783=348107=GEM4 P9962269=1270=21.5271=125273=190824000336=2346=11023=110=070
